Workbook

Sheet Cover
B8: THREE STATEMENT FINANCIAL MODEL
B9: Industry-Grade Integrated Financial Framework | 3-Year Historical + 5-Year Projection
C13: MODEL NAVIGATION
C14: 1 | D14: Inputs
C16: 2 | D16: Assumptions
C18: 3 | D18: Income Statement
C20: 4 | D20: Balance Sheet
C22: 5 | D22: Cash Flow
C24: 6 | D24: Supporting Schedules

Sheet Inputs
B1: DATA INPUTS | J1: BACK -->
B3: LINE ITEM | C3: FY-3 (Hist.) | D3: FY-2 (Hist.) | E3: FY-1 (Hist.) | F3: FY+1 (Proj.) | G3: FY+2 (Proj.) | H3: FY+3 (Proj.) | I3: FY+4 (Proj.) | J3: FY+5 (Proj.)
B4: INCOME STATEMENT INPUTS
B5: Revenue / Net Sales
B6: Cost of Goods Sold (COGS)
B7: Research & Development Expense
B8: Selling, General & Administrative (SG&A)
B9: Other Operating Income / (Expense)
B10: Depreciation & Amortization
B11: Interest Expense
B12: Interest Income
B13: Other Non-Operating Income / (Expense)
B14: Tax Rate (Effective)
B15: Shares Outstanding (mm) – Basic
... B53: Proceeds from Stock Issuance

Sheet Assumptions
B1: ASSUMPTIONS & DRIVERS | J1: BACK -->
B3: DRIVER / ASSUMPTION | C3: FY-3 (Hist.) | D3: FY-2 (Hist.) | E3: FY-1 (Hist.) | F3: FY+1 (Proj.) | G3: FY+2 (Proj.) | H3: FY+3 (Proj.) | I3: FY+4 (Proj.) | J3: FY+5 (Proj.)
B4: REVENUE DRIVERS
B5: Revenue Growth Rate YoY
B6: Revenue – Segment A
B7: Revenue – Segment B
B8: Revenue – Segment C
B10: MARGIN & COST DRIVERS
B11: Gross Margin %
B12: R&D as % of Revenue
B13: SG&A as % of Revenue
B14: EBITDA Margin %
B15: D&A as % of Revenue
B16: Effective Tax Rate %
... B42: Terminal Growth Rate %

Sheet Income Statement
B1: INCOME STATEMENT | J1: BACK -->
B3: ($mm) | C3: FY-3 (H) | D3: FY-2 (H) | E3: FY-1 (H) | F3: FY+1 (P) | G3: FY+2 (P) | H3: FY+3 (P) | I3: FY+4 (P) | J3: FY+5 (P)
B4: REVENUE
B5: Net Revenue | C5: =IF(ISNUMBER(Inputs!C5),Inputs!C5,0) -> 0 | D5: =IF(ISNUMBER(Inputs!D5),Inputs!D5,0) -> 0 | E5: =IF(ISNUMBER(Inputs!E5),Inputs!E5,0) -> 0 | F5: =IF(ISNUMBER(Inputs!F5),Inputs!F5,0) -> 0 | G5: =IF(ISNUMBER(Inputs!G5),Inputs!G5,0) -> 0 | H5: =IF(ISNUMBER(Inputs!H5),Inputs!H5,0) -> 0 | I5: =IF(ISNUMBER(Inputs!I5),Inputs!I5,0) -> 0 | J5: =IF(ISNUMBER(Inputs!J5),Inputs!J5,0) -> 0
B6: YoY Growth % | C6: - | D6: =IFERROR((D5-C5)/C5,"-") -> - | E6: =IFERROR((E5-D5)/D5,"-") -> - | F6: =IFERROR((F5-E5)/E5,"-") -> - | G6: =IFERROR((G5-F5)/F5,"-") -> - | H6: =IFERROR((H5-G5)/G5,"-") -> - | I6: =IFERROR((I5-H5)/H5,"-") -> - | J6: =IFERROR((J5-I5)/I5,"-") -> -
B7: COST OF REVENUE & GROSS PROFIT
B8: Cost of Goods Sold | C8: =IF(ISNUMBER(Inputs!C6),Inputs!C6,0) -> 0 | D8: =IF(ISNUMBER(Inputs!D6),Inputs!D6,0) -> 0 | E8: =IF(ISNUMBER(Inputs!E6),Inputs!E6,0) -> 0 | F8: =IF(ISNUMBER(Inputs!F6),Inputs!F6,0) -> 0 | G8: =IF(ISNUMBER(Inputs!G6),Inputs!G6,0) -> 0 | H8: =IF(ISNUMBER(Inputs!H6),Inputs!H6,0) -> 0 | I8: =IF(ISNUMBER(Inputs!I6),Inputs!I6,0) -> 0 | J8: =IF(ISNUMBER(Inputs!J6),Inputs!J6,0) -> 0
B9: GROSS PROFIT | C9: =C5-C8 -> 0 | D9: =D5-D8 -> 0 | E9: =E5-E8 -> 0 | F9: =F5-F8 -> 0 | G9: =G5-G8 -> 0 | H9: =H5-H8 -> 0 | I9: =I5-I8 -> 0 | J9: =J5-J8 -> 0
B10: Gross Margin % | C10: =IFERROR(C9/C5,"-") -> - | D10: =IFERROR(D9/D5,"-") -> - | E10: =IFERROR(E9/E5,"-") -> - | F10: =IFERROR(F9/F5,"-") -> - | G10: =IFERROR(G9/G5,"-") -> - | H10: =IFERROR(H9/H5,"-") -> - | I10: =IFERROR(I9/I5,"-") -> - | J10: =IFERROR(J9/J5,"-") -> -
B11: OPERATING EXPENSES
B12: Research & Development | C12: =IF(ISNUMBER(Inputs!C7),Inputs!C7,0) -> 0 | D12: =IF(ISNUMBER(Inputs!D7),Inputs!D7,0) -> 0 | E12: =IF(ISNUMBER(Inputs!E7),Inputs!E7,0) -> 0 | F12: =IF(ISNUMBER(Inputs!F7),Inputs!F7,0) -> 0 | G12: =IF(ISNUMBER(Inputs!G7),Inputs!G7,0) -> 0 | H12: =IF(ISNUMBER(Inputs!H7),Inputs!H7,0) -> 0 | I12: =IF(ISNUMBER(Inputs!I7),Inputs!I7,0) -> 0 | J12: =IF(ISNUMBER(Inputs!J7),Inputs!J7,0) -> 0
B13: Selling, General & Administrative | C13: =IF(ISNUMBER(Inputs!C8),Inputs!C8,0) -> 0 | D13: =IF(ISNUMBER(Inputs!D8),Inputs!D8,0) -> 0 | E13: =IF(ISNUMBER(Inputs!E8),Inputs!E8,0) -> 0 | F13: =IF(ISNUMBER(Inputs!F8),Inputs!F8,0) -> 0 | G13: =IF(ISNUMBER(Inputs!G8),Inputs!G8,0) -> 0 | H13: =IF(ISNUMBER(Inputs!H8),Inputs!H8,0) -> 0 | I13: =IF(ISNUMBER(Inputs!I8),Inputs!I8,0) -> 0 | J13: =IF(ISNUMBER(Inputs!J8),Inputs!J8,0) -> 0
B14: Other Operating Income / (Expense) | C14: =IF(ISNUMBER(Inputs!C9),Inputs!C9,0) -> 0 | D14: =IF(ISNUMBER(Inputs!D9),Inputs!D9,0) -> 0 | E14: =IF(ISNUMBER(Inputs!E9),Inputs!E9,0) -> 0 | F14: =IF(ISNUMBER(Inputs!F9),Inputs!F9,0) -> 0 | G14: =IF(ISNUMBER(Inputs!G9),Inputs!G9,0) -> 0 | H14: =IF(ISNUMBER(Inputs!H9),Inputs!H9,0) -> 0 | I14: =IF(ISNUMBER(Inputs!I9),Inputs!I9,0) -> 0 | J14: =IF(ISNUMBER(Inputs!J9),Inputs!J9,0) -> 0
B15: Depreciation & Amortization | C15: =IF(ISNUMBER(Inputs!C10),Inputs!C10,0) -> 0 | D15: =IF(ISNUMBER(Inputs!D10),Inputs!D10,0) -> 0 | E15: =IF(ISNUMBER(Inputs!E10),Inputs!E10,0) -> 0 | F15: =IF(ISNUMBER(Inputs!F10),Inputs!F10,0) -> 0 | G15: =IF(ISNUMBER(Inputs!G10),Inputs!G10,0) -> 0 | H15: =IF(ISNUMBER(Inputs!H10),Inputs!H10,0) -> 0 | I15: =IF(ISNUMBER(Inputs!I10),Inputs!I10,0) -> 0 | J15: =IF(ISNUMBER(Inputs!J10),Inputs!J10,0) -> 0
B16: Total Operating Expenses | C16: =C12+C13-C14+C15 -> 0 | D16: =D12+D13-D14+D15 -> 0 | E16: =E12+E13-E14+E15 -> 0 | F16: =F12+F13-F14+F15 -> 0 | G16: =G12+G13-G14+G15 -> 0 | H16: =H12+H13-H14+H15 -> 0 | I16: =I12+I13-I14+I15 -> 0 | J16: =J12+J13-J14+J15 -> 0
B17: EBIT (Operating Income) | C17: =C9-C16 -> 0 | D17: =D9-D16 -> 0 | E17: =E9-E16 -> 0 | F17: =F9-F16 -> 0 | G17: =G9-G16 -> 0 | H17: =H9-H16 -> 0 | I17: =I9-I16 -> 0 | J17: =J9-J16 -> 0
B18: EBIT Margin % | C18: =IFERROR(C17/C5,"-") -> - | D18: =IFERROR(D17/D5,"-") -> - | E18: =IFERROR(E17/E5,"-") -> - | F18: =IFERROR(F17/F5,"-") -> - | G18: =IFERROR(G17/G5,"-") -> - | H18: =IFERROR(H17/H5,"-") -> - | I18: =IFERROR(I17/I5,"-") -> - | J18: =IFERROR(J17/J5,"-") -> -
B19: EBITDA | C19: =C17+C15 -> 0 | D19: =D17+D15 -> 0 | E19: =E17+E15 -> 0 | F19: =F17+F15 -> 0 | G19: =G17+G15 -> 0 | H19: =H17+H15 -> 0 | I19: =I17+I15 -> 0 | J19: =J17+J15 -> 0
B20: EBITDA Margin % | C20: =IFERROR(C19/C5,"-") -> - | D20: =IFERROR(D19/D5,"-") -> - | E20: =IFERROR(E19/E5,"-") -> - | F20: =IFERROR(F19/F5,"-") -> - | G20: =IFERROR(G19/G5,"-") -> - | H20: =IFERROR(H19/H5,"-") -> - | I20: =IFERROR(I19/I5,"-") -> - | J20: =IFERROR(J19/J5,"-") -> -
B21: BELOW-THE-LINE ITEMS
B22: Interest Expense | C22: =IF(ISNUMBER(Inputs!C11),Inputs!C11,0) -> 0 | D22: =IF(ISNUMBER(Inputs!D11),Inputs!D11,0) -> 0 | E22: =IF(ISNUMBER(Inputs!E11),Inputs!E11,0) -> 0 | F22: =IF(ISNUMBER(Inputs!F11),Inputs!F11,0) -> 0 | G22: =IF(ISNUMBER(Inputs!G11),Inputs!G11,0) -> 0 | H22: =IF(ISNUMBER(Inputs!H11),Inputs!H11,0) -> 0 | I22: =IF(ISNUMBER(Inputs!I11),Inputs!I11,0) -> 0 | J22: =IF(ISNUMBER(Inputs!J11),Inputs!J11,0) -> 0
B23: Interest Income | C23: =IF(ISNUMBER(Inputs!C12),Inputs!C12,0) -> 0 | D23: =IF(ISNUMBER(Inputs!D12),Inputs!D12,0) -> 0 | E23: =IF(ISNUMBER(Inputs!E12),Inputs!E12,0) -> 0 | F23: =IF(ISNUMBER(Inputs!F12),Inputs!F12,0) -> 0 | G23: =IF(ISNUMBER(Inputs!G12),Inputs!G12,0) -> 0 | H23: =IF(ISNUMBER(Inputs!H12),Inputs!H12,0) -> 0 | I23: =IF(ISNUMBER(Inputs!I12),Inputs!I12,0) -> 0 | J23: =IF(ISNUMBER(Inputs!J12),Inputs!J12,0) -> 0
B24: Other Non-Operating Income / (Expense) | C24: =IF(ISNUMBER(Inputs!C13),Inputs!C13,0) -> 0 | D24: =IF(ISNUMBER(Inputs!D13),Inputs!D13,0) -> 0 | E24: =IF(ISNUMBER(Inputs!E13),Inputs!E13,0) -> 0 | F24: =IF(ISNUMBER(Inputs!F13),Inputs!F13,0) -> 0 | G24: =IF(ISNUMBER(Inputs!G13),Inputs!G13,0) -> 0 | H24: =IF(ISNUMBER(Inputs!H13),Inputs!H13,0) -> 0 | I24: =IF(ISNUMBER(Inputs!I13),Inputs!I13,0) -> 0 | J24: =IF(ISNUMBER(Inputs!J13),Inputs!J13,0) -> 0
B25: Earnings Before Tax (EBT) | C25: =C17-C22+C23+C24 -> 0 | D25: =D17-D22+D23+D24 -> 0 | E25: =E17-E22+E23+E24 -> 0 | F25: =F17-F22+F23+F24 -> 0 | G25: =G17-G22+G23+G24 -> 0 | H25: =H17-H22+H23+H24 -> 0 | I25: =I17-I22+I23+I24 -> 0 | J25: =J17-J22+J23+J24 -> 0
B26: Income Tax Expense | C26: =C25*IF(ISNUMBER(Inputs!C14),Inputs!C14,0) -> 0 | D26: =D25*IF(ISNUMBER(Inputs!D14),Inputs!D14,0) -> 0 | E26: =E25*IF(ISNUMBER(Inputs!E14),Inputs!E14,0) -> 0 | F26: =F25*IF(ISNUMBER(Inputs!F14),Inputs!F14,0) -> 0 | G26: =G25*IF(ISNUMBER(Inputs!G14),Inputs!G14,0) -> 0 | H26: =H25*IF(ISNUMBER(Inputs!H14),Inputs!H14,0) -> 0 | I26: =I25*IF(ISNUMBER(Inputs!I14),Inputs!I14,0) -> 0 | J26: =J25*IF(ISNUMBER(Inputs!J14),Inputs!J14,0) -> 0
B27: NET INCOME | C27: =C25-C26 -> 0 | D27: =D25-D26 -> 0 | E27: =E25-E26 -> 0 | F27: =F25-F26 -> 0 | G27: =G25-G26 -> 0 | H27: =H25-H26 -> 0 | I27: =I25-I26 -> 0 | J27: =J25-J26 -> 0
B28: Net Margin % | C28: =IFERROR(C27/C5,"-") -> - | D28: =IFERROR(D27/D5,"-") -> - | E28: =IFERROR(E27/E5,"-") -> - | F28: =IFERROR(F27/F5,"-") -> - | G28: =IFERROR(G27/G5,"-") -> - | H28: =IFERROR(H27/H5,"-") -> - | I28: =IFERROR(I27/I5,"-") -> - | J28: =IFERROR(J27/J5,"-") -> -
B30: PER SHARE DATA
B31: EPS – Basic ($) | C31: =IFERROR(C27/Inputs!C15,"-") -> - | D31: =IFERROR(D27/Inputs!D15,"-") -> - | E31: =IFERROR(E27/Inputs!E15,"-") -> - | F31: =IFERROR(F27/Inputs!F15,"-") -> - | G31: =IFERROR(G27/Inputs!G15,"-") -> - | H31: =IFERROR(H27/Inputs!H15,"-") -> - | I31: =IFERROR(I27/Inputs!I15,"-") -> - | J31: =IFERROR(J27/Inputs!J15,"-") -> -
B32: EPS – Diluted ($) | C32: =IFERROR(C27/Inputs!C16,"-") -> - | D32: =IFERROR(D27/Inputs!D16,"-") -> - | E32: =IFERROR(E27/Inputs!E16,"-") -> - | F32: =IFERROR(F27/Inputs!F16,"-") -> - | G32: =IFERROR(G27/Inputs!G16,"-") -> - | H32: =IFERROR(H27/Inputs!H16,"-") -> - | I32: =IFERROR(I27/Inputs!I16,"-") -> - | J32: =IFERROR(J27/Inputs!J16,"-") -> -

Sheet Balance Sheet
B1: BALANCE SHEET | J1: BACK -->
B3: ($mm) | C3: FY-3 (H) | D3: FY-2 (H) | E3: FY-1 (H) | F3: FY+1 (P) | G3: FY+2 (P) | H3: FY+3 (P) | I3: FY+4 (P) | J3: FY+5 (P)
B4: ASSETS
B5: Current Assets
B6: Cash & Cash Equivalents | C6: =IF(ISNUMBER(Inputs!C18),Inputs!C18,0) -> 0 | D6: =IF(ISNUMBER(Inputs!D18),Inputs!D18,0) -> 0 | E6: =IF(ISNUMBER(Inputs!E18),Inputs!E18,0) -> 0 | F6: =IF(ISNUMBER(Inputs!F18),Inputs!F18,0) -> 0 | G6: =IF(ISNUMBER(Inputs!G18),Inputs!G18,0) -> 0 | H6: =IF(ISNUMBER(Inputs!H18),Inputs!H18,0) -> 0 | I6: =IF(ISNUMBER(Inputs!I18),Inputs!I18,0) -> 0 | J6: =IF(ISNUMBER(Inputs!J18),Inputs!J18,0) -> 0
B7: Accounts Receivable (gross) | C7: =IF(ISNUMBER(Inputs!C19),Inputs!C19,0) -> 0 | D7: =IF(ISNUMBER(Inputs!D19),Inputs!D19,0) -> 0 | E7: =IF(ISNUMBER(Inputs!E19),Inputs!E19,0) -> 0 | F7: =IF(ISNUMBER(Inputs!F19),Inputs!F19,0) -> 0 | G7: =IF(ISNUMBER(Inputs!G19),Inputs!G19,0) -> 0 | H7: =IF(ISNUMBER(Inputs!H19),Inputs!H19,0) -> 0 | I7: =IF(ISNUMBER(Inputs!I19),Inputs!I19,0) -> 0 | J7: =IF(ISNUMBER(Inputs!J19),Inputs!J19,0) -> 0
B8: Less: Allowance for Doubtful Accounts | C8: =IF(ISNUMBER(Inputs!C20),Inputs!C20,0) -> 0 | D8: =IF(ISNUMBER(Inputs!D20),Inputs!D20,0) -> 0 | E8: =IF(ISNUMBER(Inputs!E20),Inputs!E20,0) -> 0 | F8: =IF(ISNUMBER(Inputs!F20),Inputs!F20,0) -> 0 | G8: =IF(ISNUMBER(Inputs!G20),Inputs!G20,0) -> 0 | H8: =IF(ISNUMBER(Inputs!H20),Inputs!H20,0) -> 0 | I8: =IF(ISNUMBER(Inputs!I20),Inputs!I20,0) -> 0 | J8: =IF(ISNUMBER(Inputs!J20),Inputs!J20,0) -> 0
B9: Inventories | C9: =IF(ISNUMBER(Inputs!C21),Inputs!C21,0) -> 0 | D9: =IF(ISNUMBER(Inputs!D21),Inputs!D21,0) -> 0 | E9: =IF(ISNUMBER(Inputs!E21),Inputs!E21,0) -> 0 | F9: =IF(ISNUMBER(Inputs!F21),Inputs!F21,0) -> 0 | G9: =IF(ISNUMBER(Inputs!G21),Inputs!G21,0) -> 0 | H9: =IF(ISNUMBER(Inputs!H21),Inputs!H21,0) -> 0 | I9: =IF(ISNUMBER(Inputs!I21),Inputs!I21,0) -> 0 | J9: =IF(ISNUMBER(Inputs!J21),Inputs!J21,0) -> 0
B10: Prepaid Expenses & Other Current Assets | C10: =IF(ISNUMBER(Inputs!C22),Inputs!C22,0) -> 0 | D10: =IF(ISNUMBER(Inputs!D22),Inputs!D22,0) -> 0 | E10: =IF(ISNUMBER(Inputs!E22),Inputs!E22,0) -> 0 | F10: =IF(ISNUMBER(Inputs!F22),Inputs!F22,0) -> 0 | G10: =IF(ISNUMBER(Inputs!G22),Inputs!G22,0) -> 0 | H10: =IF(ISNUMBER(Inputs!H22),Inputs!H22,0) -> 0 | I10: =IF(ISNUMBER(Inputs!I22),Inputs!I22,0) -> 0 | J10: =IF(ISNUMBER(Inputs!J22),Inputs!J22,0) -> 0
B11: Total Current Assets | C11: =C6+C7-C8+C9+C10 -> 0 | D11: =D6+D7-D8+D9+D10 -> 0 | E11: =E6+E7-E8+E9+E10 -> 0 | F11: =F6+F7-F8+F9+F10 -> 0 | G11: =G6+G7-G8+G9+G10 -> 0 | H11: =H6+H7-H8+H9+H10 -> 0 | I11: =I6+I7-I8+I9+I10 -> 0 | J11: =J6+J7-J8+J9+J10 -> 0
B12: Non-Current Assets
B13: Property, Plant & Equipment (gross) | C13: =IF(ISNUMBER(Inputs!C23),Inputs!C23,0) -> 0 | D13: =IF(ISNUMBER(Inputs!D23),Inputs!D23,0) -> 0 | E13: =IF(ISNUMBER(Inputs!E23),Inputs!E23,0) -> 0 | F13: =IF(ISNUMBER(Inputs!F23),Inputs!F23,0) -> 0 | G13: =IF(ISNUMBER(Inputs!G23),Inputs!G23,0) -> 0 | H13: =IF(ISNUMBER(Inputs!H23),Inputs!H23,0) -> 0 | I13: =IF(ISNUMBER(Inputs!I23),Inputs!I23,0) -> 0 | J13: =IF(ISNUMBER(Inputs!J23),Inputs!J23,0) -> 0
B14: Less: Accumulated Depreciation | C14: =IF(ISNUMBER(Inputs!C24),Inputs!C24,0) -> 0 | D14: =IF(ISNUMBER(Inputs!D24),Inputs!D24,0) -> 0 | E14: =IF(ISNUMBER(Inputs!E24),Inputs!E24,0) -> 0 | F14: =IF(ISNUMBER(Inputs!F24),Inputs!F24,0) -> 0 | G14: =IF(ISNUMBER(Inputs!G24),Inputs!G24,0) -> 0 | H14: =IF(ISNUMBER(Inputs!H24),Inputs!H24,0) -> 0 | I14: =IF(ISNUMBER(Inputs!I24),Inputs!I24,0) -> 0 | J14: =IF(ISNUMBER(Inputs!J24),Inputs!J24,0) -> 0
B15: Net PP&E | C15: =C13-C14 -> 0 | D15: =D13-D14 -> 0 | E15: =E13-E14 -> 0 | F15: =F13-F14 -> 0 | G15: =G13-G14 -> 0 | H15: =H13-H14 -> 0 | I15: =I13-I14 -> 0 | J15: =J13-J14 -> 0
B16: Intangible Assets (net) | C16: =IF(ISNUMBER(Inputs!C25),Inputs!C25,0) -> 0 | D16: =IF(ISNUMBER(Inputs!D25),Inputs!D25,0) -> 0 | E16: =IF(ISNUMBER(Inputs!E25),Inputs!E25,0) -> 0 | F16: =IF(ISNUMBER(Inputs!F25),Inputs!F25,0) -> 0 | G16: =IF(ISNUMBER(Inputs!G25),Inputs!G25,0) -> 0 | H16: =IF(ISNUMBER(Inputs!H25),Inputs!H25,0) -> 0 | I16: =IF(ISNUMBER(Inputs!I25),Inputs!I25,0) -> 0 | J16: =IF(ISNUMBER(Inputs!J25),Inputs!J25,0) -> 0
B17: Goodwill | C17: =IF(ISNUMBER(Inputs!C26),Inputs!C26,0) -> 0 | D17: =IF(ISNUMBER(Inputs!D26),Inputs!D26,0) -> 0 | E17: =IF(ISNUMBER(Inputs!E26),Inputs!E26,0) -> 0 | F17: =IF(ISNUMBER(Inputs!F26),Inputs!F26,0) -> 0 | G17: =IF(ISNUMBER(Inputs!G26),Inputs!G26,0) -> 0 | H17: =IF(ISNUMBER(Inputs!H26),Inputs!H26,0) -> 0 | I17: =IF(ISNUMBER(Inputs!I26),Inputs!I26,0) -> 0 | J17: =IF(ISNUMBER(Inputs!J26),Inputs!J26,0) -> 0
B18: Other Non-Current Assets | C18: =IF(ISNUMBER(Inputs!C27),Inputs!C27,0) -> 0 | D18: =IF(ISNUMBER(Inputs!D27),Inputs!D27,0) -> 0 | E18: =IF(ISNUMBER(Inputs!E27),Inputs!E27,0) -> 0 | F18: =IF(ISNUMBER(Inputs!F27),Inputs!F27,0) -> 0 | G18: =IF(ISNUMBER(Inputs!G27),Inputs!G27,0) -> 0 | H18: =IF(ISNUMBER(Inputs!H27),Inputs!H27,0) -> 0 | I18: =IF(ISNUMBER(Inputs!I27),Inputs!I27,0) -> 0 | J18: =IF(ISNUMBER(Inputs!J27),Inputs!J27,0) -> 0
B19: TOTAL ASSETS | C19: =C11+C15+C16+C17+C18 -> 0 | D19: =D11+D15+D16+D17+D18 -> 0 | E19: =E11+E15+E16+E17+E18 -> 0 | F19: =F11+F15+F16+F17+F18 -> 0 | G19: =G11+G15+G16+G17+G18 -> 0 | H19: =H11+H15+H16+H17+H18 -> 0 | I19: =I11+I15+I16+I17+I18 -> 0 | J19: =J11+J15+J16+J17+J18 -> 0
B21: LIABILITIES
B22: Current Liabilities
B23: Accounts Payable | C23: =IF(ISNUMBER(Inputs!C29),Inputs!C29,0) -> 0 | D23: =IF(ISNUMBER(Inputs!D29),Inputs!D29,0) -> 0 | E23: =IF(ISNUMBER(Inputs!E29),Inputs!E29,0) -> 0 | F23: =IF(ISNUMBER(Inputs!F29),Inputs!F29,0) -> 0 | G23: =IF(ISNUMBER(Inputs!G29),Inputs!G29,0) -> 0 | H23: =IF(ISNUMBER(Inputs!H29),Inputs!H29,0) -> 0 | I23: =IF(ISNUMBER(Inputs!I29),Inputs!I29,0) -> 0 | J23: =IF(ISNUMBER(Inputs!J29),Inputs!J29,0) -> 0
B24: Accrued Liabilities | C24: =IF(ISNUMBER(Inputs!C30),Inputs!C30,0) -> 0 | D24: =IF(ISNUMBER(Inputs!D30),Inputs!D30,0) -> 0 | E24: =IF(ISNUMBER(Inputs!E30),Inputs!E30,0) -> 0 | F24: =IF(ISNUMBER(Inputs!F30),Inputs!F30,0) -> 0 | G24: =IF(ISNUMBER(Inputs!G30),Inputs!G30,0) -> 0 | H24: =IF(ISNUMBER(Inputs!H30),Inputs!H30,0) -> 0 | I24: =IF(ISNUMBER(Inputs!I30),Inputs!I30,0) -> 0 | J24: =IF(ISNUMBER(Inputs!J30),Inputs!J30,0) -> 0
B25: Short-Term Debt / Current Portion LT Debt | C25: =IF(ISNUMBER(Inputs!C31),Inputs!C31,0) -> 0 | D25: =IF(ISNUMBER(Inputs!D31),Inputs!D31,0) -> 0 | E25: =IF(ISNUMBER(Inputs!E31),Inputs!E31,0) -> 0 | F25: =IF(ISNUMBER(Inputs!F31),Inputs!F31,0) -> 0 | G25: =IF(ISNUMBER(Inputs!G31),Inputs!G31,0) -> 0 | H25: =IF(ISNUMBER(Inputs!H31),Inputs!H31,0) -> 0 | I25: =IF(ISNUMBER(Inputs!I31),Inputs!I31,0) -> 0 | J25: =IF(ISNUMBER(Inputs!J31),Inputs!J31,0) -> 0
B26: Deferred Revenue (Current) | C26: =IF(ISNUMBER(Inputs!C32),Inputs!C32,0) -> 0 | D26: =IF(ISNUMBER(Inputs!D32),Inputs!D32,0) -> 0 | E26: =IF(ISNUMBER(Inputs!E32),Inputs!E32,0) -> 0 | F26: =IF(ISNUMBER(Inputs!F32),Inputs!F32,0) -> 0 | G26: =IF(ISNUMBER(Inputs!G32),Inputs!G32,0) -> 0 | H26: =IF(ISNUMBER(Inputs!H32),Inputs!H32,0) -> 0 | I26: =IF(ISNUMBER(Inputs!I32),Inputs!I32,0) -> 0 | J26: =IF(ISNUMBER(Inputs!J32),Inputs!J32,0) -> 0
B27: Other Current Liabilities | C27: =IF(ISNUMBER(Inputs!C33),Inputs!C33,0) -> 0 | D27: =IF(ISNUMBER(Inputs!D33),Inputs!D33,0) -> 0 | E27: =IF(ISNUMBER(Inputs!E33),Inputs!E33,0) -> 0 | F27: =IF(ISNUMBER(Inputs!F33),Inputs!F33,0) -> 0 | G27: =IF(ISNUMBER(Inputs!G33),Inputs!G33,0) -> 0 | H27: =IF(ISNUMBER(Inputs!H33),Inputs!H33,0) -> 0 | I27: =IF(ISNUMBER(Inputs!I33),Inputs!I33,0) -> 0 | J27: =IF(ISNUMBER(Inputs!J33),Inputs!J33,0) -> 0
B28: Total Current Liabilities | C28: =C23+C24+C25+C26+C27 -> 0 | D28: =D23+D24+D25+D26+D27 -> 0 | E28: =E23+E24+E25+E26+E27 -> 0 | F28: =F23+F24+F25+F26+F27 -> 0 | G28: =G23+G24+G25+G26+G27 -> 0 | H28: =H23+H24+H25+H26+H27 -> 0 | I28: =I23+I24+I25+I26+I27 -> 0 | J28: =J23+J24+J25+J26+J27 -> 0
B29: Non-Current Liabilities
B30: Long-Term Debt (net of current portion) | C30: =IF(ISNUMBER(Inputs!C34),Inputs!C34,0) -> 0 | D30: =IF(ISNUMBER(Inputs!D34),Inputs!D34,0) -> 0 | E30: =IF(ISNUMBER(Inputs!E34),Inputs!E34,0) -> 0 | F30: =IF(ISNUMBER(Inputs!F34),Inputs!F34,0) -> 0 | G30: =IF(ISNUMBER(Inputs!G34),Inputs!G34,0) -> 0 | H30: =IF(ISNUMBER(Inputs!H34),Inputs!H34,0) -> 0 | I30: =IF(ISNUMBER(Inputs!I34),Inputs!I34,0) -> 0 | J30: =IF(ISNUMBER(Inputs!J34),Inputs!J34,0) -> 0
B31: Deferred Tax Liabilities | C31: =IF(ISNUMBER(Inputs!C35),Inputs!C35,0) -> 0 | D31: =IF(ISNUMBER(Inputs!D35),Inputs!D35,0) -> 0 | E31: =IF(ISNUMBER(Inputs!E35),Inputs!E35,0) -> 0 | F31: =IF(ISNUMBER(Inputs!F35),Inputs!F35,0) -> 0 | G31: =IF(ISNUMBER(Inputs!G35),Inputs!G35,0) -> 0 | H31: =IF(ISNUMBER(Inputs!H35),Inputs!H35,0) -> 0 | I31: =IF(ISNUMBER(Inputs!I35),Inputs!I35,0) -> 0 | J31: =IF(ISNUMBER(Inputs!J35),Inputs!J35,0) -> 0
B32: Other Non-Current Liabilities | C32: =IF(ISNUMBER(Inputs!C36),Inputs!C36,0) -> 0 | D32: =IF(ISNUMBER(Inputs!D36),Inputs!D36,0) -> 0 | E32: =IF(ISNUMBER(Inputs!E36),Inputs!E36,0) -> 0 | F32: =IF(ISNUMBER(Inputs!F36),Inputs!F36,0) -> 0 | G32: =IF(ISNUMBER(Inputs!G36),Inputs!G36,0) -> 0 | H32: =IF(ISNUMBER(Inputs!H36),Inputs!H36,0) -> 0 | I32: =IF(ISNUMBER(Inputs!I36),Inputs!I36,0) -> 0 | J32: =IF(ISNUMBER(Inputs!J36),Inputs!J36,0) -> 0
B33: Total Non-Current Liabilities | C33: =C30+C31+C32 -> 0 | D33: =D30+D31+D32 -> 0 | E33: =E30+E31+E32 -> 0 | F33: =F30+F31+F32 -> 0 | G33: =G30+G31+G32 -> 0 | H33: =H30+H31+H32 -> 0 | I33: =I30+I31+I32 -> 0 | J33: =J30+J31+J32 -> 0
B34: TOTAL LIABILITIES | C34: =C28+C33 -> 0 | D34: =D28+D33 -> 0 | E34: =E28+E33 -> 0 | F34: =F28+F33 -> 0 | G34: =G28+G33 -> 0 | H34: =H28+H33 -> 0 | I34: =I28+I33 -> 0 | J34: =J28+J33 -> 0
B36: SHAREHOLDERS' EQUITY
B37: Common Stock & Additional Paid-In Capital | C37: =IF(ISNUMBER(Inputs!C37),Inputs!C37,0) -> 0 | D37: =IF(ISNUMBER(Inputs!D37),Inputs!D37,0) -> 0 | E37: =IF(ISNUMBER(Inputs!E37),Inputs!E37,0) -> 0 | F37: =IF(ISNUMBER(Inputs!F37),Inputs!F37,0) -> 0 | G37: =IF(ISNUMBER(Inputs!G37),Inputs!G37,0) -> 0 | H37: =IF(ISNUMBER(Inputs!H37),Inputs!H37,0) -> 0 | I37: =IF(ISNUMBER(Inputs!I37),Inputs!I37,0) -> 0 | J37: =IF(ISNUMBER(Inputs!J37),Inputs!J37,0) -> 0
B38: Retained Earnings | C38: =IF(ISNUMBER(Inputs!C38),Inputs!C38,0)+'Income Statement'!C27 -> 0 | D38: =IF(ISNUMBER(Inputs!D38),Inputs!D38,0)+'Income Statement'!D27 -> 0 | E38: =IF(ISNUMBER(Inputs!E38),Inputs!E38,0)+'Income Statement'!E27 -> 0 | F38: =IF(ISNUMBER(Inputs!F38),Inputs!F38,0)+'Income Statement'!F27 -> 0 | G38: =IF(ISNUMBER(Inputs!G38),Inputs!G38,0)+'Income Statement'!G27 -> 0 | H38: =IF(ISNUMBER(Inputs!H38),Inputs!H38,0)+'Income Statement'!H27 -> 0 | I38: =IF(ISNUMBER(Inputs!I38),Inputs!I38,0)+'Income Statement'!I27 -> 0 | J38: =IF(ISNUMBER(Inputs!J38),Inputs!J38,0)+'Income Statement'!J27 -> 0
B39: Accumulated Other Comprehensive Income/(Loss) | C39: =IF(ISNUMBER(Inputs!C39),Inputs!C39,0) -> 0 | D39: =IF(ISNUMBER(Inputs!D39),Inputs!D39,0) -> 0 | E39: =IF(ISNUMBER(Inputs!E39),Inputs!E39,0) -> 0 | F39: =IF(ISNUMBER(Inputs!F39),Inputs!F39,0) -> 0 | G39: =IF(ISNUMBER(Inputs!G39),Inputs!G39,0) -> 0 | H39: =IF(ISNUMBER(Inputs!H39),Inputs!H39,0) -> 0 | I39: =IF(ISNUMBER(Inputs!I39),Inputs!I39,0) -> 0 | J39: =IF(ISNUMBER(Inputs!J39),Inputs!J39,0) -> 0
B40: Treasury Stock (at cost) | C40: =IF(ISNUMBER(Inputs!C40),Inputs!C40,0) -> 0 | D40: =IF(ISNUMBER(Inputs!D40),Inputs!D40,0) -> 0 | E40: =IF(ISNUMBER(Inputs!E40),Inputs!E40,0) -> 0 | F40: =IF(ISNUMBER(Inputs!F40),Inputs!F40,0) -> 0 | G40: =IF(ISNUMBER(Inputs!G40),Inputs!G40,0) -> 0 | H40: =IF(ISNUMBER(Inputs!H40),Inputs!H40,0) -> 0 | I40: =IF(ISNUMBER(Inputs!I40),Inputs!I40,0) -> 0 | J40: =IF(ISNUMBER(Inputs!J40),Inputs!J40,0) -> 0
B41: TOTAL SHAREHOLDERS' EQUITY | C41: =C37+C38+C39-C40 -> 0 | D41: =D37+D38+D39-D40 -> 0 | E41: =E37+E38+E39-E40 -> 0 | F41: =F37+F38+F39-F40 -> 0 | G41: =G37+G38+G39-G40 -> 0 | H41: =H37+H38+H39-H40 -> 0 | I41: =I37+I38+I39-I40 -> 0 | J41: =J37+J38+J39-J40 -> 0
B42: TOTAL LIABILITIES & EQUITY | C42: =C34+C41 -> 0 | D42: =D34+D41 -> 0 | E42: =E34+E41 -> 0 | F42: =F34+F41 -> 0 | G42: =G34+G41 -> 0 | H42: =H34+H41 -> 0 | I42: =I34+I41 -> 0 | J42: =J34+J41 -> 0
B44: BALANCE SHEET CHECK ✔ (Highlights RED if out of balance)
...

Sheet Cash Flow Statement
B1: CASH FLOW STATEMENT | J1: BACK -->
B3: ($mm) | C3: FY-3 (H) | D3: FY-2 (H) | E3: FY-1 (H) | F3: FY+1 (P) | G3: FY+2 (P) | H3: FY+3 (P) | I3: FY+4 (P) | J3: FY+5 (P)
B4: OPERATING ACTIVITIES
B5: Net Income | C5: ='Income Statement'!C27 -> 0 | D5: ='Income Statement'!D27 -> 0 | E5: ='Income Statement'!E27 -> 0 | F5: ='Income Statement'!F27 -> 0 | G5: ='Income Statement'!G27 -> 0 | H5: ='Income Statement'!H27 -> 0 | I5: ='Income Statement'!I27 -> 0 | J5: ='Income Statement'!J27 -> 0
B6: Non-Cash Adjustments
B7: Add: Depreciation & Amortization | C7: ='Income Statement'!C15 -> 0 | D7: ='Income Statement'!D15 -> 0 | E7: ='Income Statement'!E15 -> 0 | F7: ='Income Statement'!F15 -> 0 | G7: ='Income Statement'!G15 -> 0 | H7: ='Income Statement'!H15 -> 0 | I7: ='Income Statement'!I15 -> 0 | J7: ='Income Statement'!J15 -> 0
B8: Add: Stock-Based Compensation | C8: =IF(ISNUMBER(Inputs!C19),Inputs!C19,0) -> 0 | D8: =IF(ISNUMBER(Inputs!D19),Inputs!D19,0) -> 0 | E8: =IF(ISNUMBER(Inputs!E19),Inputs!E19,0) -> 0 | F8: =IF(ISNUMBER(Inputs!F19),Inputs!F19,0) -> 0 | G8: =IF(ISNUMBER(Inputs!G19),Inputs!G19,0) -> 0 | H8: =IF(ISNUMBER(Inputs!H19),Inputs!H19,0) -> 0 | I8: =IF(ISNUMBER(Inputs!I19),Inputs!I19,0) -> 0 | J8: =IF(ISNUMBER(Inputs!J19),Inputs!J19,0) -> 0
B9: Add: Amortization of Debt Issuance Costs | C9: =IF(ISNUMBER(Inputs!C20),Inputs!C20,0) -> 0 | D9: =IF(ISNUMBER(Inputs!D20),Inputs!D20,0) -> 0 | E9: =IF(ISNUMBER(Inputs!E20),Inputs!E20,0) -> 0 | F9: =IF(ISNUMBER(Inputs!F20),Inputs!F20,0) -> 0 | G9: =IF(ISNUMBER(Inputs!G20),Inputs!G20,0) -> 0 | H9: =IF(ISNUMBER(Inputs!H20),Inputs!H20,0) -> 0 | I9: =IF(ISNUMBER(Inputs!I20),Inputs!I20,0) -> 0 | J9: =IF(ISNUMBER(Inputs!J20),Inputs!J20,0) -> 0
B10: Changes in Working Capital
B11: (Increase)/Decrease in Accounts Receivable | C11: =0 -> 0 | D11: =-('Balance Sheet'!D7-'Balance Sheet'!C7) -> 0 | E11: =-('Balance Sheet'!E7-'Balance Sheet'!D7) -> 0 | F11: =-('Balance Sheet'!F7-'Balance Sheet'!E7) -> 0 | G11: =-('Balance Sheet'!G7-'Balance Sheet'!F7) -> 0 | H11: =-('Balance Sheet'!H7-'Balance Sheet'!G7) -> 0 | I11: =-('Balance Sheet'!I7-'Balance Sheet'!H7) -> 0 | J11: =-('Balance Sheet'!J7-'Balance Sheet'!I7) -> 0
B12: (Increase)/Decrease in Inventories | C12: =0 -> 0 | D12: =-('Balance Sheet'!D9-'Balance Sheet'!C9) -> 0 | E12: =-('Balance Sheet'!E9-'Balance Sheet'!D9) -> 0 | F12: =-('Balance Sheet'!F9-'Balance Sheet'!E9) -> 0 | G12: =-('Balance Sheet'!G9-'Balance Sheet'!F9) -> 0 | H12: =-('Balance Sheet'!H9-'Balance Sheet'!G9) -> 0 | I12: =-('Balance Sheet'!I9-'Balance Sheet'!H9) -> 0 | J12: =-('Balance Sheet'!J9-'Balance Sheet'!I9) -> 0
B13: Increase/(Decrease) in Accounts Payable | C13: =0 -> 0 | D13: ='Balance Sheet'!D23-'Balance Sheet'!C23 -> 0 | E13: ='Balance Sheet'!E23-'Balance Sheet'!D23 -> 0 | F13: ='Balance Sheet'!F23-'Balance Sheet'!E23 -> 0 | G13: ='Balance Sheet'!G23-'Balance Sheet'!F23 -> 0 | H13: ='Balance Sheet'!H23-'Balance Sheet'!G23 -> 0 | I13: ='Balance Sheet'!I23-'Balance Sheet'!H23 -> 0 | J13: ='Balance Sheet'!J23-'Balance Sheet'!I23 -> 0
B14: NET CASH FROM OPERATIONS (CFO) | C14: =C5+C7+C8+C9+C11+C12+C13 -> 0 | D14: =D5+D7+D8+D9+D11+D12+D13 -> 0 | E14: =E5+E7+E8+E9+E11+E12+E13 -> 0 | F14: =F5+F7+F8+F9+F11+F12+F13 -> 0 | G14: =G5+G7+G8+G9+G11+G12+G13 -> 0 | H14: =H5+H7+H8+H9+H11+H12+H13 -> 0 | I14: =I5+I7+I8+I9+I11+I12+I13 -> 0 | J14: =J5+J7+J8+J9+J11+J12+J13 -> 0
B16: INVESTING ACTIVITIES
B17: Capital Expenditures | C17: =-IF(ISNUMBER(Inputs!C21),Inputs!C21,0) -> 0 | D17: =-IF(ISNUMBER(Inputs!D21),Inputs!D21,0) -> 0 | E17: =-IF(ISNUMBER(Inputs!E21),Inputs!E21,0) -> 0 | F17: =-IF(ISNUMBER(Inputs!F21),Inputs!F21,0) -> 0 | G17: =-IF(ISNUMBER(Inputs!G21),Inputs!G21,0) -> 0 | H17: =-IF(ISNUMBER(Inputs!H21),Inputs!H21,0) -> 0 | I17: =-IF(ISNUMBER(Inputs!I21),Inputs!I21,0) -> 0 | J17: =-IF(ISNUMBER(Inputs!J21),Inputs!J21,0) -> 0
B18: Acquisitions (net of cash) | C18: =-IF(ISNUMBER(Inputs!C22),Inputs!C22,0) -> 0 | D18: =-IF(ISNUMBER(Inputs!D22),Inputs!D22,0) -> 0 | E18: =-IF(ISNUMBER(Inputs!E22),Inputs!E22,0) -> 0 | F18: =-IF(ISNUMBER(Inputs!F22),Inputs!F22,0) -> 0 | G18: =-IF(ISNUMBER(Inputs!G22),Inputs!G22,0) -> 0 | H18: =-IF(ISNUMBER(Inputs!H22),Inputs!H22,0) -> 0 | I18: =-IF(ISNUMBER(Inputs!I22),Inputs!I22,0) -> 0 | J18: =-IF(ISNUMBER(Inputs!J22),Inputs!J22,0) -> 0
B19: Proceeds from Asset Sales | C19: =IF(ISNUMBER(Inputs!C23),Inputs!C23,0) -> 0 | D19: =IF(ISNUMBER(Inputs!D23),Inputs!D23,0) -> 0 | E19: =IF(ISNUMBER(Inputs!E23),Inputs!E23,0) -> 0 | F19: =IF(ISNUMBER(Inputs!F23),Inputs!F23,0) -> 0 | G19: =IF(ISNUMBER(Inputs!G23),Inputs!G23,0) -> 0 | H19: =IF(ISNUMBER(Inputs!H23),Inputs!H23,0) -> 0 | I19: =IF(ISNUMBER(Inputs!I23),Inputs!I23,0) -> 0 | J19: =IF(ISNUMBER(Inputs!J23),Inputs!J23,0) -> 0
B20: NET CASH FROM INVESTING (CFI) | C20: =C17+C18+C19 -> 0 | D20: =D17+D18+D19 -> 0 | E20: =E17+E18+E19 -> 0 | F20: =F17+F18+F19 -> 0 | G20: =G17+G18+G19 -> 0 | H20: =H17+H18+H19 -> 0 | I20: =I17+I18+I19 -> 0 | J20: =J17+J18+J19 -> 0
B22: FINANCING ACTIVITIES
B23: Net Borrowings / (Repayments) | C23: =IF(ISNUMBER(Inputs!C24),Inputs!C24,0) -> 0 | D23: =IF(ISNUMBER(Inputs!D24),Inputs!D24,0) -> 0 | E23: =IF(ISNUMBER(Inputs!E24),Inputs!E24,0) -> 0 | F23: =IF(ISNUMBER(Inputs!F24),Inputs!F24,0) -> 0 | G23: =IF(ISNUMBER(Inputs!G24),Inputs!G24,0) -> 0 | H23: =IF(ISNUMBER(Inputs!H24),Inputs!H24,0) -> 0 | I23: =IF(ISNUMBER(Inputs!I24),Inputs!I24,0) -> 0 | J23: =IF(ISNUMBER(Inputs!J24),Inputs!J24,0) -> 0
B24: Dividends Paid | C24: =-IF(ISNUMBER(Inputs!C25),Inputs!C25,0) -> 0 | D24: =-IF(ISNUMBER(Inputs!D25),Inputs!D25,0) -> 0 | E24: =-IF(ISNUMBER(Inputs!E25),Inputs!E25,0) -> 0 | F24: =-IF(ISNUMBER(Inputs!F25),Inputs!F25,0) -> 0 | G24: =-IF(ISNUMBER(Inputs!G25),Inputs!G25,0) -> 0 | H24: =-IF(ISNUMBER(Inputs!H25),Inputs!H25,0) -> 0 | I24: =-IF(ISNUMBER(Inputs!I25),Inputs!I25,0) -> 0 | J24: =-IF(ISNUMBER(Inputs!J25),Inputs!J25,0) -> 0
B25: Share Repurchases | C25: =-IF(ISNUMBER(Inputs!C26),Inputs!C26,0) -> 0 | D25: =-IF(ISNUMBER(Inputs!D26),Inputs!D26,0) -> 0 | E25: =-IF(ISNUMBER(Inputs!E26),Inputs!E26,0) -> 0 | F25: =-IF(ISNUMBER(Inputs!F26),Inputs!F26,0) -> 0 | G25: =-IF(ISNUMBER(Inputs!G26),Inputs!G26,0) -> 0 | H25: =-IF(ISNUMBER(Inputs!H26),Inputs!H26,0) -> 0 | I25: =-IF(ISNUMBER(Inputs!I26),Inputs!I26,0) -> 0 | J25: =-IF(ISNUMBER(Inputs!J26),Inputs!J26,0) -> 0
B26: Proceeds from Stock Issuance | C26: =IF(ISNUMBER(Inputs!C27),Inputs!C27,0) -> 0 | D26: =IF(ISNUMBER(Inputs!D27),Inputs!D27,0) -> 0 | E26: =IF(ISNUMBER(Inputs!E27),Inputs!E27,0) -> 0 | F26: =IF(ISNUMBER(Inputs!F27),Inputs!F27,0) -> 0 | G26: =IF(ISNUMBER(Inputs!G27),Inputs!G27,0) -> 0 | H26: =IF(ISNUMBER(Inputs!H27),Inputs!H27,0) -> 0 | I26: =IF(ISNUMBER(Inputs!I27),Inputs!I27,0) -> 0 | J26: =IF(ISNUMBER(Inputs!J27),Inputs!J27,0) -> 0
B27: NET CASH FROM FINANCING (CFF) | C27: =C23+C24+C25+C26 -> 0 | D27: =D23+D24+D25+D26 -> 0 | E27: =E23+E24+E25+E26 -> 0 | F27: =F23+F24+F25+F26 -> 0 | G27: =G23+G24+G25+G26 -> 0 | H27: =H23+H24+H25+H26 -> 0 | I27: =I23+I24+I25+I26 -> 0 | J27: =J23+J24+J25+J26 -> 0
B29: CASH RECONCILIATION
B30: Beginning Cash Balance | C30: ='Balance Sheet'!C6 -> 0 | D30: ='Balance Sheet'!C6 -> 0 | E30: ='Balance Sheet'!D6 -> 0 | F30: ='Balance Sheet'!E6 -> 0 | G30: ='Balance Sheet'!F6 -> 0 | H30: ='Balance Sheet'!G6 -> 0 | I30: ='Balance Sheet'!H6 -> 0 | J30: ='Balance Sheet'!I6 -> 0
B31: Net Change in Cash | C31: =C14+C20+C27 -> 0 | D31: =D14+D20+D27 -> 0 | E31: =E14+E20+E27 -> 0 | F31: =F14+F20+F27 -> 0 | G31: =G14+G20+G27 -> 0 | H31: =H14+H20+H27 -> 0 | I31: =I14+I20+I27 -> 0 | J31: =J14+J20+J27 -> 0
B32: ENDING CASH BALANCE | C32: =C30+C31 -> 0 | D32: =D30+D31 -> 0 | E32: =E30+E31 -> 0 | F32: =F30+F31 -> 0 | G32: =G30+G31 -> 0 | H32: =H30+H31 -> 0 | I32: =I30+I31 -> 0 | J32: =J30+J31 -> 0
B33: FREE CASH FLOW (FCF) | C33: =C14+C17 -> 0 | D33: =D14+D17 -> 0 | E33: =E14+E17 -> 0 | F33: =F14+F17 -> 0 | G33: =G14+G17 -> 0 | H33: =H14+H17 -> 0 | I33: =I14+I17 -> 0 | J33: =J14+J17 -> 0
B34: FCF Margin % | C34: =IFERROR(C33/'Income Statement'!C5,"-") -> - | D34: =IFERROR(D33/'Income Statement'!D5,"-") -> - | E34: =IFERROR(E33/'Income Statement'!E5,"-") -> - | F34: =IFERROR(F33/'Income Statement'!F5,"-") -> - | G34: =IFERROR(G33/'Income Statement'!G5,"-") -> - | H34: =IFERROR(H33/'Income Statement'!H5,"-") -> - | I34: =IFERROR(I33/'Income Statement'!I5,"-") -> - | J34: =IFERROR(J33/'Income Statement'!J5,"-") -> -

Sheet Supporting Schedules
B1: SUPPORTING SCHEDULES | J1: BACK -->
B3: SCHEDULE | C3: FY-3 (H) | D3: FY-2 (H) | E3: FY-1 (H) | F3: FY+1 (P) | G3: FY+2 (P) | H3: FY+3 (P) | I3: FY+4 (P) | J3: FY+5 (P)
B4: PP&E ROLL-FORWARD SCHEDULE
B5: Beginning Gross PP&E | C5: ='Balance Sheet'!C13 -> 0 | D5: ='Balance Sheet'!D13 -> 0 | E5: ='Balance Sheet'!E13 -> 0 | F5: ='Balance Sheet'!F13 -> 0 | G5: ='Balance Sheet'!G13 -> 0 | H5: ='Balance Sheet'!H13 -> 0 | I5: ='Balance Sheet'!I13 -> 0 | J5: ='Balance Sheet'!J13 -> 0
B6: Plus: Capital Expenditures | C6: =-('Cash Flow Statement'!C17) -> 0 | D6: =-('Cash Flow Statement'!D17) -> 0 | E6: =-('Cash Flow Statement'!E17) -> 0 | F6: =-('Cash Flow Statement'!F17) -> 0 | G6: =-('Cash Flow Statement'!G17) -> 0 | H6: =-('Cash Flow Statement'!H17) -> 0 | I6: =-('Cash Flow Statement'!I17) -> 0 | J6: =-('Cash Flow Statement'!J17) -> 0
B7: Less: Disposals / Write-offs
B8: Ending Gross PP&E
B9: Beginning Accumulated Depreciation | C9: ='Balance Sheet'!C14 -> 0 | D9: ='Balance Sheet'!D14 -> 0 | E9: ='Balance Sheet'!E14 -> 0 | F9: ='Balance Sheet'!F14 -> 0 | G9: ='Balance Sheet'!G14 -> 0 | H9: ='Balance Sheet'!H14 -> 0 | I9: ='Balance Sheet'!I14 -> 0 | J9: ='Balance Sheet'!J14 -> 0
B10: Plus: Depreciation Expense | C10: ='Income Statement'!C15 -> 0 | D10: ='Income Statement'!D15 -> 0 | E10: ='Income Statement'!E15 -> 0 | F10: ='Income Statement'!F15 -> 0 | G10: ='Income Statement'!G15 -> 0 | H10: ='Income Statement'!H15 -> 0 | I10: ='Income Statement'!I15 -> 0 | J10: ='Income Statement'!J15 -> 0
B11: Less: Accumulated Dep. on Disposals
B12: Ending Accumulated Depreciation
B13: Net PP&E (Ending) | C13: ='Balance Sheet'!C15 -> 0 | D13: ='Balance Sheet'!D15 -> 0 | E13: ='Balance Sheet'!E15 -> 0 | F13: ='Balance Sheet'!F15 -> 0 | G13: ='Balance Sheet'!G15 -> 0 | H13: ='Balance Sheet'!H15 -> 0 | I13: ='Balance Sheet'!I15 -> 0 | J13: ='Balance Sheet'!J15 -> 0
B15: DEBT SCHEDULE
B16: Revolver – Beginning Balance
B17: Revolver – Draws / (Repayments)
B18: Revolver – Ending Balance
B19: Term Loan A – Beginning Balance
B20: Term Loan A – Scheduled Amortization
B21: Term Loan A – Ending Balance
B22: Senior Notes – Principal Balance
B23: Total Debt (Gross)
B24: Less: Cash & Equivalents
B25: Net Debt
B26: LTM EBITDA (Reference)
... B29: WORKING CAPITAL ANALYSIS
B30: Accounts Receivable (net) | C30: ='Balance Sheet'!C7-'Balance Sheet'!C8 -> 0 | D30: ='Balance Sheet'!D7-'Balance Sheet'!D8 -> 0 | E30: ='Balance Sheet'!E7-'Balance Sheet'!E8 -> 0 | F30: ='Balance Sheet'!F7-'Balance Sheet'!F8 -> 0 | G30: ='Balance Sheet'!G7-'Balance Sheet'!G8 -> 0 | H30: ='Balance Sheet'!H7-'Balance Sheet'!H8 -> 0 | I30: ='Balance Sheet'!I7-'Balance Sheet'!I8 -> 0 | J30: ='Balance Sheet'!J7-'Balance Sheet'!J8 -> 0
B31: Inventories | C31: ='Balance Sheet'!C9 -> 0 | D31: ='Balance Sheet'!D9 -> 0 | E31: ='Balance Sheet'!E9 -> 0 | F31: ='Balance Sheet'!F9 -> 0 | G31: ='Balance Sheet'!G9 -> 0 | H31: ='Balance Sheet'!H9 -> 0 | I31: ='Balance Sheet'!I9 -> 0 | J31: ='Balance Sheet'!J9 -> 0
B32: Prepaid Expenses & Other CA | C32: ='Balance Sheet'!C10 -> 0 | D32: ='Balance Sheet'!D10 -> 0 | E32: ='Balance Sheet'!E10 -> 0 | F32: ='Balance Sheet'!F10 -> 0 | G32: ='Balance Sheet'!G10 -> 0 | H32: ='Balance Sheet'!H10 -> 0 | I32: ='Balance Sheet'!I10 -> 0 | J32: ='Balance Sheet'!J10 -> 0
B33: Accounts Payable | C33: ='Balance Sheet'!C23 -> 0 | D33: ='Balance Sheet'!D23 -> 0 | E33: ='Balance Sheet'!E23 -> 0 | F33: ='Balance Sheet'!F23 -> 0 | G33: ='Balance Sheet'!G23 -> 0 | H33: ='Balance Sheet'!H23 -> 0 | I33: ='Balance Sheet'!I23 -> 0 | J33: ='Balance Sheet'!J23 -> 0
B34: Accrued Liabilities | C34: ='Balance Sheet'!C24 -> 0 | D34: ='Balance Sheet'!D24 -> 0 | E34: ='Balance Sheet'!E24 -> 0 | F34: ='Balance Sheet'!F24 -> 0 | G34: ='Balance Sheet'!G24 -> 0 | H34: ='Balance Sheet'!H24 -> 0 | I34: ='Balance Sheet'!I24 -> 0 | J34: ='Balance Sheet'!J24 -> 0
B35: Deferred Revenue | C35: ='Balance Sheet'!C26 -> 0 | D35: ='Balance Sheet'!D26 -> 0 | E35: ='Balance Sheet'!E26 -> 0 | F35: ='Balance Sheet'!F26 -> 0 | G35: ='Balance Sheet'!G26 -> 0 | H35: ='Balance Sheet'!H26 -> 0 | I35: ='Balance Sheet'!I26 -> 0 | J35: ='Balance Sheet'!J26 -> 0
B36: Net Working Capital
B37: DSO (days)
B38: DIO (days)
B39: DPO (days)
B40: Cash Conversion Cycle (days)
