Workbook

Sheet Cover
B8: COMPARABLE COMPANY ANALYSIS
C13: MODEL NAVIGATION
C14: 1 | D14: Comps Inputs
C16: 2 | D16: TSM Module
C18: 3 | D18: Trading Comps
C20: 4 | D20: Valuation Summary
C22: 5 | D22: Football Field
C24: 6 | D24: Sensitivity Tables

Sheet Comps Inputs
B1: COMPARABLE COMPANY ANALYSIS – INPUTS | V1: BACK -->
B2: Blue = inputs. Black = formulas. Green = cross-sheet. Diluted Shares pull from TSM Module. EV = Mkt Cap + Debt + Min.Int + Pref. − Cash.
B3: IDENTIFICATION | D3: SHARE COUNT & MARKET CAP | H3: EV BRIDGE | M3: LTM FINANCIALS | R3: NTM ESTIMATES
B4: Company Name | C4: Ticker | D4: Share Price ($) | E4: Basic Shares Out (mm) | F4: Diluted Shares (mm, TSM → | G4: Market Cap ($mm) | H4: Total Debt ($mm) | I4: Minority Interest ($mm) | J4: Preferred Equity ($mm) | K4: Cash & Equiv ($mm) | L4: Enterprise Value ($mm) | M4: Revenue LTM ($mm) | N4: EBITDA LTM ($mm) | O4: Adj. ($mm) | P4: Adj. EBITDA LTM ($mm) | Q4: EBIT LTM ($mm) | R4: Net Income LTM ($mm) | S4: EPS LTM ($) | T4: Revenue NTM ($mm) | U4: EBITDA NTM ($mm) | V4: EPS NTM ($)
B5: PEER GROUP – MARKET & FINANCIAL DATA (Diluted shares from TSM Module)
B6: Company A (Target / Subject) | C6: TGT US | D6: 0 | E6: 0 | F6: ='TSM Module'!D12 -> 0 | G6: =D6*F6 -> 0 | H6: 0 | I6: 0 | J6: 0 | K6: 0 | L6: =G6+H6+I6+J6-K6 -> 0 | M6: 0 | N6: 0 | O6: 0 | P6: =N6+O6 -> 0 | Q6: 0 | R6: 0 | S6: 0 | T6: 0 | U6: 0 | V6: 0
B7: Peer 1 | C7: PEER1 US | D7: 0 | E7: 0 | F7: ='TSM Module'!D21 -> 0 | G7: =D7*F7 -> 0 | H7: 0 | I7: 0 | J7: 0 | K7: 0 | L7: =G7+H7+I7+J7-K7 -> 0 | M7: 0 | N7: 0 | O7: 0 | P7: =N7+O7 -> 0 | Q7: 0 | R7: 0 | S7: 0 | T7: 0 | U7: 0 | V7: 0
B8: Peer 2 | C8: PEER2 US | D8: 0 | E8: 0 | F8: ='TSM Module'!D30 -> 0 | G8: =D8*F8 -> 0 | H8: 0 | I8: 0 | J8: 0 | K8: 0 | L8: =G8+H8+I8+J8-K8 -> 0 | M8: 0 | N8: 0 | O8: 0 | P8: =N8+O8 -> 0 | Q8: 0 | R8: 0 | S8: 0 | T8: 0 | U8: 0 | V8: 0
B9: Peer 3 | C9: PEER3 US | D9: 0 | E9: 0 | F9: ='TSM Module'!D39 -> 0 | G9: =D9*F9 -> 0 | H9: 0 | I9: 0 | J9: 0 | K9: 0 | L9: =G9+H9+I9+J9-K9 -> 0 | M9: 0 | N9: 0 | O9: 0 | P9: =N9+O9 -> 0 | Q9: 0 | R9: 0 | S9: 0 | T9: 0 | U9: 0 | V9: 0
B10: Peer 4 | C10: PEER4 US | D10: 0 | E10: 0 | F10: ='TSM Module'!D48 -> 0 | G10: =D10*F10 -> 0 | H10: 0 | I10: 0 | J10: 0 | K10: 0 | L10: =G10+H10+I10+J10-K10 -> 0 | M10: 0 | N10: 0 | O10: 0 | P10: =N10+O10 -> 0 | Q10: 0 | R10: 0 | S10: 0 | T10: 0 | U10: 0 | V10: 0
B11: Peer 5 | C11: PEER5 US | D11: 0 | E11: 0 | F11: ='TSM Module'!D57 -> 0 | G11: =D11*F11 -> 0 | H11: 0 | I11: 0 | J11: 0 | K11: 0 | L11: =G11+H11+I11+J11-K11 -> 0 | M11: 0 | N11: 0 | O11: 0 | P11: =N11+O11 -> 0 | Q11: 0 | R11: 0 | S11: 0 | T11: 0 | U11: 0 | V11: 0
B12: Peer 6 | C12: PEER6 US | D12: 0 | E12: 0 | F12: ='TSM Module'!D66 -> 0 | G12: =D12*F12 -> 0 | H12: 0 | I12: 0 | J12: 0 | K12: 0 | L12: =G12+H12+I12+J12-K12 -> 0 | M12: 0 | N12: 0 | O12: 0 | P12: =N12+O12 -> 0 | Q12: 0 | R12: 0 | S12: 0 | T12: 0 | U12: 0 | V12: 0
B13: Peer 7 | C13: PEER7 US | D13: 0 | E13: 0 | F13: ='TSM Module'!D75 -> 0 | G13: =D13*F13 -> 0 | H13: 0 | I13: 0 | J13: 0 | K13: 0 | L13: =G13+H13+I13+J13-K13 -> 0 | M13: 0 | N13: 0 | O13: 0 | P13: =N13+O13 -> 0 | Q13: 0 | R13: 0 | S13: 0 | T13: 0 | U13: 0 | V13: 0
B15: Source: Bloomberg / FactSet / 10-K Filings. Col O = non-recurring items from footnotes (SBC, restructuring, legal, etc.). Col L EV = Mkt Cap + Debt + Minority Interest + Preferred − Cash. Replace placeholder names/tickers before use.

Sheet TSM Module
B1: TSM MODULE – TREASURY STOCK METHOD (DILUTED SHARE COUNT) | J1: BACK -->
B4: Line Item | C4: Tranche / Type | D4: Options / RSUs (mm) | E4: Strike / Avg Vesting Price ($) | F4: Current Share Price ($) | G4: In-the-Money? (Y/N) | H4: Gross Proceeds ($mm) | I4: Shares Repurchased (mm) | J4: Net Dilution (mm shares)
B5: Company A (Target / Subject) | TGT US
B6: Basic Shares Outstanding | D6: ='Comps Inputs'!E6 -> 0
B7: Options – Tranche 1 | C7: Low-Strike / Earliest | D7: 0 | E7: 0 | F7: ='Comps Inputs'!D6 -> 0 | G7: =IF(F7>E7,"Yes","No") -> No | H7: =IFERROR(IF(F7>E7,D7*E7/1000,0),0) -> 0 | I7: =IFERROR(H7/(F7/1000),0) -> 0 | J7: =IFERROR(IF(F7>E7,D7-I7,0),0) -> 0
B8: Options – Tranche 2 | C8: Mid-Strike | D8: 0 | E8: 0 | F8: ='Comps Inputs'!D6 -> 0 | G8: =IF(F8>E8,"Yes","No") -> No | H8: =IFERROR(IF(F8>E8,D8*E8/1000,0),0) -> 0 | I8: =IFERROR(H8/(F8/1000),0) -> 0 | J8: =IFERROR(IF(F8>E8,D8-I8,0),0) -> 0
B9: Options – Tranche 3 | C9: High-Strike / OTM | D9: 0 | E9: 0 | F9: ='Comps Inputs'!D6 -> 0 | G9: =IF(F9>E9,"Yes","No") -> No | H9: =IFERROR(IF(F9>E9,D9*E9/1000,0),0) -> 0 | I9: =IFERROR(H9/(F9/1000),0) -> 0 | J9: =IFERROR(IF(F9>E9,D9-I9,0),0) -> 0
B10: Restricted Stock Units (RSUs) | C10: Unvested / Full Dilution | D10: 0 | E10: 0 | F10: ='Comps Inputs'!D6 -> 0 | G10: — | H10: — | I10: =IFERROR(D10*F10/1000,0) -> 0 | J10: =IFERROR(D10-I10,0) -> 0
B12: ► Diluted Shares – Company A (Target / Subject) | D12: =IFERROR(D6+J7+J8+J9+J10,D6) -> 0 | J12: =IFERROR(J7+J8+J9+J10,0) -> 0
B14: Peer 1 | PEER1 US
B15: Basic Shares Outstanding | D15: ='Comps Inputs'!E7 -> 0
B16: Options – Tranche 1 | C16: Low-Strike / Earliest | D16: 0 | E16: 0 | F16: ='Comps Inputs'!D7 -> 0 | G16: =IF(F16>E16,"Yes","No") -> No | H16: =IFERROR(IF(F16>E16,D16*E16/1000,0),0) -> 0 | I16: =IFERROR(H16/(F16/1000),0) -> 0 | J16: =IFERROR(IF(F16>E16,D16-I16,0),0) -> 0
B17: Options – Tranche 2 | C17: Mid-Strike | D17: 0 | E17: 0 | F17: ='Comps Inputs'!D7 -> 0 | G17: =IF(F17>E17,"Yes","No") -> No | H17: =IFERROR(IF(F17>E17,D17*E17/1000,0),0) -> 0 | I17: =IFERROR(H17/(F17/1000),0) -> 0 | J17: =IFERROR(IF(F17>E17,D17-I17,0),0) -> 0
B18: Options – Tranche 3 | C18: High-Strike / OTM | D18: 0 | E18: 0 | F18: ='Comps Inputs'!D7 -> 0 | G18: =IF(F18>E18,"Yes","No") -> No | H18: =IFERROR(IF(F18>E18,D18*E18/1000,0),0) -> 0 | I18: =IFERROR(H18/(F18/1000),0) -> 0 | J18: =IFERROR(IF(F18>E18,D18-I18,0),0) -> 0
B19: Restricted Stock Units (RSUs) | C19: Unvested / Full Dilution | D19: 0 | E19: 0 | F19: ='Comps Inputs'!D7 -> 0 | G19: — | H19: — | I19: =IFERROR(D19*F19/1000,0) -> 0 | J19: =IFERROR(D19-I19,0) -> 0
B21: ► Diluted Shares – Peer 1 | D21: =IFERROR(D15+J16+J17+J18+J19,D15) -> 0 | J21: =IFERROR(J16+J17+J18+J19,0) -> 0
B23: Peer 2 | PEER2 US
B24: Basic Shares Outstanding | D24: ='Comps Inputs'!E8 -> 0
B25: Options – Tranche 1 | C25: Low-Strike / Earliest | D25: 0 | E25: 0 | F25: ='Comps Inputs'!D8 -> 0 | G25: =IF(F25>E25,"Yes","No") -> No | H25: =IFERROR(IF(F25>E25,D25*E25/1000,0),0) -> 0 | I25: =IFERROR(H25/(F25/1000),0) -> 0 | J25: =IFERROR(IF(F25>E25,D25-I25,0),0) -> 0
B26: Options – Tranche 2 | C26: Mid-Strike | D26: 0 | E26: 0 | F26: ='Comps Inputs'!D8 -> 0 | G26: =IF(F26>E26,"Yes","No") -> No | H26: =IFERROR(IF(F26>E26,D26*E26/1000,0),0) -> 0 | I26: =IFERROR(H26/(F26/1000),0) -> 0 | J26: =IFERROR(IF(F26>E26,D26-I26,0),0) -> 0
B27: Options – Tranche 3 | C27: High-Strike / OTM | D27: 0 | E27: 0 | F27: ='Comps Inputs'!D8 -> 0 | G27: =IF(F27>E27,"Yes","No") -> No | H27: =IFERROR(IF(F27>E27,D27*E27/1000,0),0) -> 0 | I27: =IFERROR(H27/(F27/1000),0) -> 0 | J27: =IFERROR(IF(F27>E27,D27-I27,0),0) -> 0
B28: Restricted Stock Units (RSUs) | C28: Unvested / Full Dilution | D28: 0 | E28: 0 | F28: ='Comps Inputs'!D8 -> 0 | G28: — | H28: — | I28: =IFERROR(D28*F28/1000,0) -> 0 | J28: =IFERROR(D28-I28,0) -> 0
B30: ► Diluted Shares – Peer 2 | D30: =IFERROR(D24+J25+J26+J27+J28,D24) -> 0 | J30: =IFERROR(J25+J26+J27+J28,0) -> 0
B32: Peer 3 | PEER3 US
B33: Basic Shares Outstanding | D33: ='Comps Inputs'!E9 -> 0
B34: Options – Tranche 1 | C34: Low-Strike / Earliest | D34: 0 | E34: 0 | F34: ='Comps Inputs'!D9 -> 0 | G34: =IF(F34>E34,"Yes","No") -> No | H34: =IFERROR(IF(F34>E34,D34*E34/1000,0),0) -> 0 | I34: =IFERROR(H34/(F34/1000),0) -> 0 | J34: =IFERROR(IF(F34>E34,D34-I34,0),0) -> 0
B35: Options – Tranche 2 | C35: Mid-Strike | D35: 0 | E35: 0 | F35: ='Comps Inputs'!D9 -> 0 | G35: =IF(F35>E35,"Yes","No") -> No | H35: =IFERROR(IF(F35>E35,D35*E35/1000,0),0) -> 0 | I35: =IFERROR(H35/(F35/1000),0) -> 0 | J35: =IFERROR(IF(F35>E35,D35-I35,0),0) -> 0
B36: Options – Tranche 3 | C36: High-Strike / OTM | D36: 0 | E36: 0 | F36: ='Comps Inputs'!D9 -> 0 | G36: =IF(F36>E36,"Yes","No") -> No | H36: =IFERROR(IF(F36>E36,D36*E36/1000,0),0) -> 0 | I36: =IFERROR(H36/(F36/1000),0) -> 0 | J36: =IFERROR(IF(F36>E36,D36-I36,0),0) -> 0
B37: Restricted Stock Units (RSUs) | C37: Unvested / Full Dilution | D37: 0 | E37: 0 | F37: ='Comps Inputs'!D9 -> 0 | G37: — | H37: — | I37: =IFERROR(D37*F37/1000,0) -> 0 | J37: =IFERROR(D37-I37,0) -> 0
B39: ► Diluted Shares – Peer 3 | D39: =IFERROR(D33+J34+J35+J36+J37,D33) -> 0 | J39: =IFERROR(J34+J35+J36+J37,0) -> 0
B41: Peer 4 | PEER4 US
B42: Basic Shares Outstanding | D42: ='Comps Inputs'!E10 -> 0
B43: Options – Tranche 1 | C43: Low-Strike / Earliest | D43: 0 | E43: 0 | F43: ='Comps Inputs'!D10 -> 0 | G43: =IF(F43>E43,"Yes","No") -> No | H43: =IFERROR(IF(F43>E43,D43*E43/1000,0),0) -> 0 | I43: =IFERROR(H43/(F43/1000),0) -> 0 | J43: =IFERROR(IF(F43>E43,D43-I43,0),0) -> 0
B44: Options – Tranche 2 | C44: Mid-Strike | D44: 0 | E44: 0 | F44: ='Comps Inputs'!D10 -> 0 | G44: =IF(F44>E44,"Yes","No") -> No | H44: =IFERROR(IF(F44>E44,D44*E44/1000,0),0) -> 0 | I44: =IFERROR(H44/(F44/1000),0) -> 0 | J44: =IFERROR(IF(F44>E44,D44-I44,0),0) -> 0
B45: Options – Tranche 3 | C45: High-Strike / OTM | D45: 0 | E45: 0 | F45: ='Comps Inputs'!D10 -> 0 | G45: =IF(F45>E45,"Yes","No") -> No | H45: =IFERROR(IF(F45>E45,D45*E45/1000,0),0) -> 0 | I45: =IFERROR(H45/(F45/1000),0) -> 0 | J45: =IFERROR(IF(F45>E45,D45-I45,0),0) -> 0
B46: Restricted Stock Units (RSUs) | C46: Unvested / Full Dilution | D46: 0 | E46: 0 | F46: ='Comps Inputs'!D10 -> 0 | G46: — | H46: — | I46: =IFERROR(D46*F46/1000,0) -> 0 | J46: =IFERROR(D46-I46,0) -> 0
B48: ► Diluted Shares – Peer 4 | D48: =IFERROR(D42+J43+J44+J45+J46,D42) -> 0 | J48: =IFERROR(J43+J44+J45+J46,0) -> 0
B50: Peer 5 | PEER5 US
B51: Basic Shares Outstanding | D51: ='Comps Inputs'!E11 -> 0
B52: Options – Tranche 1 | C52: Low-Strike / Earliest | D52: 0 | E52: 0 | F52: ='Comps Inputs'!D11 -> 0 | G52: =IF(F52>E52,"Yes","No") -> No | H52: =IFERROR(IF(F52>E52,D52*E52/1000,0),0) -> 0 | I52: =IFERROR(H52/(F52/1000),0) -> 0 | J52: =IFERROR(IF(F52>E52,D52-I52,0),0) -> 0
...

Sheet Trading Comps
B1: TRADING COMPS | O1: BACK -->
B2: EV/EBITDA uses Adjusted EBITDA (col P from Comps Inputs). Green = cross-sheet reference.
B3: Company | C3: Ticker | D3: Mkt Cap ($mm) | E3: EV ($mm) | F3: EV/Rev LTM | G3: EV/Adj. EBITDA LTM | H3: EV/EBIT LTM | I3: P/E LTM | J3: EV/Rev NTM | K3: EV/EBITDA NTM | L3: P/E NTM | M3: Adj.EBITDA Margin % | N3: Net Margin % | O3: Rev Growth % NTM
B5: PEER GROUP TRADING MULTIPLES
B6: ='Comps Inputs'!B6 -> Company A (Target / Subject) | C6: ='Comps Inputs'!C6 -> TGT US | D6: ='Comps Inputs'!G6 -> 0 | E6: ='Comps Inputs'!L6 -> 0 | F6: =IFERROR('Comps Inputs'!L6/'Comps Inputs'!M6,"-") -> - | G6: =IFERROR('Comps Inputs'!L6/'Comps Inputs'!P6,"-") -> - | H6: =IFERROR('Comps Inputs'!L6/'Comps Inputs'!Q6,"-") -> - | I6: =IFERROR('Comps Inputs'!G6/('Comps Inputs'!S6*'Comps Inputs'!F6),"-") -> - | J6: =IFERROR('Comps Inputs'!L6/'Comps Inputs'!T6,"-") -> - | K6: =IFERROR('Comps Inputs'!L6/'Comps Inputs'!U6,"-") -> - | L6: =IFERROR('Comps Inputs'!G6/('Comps Inputs'!V6*'Comps Inputs'!F6),"-") -> - | M6: =IFERROR('Comps Inputs'!P6/'Comps Inputs'!M6,"-") -> - | N6: =IFERROR('Comps Inputs'!R6/'Comps Inputs'!M6,"-") -> - | O6: =IFERROR(('Comps Inputs'!T6-'Comps Inputs'!M6)/'Comps Inputs'!M6,"-") -> -
B7: ='Comps Inputs'!B7 -> Peer 1 | C7: ='Comps Inputs'!C7 -> PEER1 US | D7: ='Comps Inputs'!G7 -> 0 | E7: ='Comps Inputs'!L7 -> 0 | F7: =IFERROR('Comps Inputs'!L7/'Comps Inputs'!M7,"-") -> - | G7: =IFERROR('Comps Inputs'!L7/'Comps Inputs'!P7,"-") -> - | H7: =IFERROR('Comps Inputs'!L7/'Comps Inputs'!Q7,"-") -> - | I7: =IFERROR('Comps Inputs'!G7/('Comps Inputs'!S7*'Comps Inputs'!F7),"-") -> - | J7: =IFERROR('Comps Inputs'!L7/'Comps Inputs'!T7,"-") -> - | K7: =IFERROR('Comps Inputs'!L7/'Comps Inputs'!U7,"-") -> - | L7: =IFERROR('Comps Inputs'!G7/('Comps Inputs'!V7*'Comps Inputs'!F7),"-") -> - | M7: =IFERROR('Comps Inputs'!P7/'Comps Inputs'!M7,"-") -> - | N7: =IFERROR('Comps Inputs'!R7/'Comps Inputs'!M7,"-") -> - | O7: =IFERROR(('Comps Inputs'!T7-'Comps Inputs'!M7)/'Comps Inputs'!M7,"-") -> -
B8: ='Comps Inputs'!B8 -> Peer 2 | C8: ='Comps Inputs'!C8 -> PEER2 US | D8: ='Comps Inputs'!G8 -> 0 | E8: ='Comps Inputs'!L8 -> 0 | F8: =IFERROR('Comps Inputs'!L8/'Comps Inputs'!M8,"-") -> - | G8: =IFERROR('Comps Inputs'!L8/'Comps Inputs'!P8,"-") -> - | H8: =IFERROR('Comps Inputs'!L8/'Comps Inputs'!Q8,"-") -> - | I8: =IFERROR('Comps Inputs'!G8/('Comps Inputs'!S8*'Comps Inputs'!F8),"-") -> - | J8: =IFERROR('Comps Inputs'!L8/'Comps Inputs'!T8,"-") -> - | K8: =IFERROR('Comps Inputs'!L8/'Comps Inputs'!U8,"-") -> - | L8: =IFERROR('Comps Inputs'!G8/('Comps Inputs'!V8*'Comps Inputs'!F8),"-") -> - | M8: =IFERROR('Comps Inputs'!P8/'Comps Inputs'!M8,"-") -> - | N8: =IFERROR('Comps Inputs'!R8/'Comps Inputs'!M8,"-") -> - | O8: =IFERROR(('Comps Inputs'!T8-'Comps Inputs'!M8)/'Comps Inputs'!M8,"-") -> -
B9: ='Comps Inputs'!B9 -> Peer 3 | C9: ='Comps Inputs'!C9 -> PEER3 US | D9: ='Comps Inputs'!G9 -> 0 | E9: ='Comps Inputs'!L9 -> 0 | F9: =IFERROR('Comps Inputs'!L9/'Comps Inputs'!M9,"-") -> - | G9: =IFERROR('Comps Inputs'!L9/'Comps Inputs'!P9,"-") -> - | H9: =IFERROR('Comps Inputs'!L9/'Comps Inputs'!Q9,"-") -> - | I9: =IFERROR('Comps Inputs'!G9/('Comps Inputs'!S9*'Comps Inputs'!F9),"-") -> - | J9: =IFERROR('Comps Inputs'!L9/'Comps Inputs'!T9,"-") -> - | K9: =IFERROR('Comps Inputs'!L9/'Comps Inputs'!U9,"-") -> - | L9: =IFERROR('Comps Inputs'!G9/('Comps Inputs'!V9*'Comps Inputs'!F9),"-") -> - | M9: =IFERROR('Comps Inputs'!P9/'Comps Inputs'!M9,"-") -> - | N9: =IFERROR('Comps Inputs'!R9/'Comps Inputs'!M9,"-") -> - | O9: =IFERROR(('Comps Inputs'!T9-'Comps Inputs'!M9)/'Comps Inputs'!M9,"-") -> -
B10: ='Comps Inputs'!B10 -> Peer 4 | C10: ='Comps Inputs'!C10 -> PEER4 US | D10: ='Comps Inputs'!G10 -> 0 | E10: ='Comps Inputs'!L10 -> 0 | F10: =IFERROR('Comps Inputs'!L10/'Comps Inputs'!M10,"-") -> - | G10: =IFERROR('Comps Inputs'!L10/'Comps Inputs'!P10,"-") -> - | H10: =IFERROR('Comps Inputs'!L10/'Comps Inputs'!Q10,"-") -> - | I10: =IFERROR('Comps Inputs'!G10/('Comps Inputs'!S10*'Comps Inputs'!F10),"-") -> - | J10: =IFERROR('Comps Inputs'!L10/'Comps Inputs'!T10,"-") -> - | K10: =IFERROR('Comps Inputs'!L10/'Comps Inputs'!U10,"-") -> - | L10: =IFERROR('Comps Inputs'!G10/('Comps Inputs'!V10*'Comps Inputs'!F10),"-") -> - | M10: =IFERROR('Comps Inputs'!P10/'Comps Inputs'!M10,"-") -> - | N10: =IFERROR('Comps Inputs'!R10/'Comps Inputs'!M10,"-") -> - | O10: =IFERROR(('Comps Inputs'!T10-'Comps Inputs'!M10)/'Comps Inputs'!M10,"-") -> -
B11: ='Comps Inputs'!B11 -> Peer 5 | C11: ='Comps Inputs'!C11 -> PEER5 US | D11: ='Comps Inputs'!G11 -> 0 | E11: ='Comps Inputs'!L11 -> 0 | F11: =IFERROR('Comps Inputs'!L11/'Comps Inputs'!M11,"-") -> - | G11: =IFERROR('Comps Inputs'!L11/'Comps Inputs'!P11,"-") -> - | H11: =IFERROR('Comps Inputs'!L11/'Comps Inputs'!Q11,"-") -> - | I11: =IFERROR('Comps Inputs'!G11/('Comps Inputs'!S11*'Comps Inputs'!F11),"-") -> - | J11: =IFERROR('Comps Inputs'!L11/'Comps Inputs'!T11,"-") -> - | K11: =IFERROR('Comps Inputs'!L11/'Comps Inputs'!U11,"-") -> - | L11: =IFERROR('Comps Inputs'!G11/('Comps Inputs'!V11*'Comps Inputs'!F11),"-") -> - | M11: =IFERROR('Comps Inputs'!P11/'Comps Inputs'!M11,"-") -> - | N11: =IFERROR('Comps Inputs'!R11/'Comps Inputs'!M11,"-") -> - | O11: =IFERROR(('Comps Inputs'!T11-'Comps Inputs'!M11)/'Comps Inputs'!M11,"-") -> -
B12: ='Comps Inputs'!B12 -> Peer 6 | C12: ='Comps Inputs'!C12 -> PEER6 US | D12: ='Comps Inputs'!G12 -> 0 | E12: ='Comps Inputs'!L12 -> 0 | F12: =IFERROR('Comps Inputs'!L12/'Comps Inputs'!M12,"-") -> - | G12: =IFERROR('Comps Inputs'!L12/'Comps Inputs'!P12,"-") -> - | H12: =IFERROR('Comps Inputs'!L12/'Comps Inputs'!Q12,"-") -> - | I12: =IFERROR('Comps Inputs'!G12/('Comps Inputs'!S12*'Comps Inputs'!F12),"-") -> - | J12: =IFERROR('Comps Inputs'!L12/'Comps Inputs'!T12,"-") -> - | K12: =IFERROR('Comps Inputs'!L12/'Comps Inputs'!U12,"-") -> - | L12: =IFERROR('Comps Inputs'!G12/('Comps Inputs'!V12*'Comps Inputs'!F12),"-") -> - | M12: =IFERROR('Comps Inputs'!P12/'Comps Inputs'!M12,"-") -> - | N12: =IFERROR('Comps Inputs'!R12/'Comps Inputs'!M12,"-") -> - | O12: =IFERROR(('Comps Inputs'!T12-'Comps Inputs'!M12)/'Comps Inputs'!M12,"-") -> -
B13: ='Comps Inputs'!B13 -> Peer 7 | C13: ='Comps Inputs'!C13 -> PEER7 US | D13: ='Comps Inputs'!G13 -> 0 | E13: ='Comps Inputs'!L13 -> 0 | F13: =IFERROR('Comps Inputs'!L13/'Comps Inputs'!M13,"-") -> - | G13: =IFERROR('Comps Inputs'!L13/'Comps Inputs'!P13,"-") -> - | H13: =IFERROR('Comps Inputs'!L13/'Comps Inputs'!Q13,"-") -> - | I13: =IFERROR('Comps Inputs'!G13/('Comps Inputs'!S13*'Comps Inputs'!F13),"-") -> - | J13: =IFERROR('Comps Inputs'!L13/'Comps Inputs'!T13,"-") -> - | K13: =IFERROR('Comps Inputs'!L13/'Comps Inputs'!U13,"-") -> - | L13: =IFERROR('Comps Inputs'!G13/('Comps Inputs'!V13*'Comps Inputs'!F13),"-") -> - | M13: =IFERROR('Comps Inputs'!P13/'Comps Inputs'!M13,"-") -> - | N13: =IFERROR('Comps Inputs'!R13/'Comps Inputs'!M13,"-") -> - | O13: =IFERROR(('Comps Inputs'!T13-'Comps Inputs'!M13)/'Comps Inputs'!M13,"-") -> -
B15: SUMMARY STATISTICS
B16: Mean | D16: =IFERROR(AVERAGE(D6:D13),"-") -> 0 | E16: =IFERROR(AVERAGE(E6:E13),"-") -> 0 | F16: =IFERROR(AVERAGE(F6:F13),"-") -> - | G16: =IFERROR(AVERAGE(G6:G13),"-") -> - | H16: =IFERROR(AVERAGE(H6:H13),"-") -> - | I16: =IFERROR(AVERAGE(I6:I13),"-") -> - | J16: =IFERROR(AVERAGE(J6:J13),"-") -> - | K16: =IFERROR(AVERAGE(K6:K13),"-") -> - | ... O16: =IFERROR(AVERAGE(O6:O13),"-") -> -
B17: Median | D17: =IFERROR(MEDIAN(D6:D13),"-") -> 0 | E17: =IFERROR(MEDIAN(E6:E13),"-") -> 0 | F17: =IFERROR(MEDIAN(F6:F13),"-") -> - | G17: =IFERROR(MEDIAN(G6:G13),"-") -> - | H17: =IFERROR(MEDIAN(H6:H13),"-") -> - | I17: =IFERROR(MEDIAN(I6:I13),"-") -> - | J17: =IFERROR(MEDIAN(J6:J13),"-") -> - | K17: =IFERROR(MEDIAN(K6:K13),"-") -> - | ... O17: =IFERROR(MEDIAN(O6:O13),"-") -> -
B18: High | D18: =IFERROR(MAX(D6:D13),"-") -> 0 | E18: =IFERROR(MAX(E6:E13),"-") -> 0 | F18: =IFERROR(MAX(F6:F13),"-") -> 0 | G18: =IFERROR(MAX(G6:G13),"-") -> 0 | H18: =IFERROR(MAX(H6:H13),"-") -> 0 | I18: =IFERROR(MAX(I6:I13),"-") -> 0 | J18: =IFERROR(MAX(J6:J13),"-") -> 0 | K18: =IFERROR(MAX(K6:K13),"-") -> 0 | ... O18: =IFERROR(MAX(O6:O13),"-") -> 0
B19: Low | D19: =IFERROR(MIN(D6:D13),"-") -> 0 | E19: =IFERROR(MIN(E6:E13),"-") -> 0 | F19: =IFERROR(MIN(F6:F13),"-") -> 0 | G19: =IFERROR(MIN(G6:G13),"-") -> 0 | H19: =IFERROR(MIN(H6:H13),"-") -> 0 | I19: =IFERROR(MIN(I6:I13),"-") -> 0 | J19: =IFERROR(MIN(J6:J13),"-") -> 0 | K19: =IFERROR(MIN(K6:K13),"-") -> 0 | ... O19: =IFERROR(MIN(O6:O13),"-") -> 0
B20: 25th Percentile | D20: =IFERROR(PERCENTILE(D6:D13,0.25),"-") -> 0 | E20: =IFERROR(PERCENTILE(E6:E13,0.25),"-") -> 0 | F20: =IFERROR(PERCENTILE(F6:F13,0.25),"-") -> - | G20: =IFERROR(PERCENTILE(G6:G13,0.25),"-") -> - | H20: =IFERROR(PERCENTILE(H6:H13,0.25),"-") -> - | I20: =IFERROR(PERCENTILE(I6:I13,0.25),"-") -> - | J20: =IFERROR(PERCENTILE(J6:J13,0.25),"-") -> - | K20: =IFERROR(PERCENTILE(K6:K13,0.25),"-") -> - | ... O20: =IFERROR(PERCENTILE(O6:O13,0.25),"-") -> -
B21: 75th Percentile | D21: =IFERROR(PERCENTILE(D6:D13,0.75),"-") -> 0 | E21: =IFERROR(PERCENTILE(E6:E13,0.75),"-") -> 0 | F21: =IFERROR(PERCENTILE(F6:F13,0.75),"-") -> - | G21: =IFERROR(PERCENTILE(G6:G13,0.75),"-") -> - | H21: =IFERROR(PERCENTILE(H6:H13,0.75),"-") -> - | I21: =IFERROR(PERCENTILE(I6:I13,0.75),"-") -> - | J21: =IFERROR(PERCENTILE(J6:J13,0.75),"-") -> - | K21: =IFERROR(PERCENTILE(K6:K13,0.75),"-") -> - | ... O21: =IFERROR(PERCENTILE(O6:O13,0.75),"-") -> -

Sheet Valuation Summary
B1: VALUATION SUMMARY | K1: BACK -->
B2: All multiples pre-filled from Trading Comps (25th/75th %ile). Discount toggles apply before final price output.
B3: Valuation Method | C3: Subject Co. Metric ($mm) | D3: Multiple Low (x) | E3: Multiple High (x) | F3: Adj. Multiple Low (post-disc.) | G3: Adj. Multiple High (post-disc.) | H3: Implied EV Low ($mm) | I3: Implied EV High ($mm) | J3: Implied Price Low ($) | K3: Implied Price High ($)
B4: SUBJECT COMPANY ASSUMPTIONS
B5: Net Debt of Subject Company ($mm) | C5: 0
B6: Diluted Shares Outstanding (mm) – from TSM Module | C6: 0
B7: Current Share Price ($) – for reference | C7: 0
B9: PREMIUM / DISCOUNT TOGGLES (Applied to multiples before implying price)
B10: Illiquidity / Minority Discount (%) | C10: -0.1 | D10: Applied for private/minority-stake targets. Typical: (10%) to (20%).
B11: Size / SMID-Cap Discount (%) | C11: -0.05 | D11: Applied when subject is smaller than peer avg. Typical: (5%) to (15%).
B12: Quality / Margin Discount (%) | C12: 0 | D12: Applied when subject margins below peer median. Typical: 0% to (10%).
B13: Control Premium (%) | C13: 0 | D13: Add for M&A context. Typical: +20% to +30% over trading value.
B14: ► Net Adjustment Factor (1 + sum of above) | C14: =PRODUCT(1+C10,1+C11,1+C12,1+C13) -> 0.855
B16: SUBJECT COMPANY FINANCIALS (Enter Below)
B17: Revenue – LTM ($mm) | C17: 0
B18: EBITDA – LTM (reported, $mm) | C18: 0
B19: EBITDA – LTM (adjusted, $mm) | C19: 0
B20: EBIT – LTM ($mm) | C20: 0
B21: Net Income – LTM ($mm) | C21: 0
B22: EPS – LTM ($) | C22: 0
B23: Revenue – NTM ($mm) | C23: 0
B24: EBITDA – NTM ($mm) | C24: 0
B25: EPS – NTM ($) | C25: 0
B27: TRADING COMPS MULTIPLES (Pre-filled: 25th & 75th %ile from Trading Comps — override as needed)
B28: EV / Revenue – LTM | C28: =C17 -> 0 | D28: =IFERROR('Trading Comps'!F20,0) -> - | E28: =IFERROR('Trading Comps'!F21,0) -> - | F28: =IFERROR(D28*$C$14,"-") -> - | G28: =IFERROR(E28*$C$14,"-") -> - | H28: =IFERROR(F28*C28,"-") -> - | I28: =IFERROR(G28*C28,"-") -> - | J28: =IFERROR((H28-$C$5)/$C$6,"-") -> - | K28: =IFERROR((I28-$C$5)/$C$6,"-") -> -
B29: EV / Adj.EBITDA – LTM | C29: =C19 -> 0 | D29: =IFERROR('Trading Comps'!G20,0) -> - | E29: =IFERROR('Trading Comps'!G21,0) -> - | F29: =IFERROR(D29*$C$14,"-") -> - | G29: =IFERROR(E29*$C$14,"-") -> - | H29: =IFERROR(F29*C29,"-") -> - | I29: =IFERROR(G29*C29,"-") -> - | J29: =IFERROR((H29-$C$5)/$C$6,"-") -> - | K29: =IFERROR((I29-$C$5)/$C$6,"-") -> -
B30: EV / EBIT – LTM | C30: =C20 -> 0 | D30: =IFERROR('Trading Comps'!H20,0) -> - | E30: =IFERROR('Trading Comps'!H21,0) -> - | F30: =IFERROR(D30*$C$14,"-") -> - | G30: =IFERROR(E30*$C$14,"-") -> - | H30: =IFERROR(F30*C30,"-") -> - | I30: =IFERROR(G30*C30,"-") -> - | J30: =IFERROR((H30-$C$5)/$C$6,"-") -> - | K30: =IFERROR((I30-$C$5)/$C$6,"-") -> -
B31: P/E – LTM | C31: =C21 -> 0 | D31: =IFERROR('Trading Comps'!I20,0) -> - | E31: =IFERROR('Trading Comps'!I21,0) -> - | F31: =IFERROR(D31*$C$14,"-") -> - | G31: =IFERROR(E31*$C$14,"-") -> - | H31: =IFERROR(F31*C31,"-") -> - | I31: =IFERROR(G31*C31,"-") -> - | J31: =IFERROR(H31/$C$6,"-") -> - | K31: =IFERROR(I31/$C$6,"-") -> -
B32: EV / Revenue – NTM | C32: =C23 -> 0 | D32: =IFERROR('Trading Comps'!J20,0) -> - | E32: =IFERROR('Trading Comps'!J21,0) -> - | F32: =IFERROR(D32*$C$14,"-") -> - | G32: =IFERROR(E32*$C$14,"-") -> - | H32: =IFERROR(F32*C32,"-") -> - | I32: =IFERROR(G32*C32,"-") -> - | J32: =IFERROR((H32-$C$5)/$C$6,"-") -> - | K32: =IFERROR((I32-$C$5)/$C$6,"-") -> -
B33: EV / EBITDA – NTM | C33: =C24 -> 0 | D33: =IFERROR('Trading Comps'!K20,0) -> - | E33: =IFERROR('Trading Comps'!K21,0) -> - | F33: =IFERROR(D33*$C$14,"-") -> - | G33: =IFERROR(E33*$C$14,"-") -> - | H33: =IFERROR(F33*C33,"-") -> - | I33: =IFERROR(G33*C33,"-") -> - | J33: =IFERROR((H33-$C$5)/$C$6,"-") -> - | K33: =IFERROR((I33-$C$5)/$C$6,"-") -> -
B34: P/E – NTM | C34: =C25 -> 0 | D34: =IFERROR('Trading Comps'!L20,0) -> - | E34: =IFERROR('Trading Comps'!L21,0) -> - | F34: =IFERROR(D34*$C$14,"-") -> - | G34: =IFERROR(E34*$C$14,"-") -> - | H34: =IFERROR(F34*C34,"-") -> - | I34: =IFERROR(G34*C34,"-") -> - | J34: =IFERROR(H34/$C$6,"-") -> - | K34: =IFERROR(I34/$C$6,"-") -> -
B36: OVERALL IMPLIED PRICE RANGE (Post-Discount / Post-Premium)
B37: Overall Implied Price Range (All Methodologies) | J37: =IFERROR(MIN(J28:J34),"-") -> 0 | K37: =IFERROR(MAX(K28:K34),"-") -> 0

Sheet Football Field
B1: FOOTBALL FIELD – IMPLIED PRICE RANGE (Post-Discount) | G1: BACK -->
B2: Implied prices reflect discount/premium toggles from Valuation Summary. Net adj. factor shown below.
B3: Valuation Method | C3: Implied Price Low ($) | D3: Implied Price High ($) | E3: Midpoint ($) | F3: Range Width ($) | G3: vs. Current Price (% Prem./(Disc.))
B4: Net Adjustment Factor applied: ='Valuation Summary'!C14 | C4: ='Valuation Summary'!C14 -> 0.855
B5: VALUATION RANGE BY METHOD
B6: EV / Revenue – LTM | C6: =IFERROR('Valuation Summary'!J28,"-") -> - | D6: =IFERROR('Valuation Summary'!K28,"-") -> - | E6: =IFERROR((C6+D6)/2,"-") -> - | F6: =IFERROR(D6-C6,"-") -> - | G6: =IFERROR((E6/'Valuation Summary'!$C$7)-1,"-") -> -
B7: EV / Adj.EBITDA – LTM | C7: =IFERROR('Valuation Summary'!J29,"-") -> - | D7: =IFERROR('Valuation Summary'!K29,"-") -> - | E7: =IFERROR((C7+D7)/2,"-") -> - | F7: =IFERROR(D7-C7,"-") -> - | G7: =IFERROR((E7/'Valuation Summary'!$C$7)-1,"-") -> -
B8: EV / EBIT – LTM | C8: =IFERROR('Valuation Summary'!J30,"-") -> - | D8: =IFERROR('Valuation Summary'!K30,"-") -> - | E8: =IFERROR((C8+D8)/2,"-") -> - | F8: =IFERROR(D8-C8,"-") -> - | G8: =IFERROR((E8/'Valuation Summary'!$C$7)-1,"-") -> -
B9: P/E – LTM | C9: =IFERROR('Valuation Summary'!J31,"-") -> - | D9: =IFERROR('Valuation Summary'!K31,"-") -> - | E9: =IFERROR((C9+D9)/2,"-") -> - | F9: =IFERROR(D9-C9,"-") -> - | G9: =IFERROR((E9/'Valuation Summary'!$C$7)-1,"-") -> -
B10: EV / Revenue – NTM | C10: =IFERROR('Valuation Summary'!J32,"-") -> - | D10: =IFERROR('Valuation Summary'!K32,"-") -> - | E10: =IFERROR((C10+D10)/2,"-") -> - | F10: =IFERROR(D10-C10,"-") -> - | G10: =IFERROR((E10/'Valuation Summary'!$C$7)-1,"-") -> -
B11: EV / EBITDA – NTM | C11: =IFERROR('Valuation Summary'!J33,"-") -> - | D11: =IFERROR('Valuation Summary'!K33,"-") -> - | E11: =IFERROR((C11+D11)/2,"-") -> - | F11: =IFERROR(D11-C11,"-") -> - | G11: =IFERROR((E11/'Valuation Summary'!$C$7)-1,"-") -> -
B12: P/E – NTM | C12: =IFERROR('Valuation Summary'!J34,"-") -> - | D12: =IFERROR('Valuation Summary'!K34,"-") -> - | E12: =IFERROR((C12+D12)/2,"-") -> - | F12: =IFERROR(D12-C12,"-") -> - | G12: =IFERROR((E12/'Valuation Summary'!$C$7)-1,"-") -> -
B13: Overall Implied Price Range | C13: =IFERROR(MIN(C6:C12),"-") -> 0 | D13: =IFERROR(MAX(D6:D12),"-") -> 0 | E13: =IFERROR((C13+D13)/2,"-") -> 0

Sheet Sensitivity Tables
B1: SENSITIVITY TABLES | J1: BACK -->
B2: Implied share prices incorporate net discount/premium factor from Valuation Summary. Blue = editable inputs.
B3: TABLE 1: IMPLIED SHARE PRICE | EV/Adj.EBITDA Multiple × Adj.EBITDA ($mm) [w/ Discount]
B4: EV/EBITDA Multiple → | C4: 5 | D4: 6 | E4: 7 | F4: 8 | G4: 9 | H4: 10 | I4: 11 | J4: 12
B5: Adj.EBITDA ↓
B6: 50 | C6: =IFERROR(($B6*$C$4*'Valuation Summary'!$C$14-'Valuation Summary'!$C$5)/'Valuation Summary'!$C$6,"-") -> - | D6: =IFERROR(($B6*$D$4*'Valuation Summary'!$C$14-'Valuation Summary'!$C$5)/'Valuation Summary'!$C$6,"-") -> - | E6: =IFERROR(($B6*$E$4*'Valuation Summary'!$C$14-'Valuation Summary'!$C$5)/'Valuation Summary'!$C$6,"-") -> - | F6: =IFERROR(($B6*$F$4*'Valuation Summary'!$C$14-'Valuation Summary'!$C$5)/'Valuation Summary'!$C$6,"-") -> - | G6: =IFERROR(($B6*$G$4*'Valuation Summary'!$C$14-'Valuation Summary'!$C$5)/'Valuation Summary'!$C$6,"-") -> - | H6: =IFERROR(($B6*$H$4*'Valuation Summary'!$C$14-'Valuation Summary'!$C$5)/'Valuation Summary'!$C$6,"-") -> - | I6: =IFERROR(($B6*$I$4*'Valuation Summary'!$C$14-'Valuation Summary'!$C$5)/'Valuation Summary'!$C$6,"-") -> - | J6: =IFERROR(($B6*$J$4*'Valuation Summary'!$C$14-'Valuation Summary'!$C$5)/'Valuation Summary'!$C$6,"-") -> -
B7: 75 | C7: =IFERROR(($B7*$C$4*'Valuation Summary'!$C$14-'Valuation Summary'!$C$5)/'Valuation Summary'!$C$6,"-") -> - | D7: =IFERROR(($B7*$D$4*'Valuation Summary'!$C$14-'Valuation Summary'!$C$5)/'Valuation Summary'!$C$6,"-") -> - | E7: =IFERROR(($B7*$E$4*'Valuation Summary'!$C$14-'Valuation Summary'!$C$5)/'Valuation Summary'!$C$6,"-") -> - | F7: =IFERROR(($B7*$F$4*'Valuation Summary'!$C$14-'Valuation Summary'!$C$5)/'Valuation Summary'!$C$6,"-") -> - | G7: =IFERROR(($B7*$G$4*'Valuation Summary'!$C$14-'Valuation Summary'!$C$5)/'Valuation Summary'!$C$6,"-") -> - | H7: =IFERROR(($B7*$H$4*'Valuation Summary'!$C$14-'Valuation Summary'!$C$5)/'Valuation Summary'!$C$6,"-") -> - | I7: =IFERROR(($B7*$I$4*'Valuation Summary'!$C$14-'Valuation Summary'!$C$5)/'Valuation Summary'!$C$6,"-") -> - | J7: =IFERROR(($B7*$J$4*'Valuation Summary'!$C$14-'Valuation Summary'!$C$5)/'Valuation Summary'!$C$6,"-") -> -
B8: 100 | C8: =IFERROR(($B8*$C$4*'Valuation Summary'!$C$14-'Valuation Summary'!$C$5)/'Valuation Summary'!$C$6,"-") -> - | D8: =IFERROR(($B8*$D$4*'Valuation Summary'!$C$14-'Valuation Summary'!$C$5)/'Valuation Summary'!$C$6,"-") -> - | E8: =IFERROR(($B8*$E$4*'Valuation Summary'!$C$14-'Valuation Summary'!$C$5)/'Valuation Summary'!$C$6,"-") -> - | F8: =IFERROR(($B8*$F$4*'Valuation Summary'!$C$14-'Valuation Summary'!$C$5)/'Valuation Summary'!$C$6,"-") -> - | G8: =IFERROR(($B8*$G$4*'Valuation Summary'!$C$14-'Valuation Summary'!$C$5)/'Valuation Summary'!$C$6,"-") -> - | H8: =IFERROR(($B8*$H$4*'Valuation Summary'!$C$14-'Valuation Summary'!$C$5)/'Valuation Summary'!$C$6,"-") -> - | I8: =IFERROR(($B8*$I$4*'Valuation Summary'!$C$14-'Valuation Summary'!$C$5)/'Valuation Summary'!$C$6,"-") -> - | J8: =IFERROR(($B8*$J$4*'Valuation Summary'!$C$14-'Valuation Summary'!$C$5)/'Valuation Summary'!$C$6,"-") -> -
B9: 125 | C9: =IFERROR(($B9*$C$4*'Valuation Summary'!$C$14-'Valuation Summary'!$C$5)/'Valuation Summary'!$C$6,"-") -> - | D9: =IFERROR(($B9*$D$4*'Valuation Summary'!$C$14-'Valuation Summary'!$C$5)/'Valuation Summary'!$C$6,"-") -> - | E9: =IFERROR(($B9*$E$4*'Valuation Summary'!$C$14-'Valuation Summary'!$C$5)/'Valuation Summary'!$C$6,"-") -> - | F9: =IFERROR(($B9*$F$4*'Valuation Summary'!$C$14-'Valuation Summary'!$C$5)/'Valuation Summary'!$C$6,"-") -> - | G9: =IFERROR(($B9*$G$4*'Valuation Summary'!$C$14-'Valuation Summary'!$C$5)/'Valuation Summary'!$C$6,"-") -> - | H9: =IFERROR(($B9*$H$4*'Valuation Summary'!$C$14-'Valuation Summary'!$C$5)/'Valuation Summary'!$C$6,"-") -> - | I9: =IFERROR(($B9*$I$4*'Valuation Summary'!$C$14-'Valuation Summary'!$C$5)/'Valuation Summary'!$C$6,"-") -> - | J9: =IFERROR(($B9*$J$4*'Valuation Summary'!$C$14-'Valuation Summary'!$C$5)/'Valuation Summary'!$C$6,"-") -> -
B10: 150 | C10: =IFERROR(($B10*$C$4*'Valuation Summary'!$C$14-'Valuation Summary'!$C$5)/'Valuation Summary'!$C$6,"-") -> - | D10: =IFERROR(($B10*$D$4*'Valuation Summary'!$C$14-'Valuation Summary'!$C$5)/'Valuation Summary'!$C$6,"-") -> - | E10: =IFERROR(($B10*$E$4*'Valuation Summary'!$C$14-'Valuation Summary'!$C$5)/'Valuation Summary'!$C$6,"-") -> - | F10: =IFERROR(($B10*$F$4*'Valuation Summary'!$C$14-'Valuation Summary'!$C$5)/'Valuation Summary'!$C$6,"-") -> - | G10: =IFERROR(($B10*$G$4*'Valuation Summary'!$C$14-'Valuation Summary'!$C$5)/'Valuation Summary'!$C$6,"-") -> - | H10: =IFERROR(($B10*$H$4*'Valuation Summary'!$C$14-'Valuation Summary'!$C$5)/'Valuation Summary'!$C$6,"-") -> - | I10: =IFERROR(($B10*$I$4*'Valuation Summary'!$C$14-'Valuation Summary'!$C$5)/'Valuation Summary'!$C$6,"-") -> - | J10: =IFERROR(($B10*$J$4*'Valuation Summary'!$C$14-'Valuation Summary'!$C$5)/'Valuation Summary'!$C$6,"-") -> -
B11: 175 | C11: =IFERROR(($B11*$C$4*'Valuation Summary'!$C$14-'Valuation Summary'!$C$5)/'Valuation Summary'!$C$6,"-") -> - | D11: =IFERROR(($B11*$D$4*'Valuation Summary'!$C$14-'Valuation Summary'!$C$5)/'Valuation Summary'!$C$6,"-") -> - | E11: =IFERROR(($B11*$E$4*'Valuation Summary'!$C$14-'Valuation Summary'!$C$5)/'Valuation Summary'!$C$6,"-") -> - | F11: =IFERROR(($B11*$F$4*'Valuation Summary'!$C$14-'Valuation Summary'!$C$5)/'Valuation Summary'!$C$6,"-") -> - | G11: =IFERROR(($B11*$G$4*'Valuation Summary'!$C$14-'Valuation Summary'!$C$5)/'Valuation Summary'!$C$6,"-") -> - | H11: =IFERROR(($B11*$H$4*'Valuation Summary'!$C$14-'Valuation Summary'!$C$5)/'Valuation Summary'!$C$6,"-") -> - | I11: =IFERROR(($B11*$I$4*'Valuation Summary'!$C$14-'Valuation Summary'!$C$5)/'Valuation Summary'!$C$6,"-") -> - | J11: =IFERROR(($B11*$J$4*'Valuation Summary'!$C$14-'Valuation Summary'!$C$5)/'Valuation Summary'!$C$6,"-") -> -
B12: 200 | C12: =IFERROR(($B12*$C$4*'Valuation Summary'!$C$14-'Valuation Summary'!$C$5)/'Valuation Summary'!$C$6,"-") -> - | D12: =IFERROR(($B12*$D$4*'Valuation Summary'!$C$14-'Valuation Summary'!$C$5)/'Valuation Summary'!$C$6,"-") -> - | E12: =IFERROR(($B12*$E$4*'Valuation Summary'!$C$14-'Valuation Summary'!$C$5)/'Valuation Summary'!$C$6,"-") -> - | F12: =IFERROR(($B12*$F$4*'Valuation Summary'!$C$14-'Valuation Summary'!$C$5)/'Valuation Summary'!$C$6,"-") -> - | G12: =IFERROR(($B12*$G$4*'Valuation Summary'!$C$14-'Valuation Summary'!$C$5)/'Valuation Summary'!$C$6,"-") -> - | H12: =IFERROR(($B12*$H$4*'Valuation Summary'!$C$14-'Valuation Summary'!$C$5)/'Valuation Summary'!$C$6,"-") -> - | I12: =IFERROR(($B12*$I$4*'Valuation Summary'!$C$14-'Valuation Summary'!$C$5)/'Valuation Summary'!$C$6,"-") -> - | J12: =IFERROR(($B12*$J$4*'Valuation Summary'!$C$14-'Valuation Summary'!$C$5)/'Valuation Summary'!$C$6,"-") -> -
B13: 250 | C13: =IFERROR(($B13*$C$4*'Valuation Summary'!$C$14-'Valuation Summary'!$C$5)/'Valuation Summary'!$C$6,"-") -> - | D13: =IFERROR(($B13*$D$4*'Valuation Summary'!$C$14-'Valuation Summary'!$C$5)/'Valuation Summary'!$C$6,"-") -> - | E13: =IFERROR(($B13*$E$4*'Valuation Summary'!$C$14-'Valuation Summary'!$C$5)/'Valuation Summary'!$C$6,"-") -> - | F13: =IFERROR(($B13*$F$4*'Valuation Summary'!$C$14-'Valuation Summary'!$C$5)/'Valuation Summary'!$C$6,"-") -> - | G13: =IFERROR(($B13*$G$4*'Valuation Summary'!$C$14-'Valuation Summary'!$C$5)/'Valuation Summary'!$C$6,"-") -> - | H13: =IFERROR(($B13*$H$4*'Valuation Summary'!$C$14-'Valuation Summary'!$C$5)/'Valuation Summary'!$C$6,"-") -> - | I13: =IFERROR(($B13*$I$4*'Valuation Summary'!$C$14-'Valuation Summary'!$C$5)/'Valuation Summary'!$C$6,"-") -> - | J13: =IFERROR(($B13*$J$4*'Valuation Summary'!$C$14-'Valuation Summary'!$C$5)/'Valuation Summary'!$C$6,"-") -> -
B16: TABLE 2: IMPLIED SHARE PRICE | EV/Revenue Multiple × Revenue ($mm) [w/ Discount]
B17: EV/Revenue Multiple → | C17: 1 | D17: 1.5 | E17: 2 | F17: 2.5 | G17: 3 | H17: 3.5 | I17: 4 | J17: 5
B18: Revenue ↓
B19: 100 | C19: =IFERROR(($B19*$C$17*'Valuation Summary'!$C$14-'Valuation Summary'!$C$5)/'Valuation Summary'!$C$6,"-") -> - | D19: =IFERROR(($B19*$D$17*'Valuation Summary'!$C$14-'Valuation Summary'!$C$5)/'Valuation Summary'!$C$6,"-") -> - | E19: =IFERROR(($B19*$E$17*'Valuation Summary'!$C$14-'Valuation Summary'!$C$5)/'Valuation Summary'!$C$6,"-") -> - | F19: =IFERROR(($B19*$F$17*'Valuation Summary'!$C$14-'Valuation Summary'!$C$5)/'Valuation Summary'!$C$6,"-") -> - | G19: =IFERROR(($B19*$G$17*'Valuation Summary'!$C$14-'Valuation Summary'!$C$5)/'Valuation Summary'!$C$6,"-") -> - | H19: =IFERROR(($B19*$H$17*'Valuation Summary'!$C$14-'Valuation Summary'!$C$5)/'Valuation Summary'!$C$6,"-") -> - | I19: =IFERROR(($B19*$I$17*'Valuation Summary'!$C$14-'Valuation Summary'!$C$5)/'Valuation Summary'!$C$6,"-") -> - | J19: =IFERROR(($B19*$J$17*'Valuation Summary'!$C$14-'Valuation Summary'!$C$5)/'Valuation Summary'!$C$6,"-") -> -
B20: 150 | C20: =IFERROR(($B20*$C$17*'Valuation Summary'!$C$14-'Valuation Summary'!$C$5)/'Valuation Summary'!$C$6,"-") -> - | D20: =IFERROR(($B20*$D$17*'Valuation Summary'!$C$14-'Valuation Summary'!$C$5)/'Valuation Summary'!$C$6,"-") -> - | E20: =IFERROR(($B20*$E$17*'Valuation Summary'!$C$14-'Valuation Summary'!$C$5)/'Valuation Summary'!$C$6,"-") -> - | F20: =IFERROR(($B20*$F$17*'Valuation Summary'!$C$14-'Valuation Summary'!$C$5)/'Valuation Summary'!$C$6,"-") -> - | G20: =IFERROR(($B20*$G$17*'Valuation Summary'!$C$14-'Valuation Summary'!$C$5)/'Valuation Summary'!$C$6,"-") -> - | H20: =IFERROR(($B20*$H$17*'Valuation Summary'!$C$14-'Valuation Summary'!$C$5)/'Valuation Summary'!$C$6,"-") -> - | I20: =IFERROR(($B20*$I$17*'Valuation Summary'!$C$14-'Valuation Summary'!$C$5)/'Valuation Summary'!$C$6,"-") -> - | J20: =IFERROR(($B20*$J$17*'Valuation Summary'!$C$14-'Valuation Summary'!$C$5)/'Valuation Summary'!$C$6,"-") -> -
B21: 200 | C21: =IFERROR(($B21*$C$17*'Valuation Summary'!$C$14-'Valuation Summary'!$C$5)/'Valuation Summary'!$C$6,"-") -> - | D21: =IFERROR(($B21*$D$17*'Valuation Summary'!$C$14-'Valuation Summary'!$C$5)/'Valuation Summary'!$C$6,"-") -> - | E21: =IFERROR(($B21*$E$17*'Valuation Summary'!$C$14-'Valuation Summary'!$C$5)/'Valuation Summary'!$C$6,"-") -> - | F21: =IFERROR(($B21*$F$17*'Valuation Summary'!$C$14-'Valuation Summary'!$C$5)/'Valuation Summary'!$C$6,"-") -> - | G21: =IFERROR(($B21*$G$17*'Valuation Summary'!$C$14-'Valuation Summary'!$C$5)/'Valuation Summary'!$C$6,"-") -> - | H21: =IFERROR(($B21*$H$17*'Valuation Summary'!$C$14-'Valuation Summary'!$C$5)/'Valuation Summary'!$C$6,"-") -> - | I21: =IFERROR(($B21*$I$17*'Valuation Summary'!$C$14-'Valuation Summary'!$C$5)/'Valuation Summary'!$C$6,"-") -> - | J21: =IFERROR(($B21*$J$17*'Valuation Summary'!$C$14-'Valuation Summary'!$C$5)/'Valuation Summary'!$C$6,"-") -> -
B22: 250 | C22: =IFERROR(($B22*$C$17*'Valuation Summary'!$C$14-'Valuation Summary'!$C$5)/'Valuation Summary'!$C$6,"-") -> - | D22: =IFERROR(($B22*$D$17*'Valuation Summary'!$C$14-'Valuation Summary'!$C$5)/'Valuation Summary'!$C$6,"-") -> - | E22: =IFERROR(($B22*$E$17*'Valuation Summary'!$C$14-'Valuation Summary'!$C$5)/'Valuation Summary'!$C$6,"-") -> - | F22: =IFERROR(($B22*$F$17*'Valuation Summary'!$C$14-'Valuation Summary'!$C$5)/'Valuation Summary'!$C$6,"-") -> - | G22: =IFERROR(($B22*$G$17*'Valuation Summary'!$C$14-'Valuation Summary'!$C$5)/'Valuation Summary'!$C$6,"-") -> - | H22: =IFERROR(($B22*$H$17*'Valuation Summary'!$C$14-'Valuation Summary'!$C$5)/'Valuation Summary'!$C$6,"-") -> - | I22: =IFERROR(($B22*$I$17*'Valuation Summary'!$C$14-'Valuation Summary'!$C$5)/'Valuation Summary'!$C$6,"-") -> - | J22: =IFERROR(($B22*$J$17*'Valuation Summary'!$C$14-'Valuation Summary'!$C$5)/'Valuation Summary'!$C$6,"-") -> -
B23: 300 | C23: =IFERROR(($B23*$C$17*'Valuation Summary'!$C$14-'Valuation Summary'!$C$5)/'Valuation Summary'!$C$6,"-") -> - | D23: =IFERROR(($B23*$D$17*'Valuation Summary'!$C$14-'Valuation Summary'!$C$5)/'Valuation Summary'!$C$6,"-") -> - | E23: =IFERROR(($B23*$E$17*'Valuation Summary'!$C$14-'Valuation Summary'!$C$5)/'Valuation Summary'!$C$6,"-") -> - | F23: =IFERROR(($B23*$F$17*'Valuation Summary'!$C$14-'Valuation Summary'!$C$5)/'Valuation Summary'!$C$6,"-") -> - | G23: =IFERROR(($B23*$G$17*'Valuation Summary'!$C$14-'Valuation Summary'!$C$5)/'Valuation Summary'!$C$6,"-") -> - | H23: =IFERROR(($B23*$H$17*'Valuation Summary'!$C$14-'Valuation Summary'!$C$5)/'Valuation Summary'!$C$6,"-") -> - | I23: =IFERROR(($B23*$I$17*'Valuation Summary'!$C$14-'Valuation Summary'!$C$5)/'Valuation Summary'!$C$6,"-") -> - | J23: =IFERROR(($B23*$J$17*'Valuation Summary'!$C$14-'Valuation Summary'!$C$5)/'Valuation Summary'!$C$6,"-") -> -
B24: 350 | C24: =IFERROR(($B24*$C$17*'Valuation Summary'!$C$14-'Valuation Summary'!$C$5)/'Valuation Summary'!$C$6,"-") -> - | D24: =IFERROR(($B24*$D$17*'Valuation Summary'!$C$14-'Valuation Summary'!$C$5)/'Valuation Summary'!$C$6,"-") -> - | E24: =IFERROR(($B24*$E$17*'Valuation Summary'!$C$14-'Valuation Summary'!$C$5)/'Valuation Summary'!$C$6,"-") -> - | F24: =IFERROR(($B24*$F$17*'Valuation Summary'!$C$14-'Valuation Summary'!$C$5)/'Valuation Summary'!$C$6,"-") -> - | G24: =IFERROR(($B24*$G$17*'Valuation Summary'!$C$14-'Valuation Summary'!$C$5)/'Valuation Summary'!$C$6,"-") -> - | H24: =IFERROR(($B24*$H$17*'Valuation Summary'!$C$14-'Valuation Summary'!$C$5)/'Valuation Summary'!$C$6,"-") -> - | I24: =IFERROR(($B24*$I$17*'Valuation Summary'!$C$14-'Valuation Summary'!$C$5)/'Valuation Summary'!$C$6,"-") -> - | J24: =IFERROR(($B24*$J$17*'Valuation Summary'!$C$14-'Valuation Summary'!$C$5)/'Valuation Summary'!$C$6,"-") -> -
B25: 400 | C25: =IFERROR(($B25*$C$17*'Valuation Summary'!$C$14-'Valuation Summary'!$C$5)/'Valuation Summary'!$C$6,"-") -> - | D25: =IFERROR(($B25*$D$17*'Valuation Summary'!$C$14-'Valuation Summary'!$C$5)/'Valuation Summary'!$C$6,"-") -> - | E25: =IFERROR(($B25*$E$17*'Valuation Summary'!$C$14-'Valuation Summary'!$C$5)/'Valuation Summary'!$C$6,"-") -> - | F25: =IFERROR(($B25*$F$17*'Valuation Summary'!$C$14-'Valuation Summary'!$C$5)/'Valuation Summary'!$C$6,"-") -> - | G25: =IFERROR(($B25*$G$17*'Valuation Summary'!$C$14-'Valuation Summary'!$C$5)/'Valuation Summary'!$C$6,"-") -> - | H25: =IFERROR(($B25*$H$17*'Valuation Summary'!$C$14-'Valuation Summary'!$C$5)/'Valuation Summary'!$C$6,"-") -> - | I25: =IFERROR(($B25*$I$17*'Valuation Summary'!$C$14-'Valuation Summary'!$C$5)/'Valuation Summary'!$C$6,"-") -> - | J25: =IFERROR(($B25*$J$17*'Valuation Summary'!$C$14-'Valuation Summary'!$C$5)/'Valuation Summary'!$C$6,"-") -> -
B26: 500 | C26: =IFERROR(($B26*$C$17*'Valuation Summary'!$C$14-'Valuation Summary'!$C$5)/'Valuation Summary'!$C$6,"-") -> - | D26: =IFERROR(($B26*$D$17*'Valuation Summary'!$C$14-'Valuation Summary'!$C$5)/'Valuation Summary'!$C$6,"-") -> - | E26: =IFERROR(($B26*$E$17*'Valuation Summary'!$C$14-'Valuation Summary'!$C$5)/'Valuation Summary'!$C$6,"-") -> - | F26: =IFERROR(($B26*$F$17*'Valuation Summary'!$C$14-'Valuation Summary'!$C$5)/'Valuation Summary'!$C$6,"-") -> - | G26: =IFERROR(($B26*$G$17*'Valuation Summary'!$C$14-'Valuation Summary'!$C$5)/'Valuation Summary'!$C$6,"-") -> - | H26: =IFERROR(($B26*$H$17*'Valuation Summary'!$C$14-'Valuation Summary'!$C$5)/'Valuation Summary'!$C$6,"-") -> - | I26: =IFERROR(($B26*$I$17*'Valuation Summary'!$C$14-'Valuation Summary'!$C$5)/'Valuation Summary'!$C$6,"-") -> - | J26: =IFERROR(($B26*$J$17*'Valuation Summary'!$C$14-'Valuation Summary'!$C$5)/'Valuation Summary'!$C$6,"-") -> -
