Workbook

Sheet Cover
B3: DISCOUNTED CASH FLOW VALUATION
B4: FCFF Model · WACC · GGM + Exit Multiple · Sensitivity Analysis
B7: Company
B9: Analyst
B11: Valuation Date
B13: Currency | C13: USD ($mm)
B15: Fiscal Year End | C15: December 31
B20: LIVE VALUATION SUMMARY
B21: Enterprise Value ($mm) | D21: ='DCF Valuation'!C39 -> 1130.0217
B22: Equity Value ($mm) | D22: ='DCF Valuation'!C43 -> 1000.0217
B23: DCF Price / Share ($) | D23: ='DCF Valuation'!C54 -> 10.000217
B24: Current Price ($) | D24: ='DCF Valuation'!C46 -> 42
B25: Implied Upside / (Downside) | D25: ='DCF Valuation'!C47 -> -0.76189959
B26: WACC | D26: =WACC!D22 -> 0.10272191
B27: Terminal Growth Rate | D27: ='DCF Valuation'!C25 -> 0.02
B28: EV/EBITDA Exit Multiple | D28: ='DCF Valuation'!C30 -> 8
B29: TV as % of EV | D29: ='DCF Valuation'!C37 -> 0.72187537
B32: SHEET GUIDE
B33: Assumptions | C33: All blue-cell inputs: growth, margins, WACC drivers, bridge
B34: WACC | C34: CAPM cost of equity, after-tax debt cost, capital structure
B35: DCF Valuation | C35: FCFF projection, GGM + Exit Multiple TV, equity bridge
B36: Sensitivity | C36: Table 1: WACC vs g | Table 2: WACC vs EV/EBITDA
B37: Support | C37: D&A schedule, NWC waterfall, debt waterfall

Sheet Assumptions
B2: MODEL ASSUMPTIONS
B4: ASSUMPTION | C4: 2025E | D4: 2026E | E4: 2027E | F4: 2028E | G4: 2029E
B5: REVENUE
B6: Revenue — Base Year ($mm) | C6: 500 | D6: =C6*(1+D7) -> 540 | E6: =D6*(1+E7) -> 577.8 | F6: =E6*(1+F7) -> 612.468 | G6: =F6*(1+G7) -> 643.0914
B7: YoY Revenue Growth (%) | C7: 0.1 | D7: 0.08 | E7: 0.07 | F7: 0.06 | G7: 0.05
B8: PROFITABILITY
B9: EBITDA Margin (%) | C9: 0.22 | D9: 0.23 | E9: 0.24 | F9: 0.25 | G9: 0.26
B10: COGS Margin (% of Revenue) | C10: 0.65 | D10: 0.65 | E10: 0.64 | F10: 0.63 | G10: 0.62
B11: D&A (% of Revenue) | C11: 0.04 | D11: 0.04 | E11: 0.04 | F11: 0.04 | G11: 0.04
B12: Capex (% of Revenue) | C12: 0.06 | D12: 0.06 | E12: 0.05 | F12: 0.05 | G12: 0.05
B13: Effective Tax Rate (%) | C13: 0.21 | D13: 0.21 | E13: 0.21 | F13: 0.21 | G13: 0.21
B14: WORKING CAPITAL
B15: Days Sales Outstanding (DSO) | C15: 45 | D15: 45 | E15: 44 | F15: 44 | G15: 43
B16: Days Inventory Outstanding (DIO) | C16: 30 | D16: 30 | E16: 29 | F16: 29 | G16: 28
B17: Days Payable Outstanding (DPO) | C17: 35 | D17: 35 | E17: 36 | F17: 36 | G17: 37
B18: TERMINAL VALUE & DISCOUNT RATE
B19: Terminal Growth Rate — g (%) | C19: 0.02
B20: EV/EBITDA Exit Multiple (x) | C20: 8
B21: WACC — auto-calculated from WACC sheet | C21: =WACC!D22 -> 0.10272191
B22: EQUITY BRIDGE
B23: Cash & Equivalents ($mm) | C23: 120
B24: Total Debt ($mm) | C24: 250
B25: Minority Interest ($mm) | C25: 0
B26: Diluted Shares Outstanding (mm) | C26: 100
B27: Current Share Price ($) | C27: 42

Sheet WACC
B2: WACC - WEIGHTED AVERAGE COST OF CAPITAL
B4: COMPONENT | C4: INPUT | D4: RESULT
B5: COST OF EQUITY — CAPM
B6: Risk-Free Rate (Rf) | C6: 0.043
B7: Equity Risk Premium (ERP) | C7: 0.055
B8: Levered Beta (β) | C8: 1.15
B9: Size / Company-Specific Premium | C9: 0
B10: Cost of Equity [Ke] | D10: =C6+C8*C7+C9 -> 0.10625
B11: COST OF DEBT
B12: Pre-Tax Cost of Debt (Kd) | C12: 0.055
B13: Marginal Tax Rate | C13: 0.21
B14: After-Tax Cost of Debt [Kd×(1−t)] | D14: =C12*(1-C13) -> 0.04345
B15: CAPITAL STRUCTURE (MARKET VALUE WEIGHTS)
B16: Market Value of Equity ($mm) | D16: =Assumptions!C26*Assumptions!C27 -> 4200
B17: Market Value of Debt ($mm) | D17: =Assumptions!C24 -> 250
B18: Total Capital ($mm) | D18: =D16+D17 -> 4450
B19: Weight of Equity [E/(E+D)] | D19: =D16/D18 -> 0.94382022
B20: Weight of Debt [D/(E+D)] | D20: =D17/D18 -> 0.056179775
B21: WACC OUTPUT
B22: WACC = Ke×We + Kd×(1−t)×Wd | D22: =D10*D19+D14*D20 -> 0.10272191

Sheet DCF Valuation
B1: DCF VALUATION — FREE CASH FLOW TO FIRM (FCFF)
B3: LINE ITEM ($mm) | C3: 2025E | D3: 2026E | E3: 2027E | F3: 2028E | G3: 2029E
B4: INCOME STATEMENT BRIDGE
B5: Revenue ($mm) | C5: =Assumptions!C6 -> 500 | D5: =Assumptions!D6 -> 540 | E5: =Assumptions!E6 -> 577.8 | F5: =Assumptions!F6 -> 612.468 | G5: =Assumptions!G6 -> 643.0914
B6: EBITDA ($mm) | C6: =C5*Assumptions!C9 -> 110 | D6: =D5*Assumptions!D9 -> 124.2 | E6: =E5*Assumptions!E9 -> 138.672 | F6: =F5*Assumptions!F9 -> 153.117 | G6: =G5*Assumptions!G9 -> 167.20376
B7: (-) Depreciation & Amortization ($mm) | C7: =Support!C7 -> 20 | D7: =Support!D7 -> 21.6 | E7: =Support!E7 -> 23.112 | F7: =Support!F7 -> 24.49872 | G7: =Support!G7 -> 25.723656
B8: EBIT ($mm) | C8: =C6-C7 -> 90 | D8: =D6-D7 -> 102.6 | E8: =E6-E7 -> 115.56 | F8: =F6-F7 -> 128.61828 | G8: =G6-G7 -> 141.48011
B9: (-) Tax on EBIT ($mm) | C9: =-C8*Assumptions!C13 -> -18.9 | D9: =-D8*Assumptions!D13 -> -21.546 | E9: =-E8*Assumptions!E13 -> -24.2676 | F9: =-F8*Assumptions!F13 -> -27.009839 | G9: =-G8*Assumptions!G13 -> -29.710823
B10: NOPAT = EBIT × (1 − Tax Rate) ($mm) | C10: =C8+C9 -> 71.1 | D10: =D8+D9 -> 81.054 | E10: =E8+E9 -> 91.2924 | F10: =F8+F9 -> 101.60844 | G10: =G8+G9 -> 111.76929
B11: FREE CASH FLOW ADJUSTMENTS
B12: (+) Add-back D&A ($mm) | C12: =C7 -> 20 | D12: =D7 -> 21.6 | E12: =E7 -> 23.112 | F12: =F7 -> 24.49872 | G12: =G7 -> 25.723656
B13: (-) Capital Expenditures ($mm) | C13: =-C5*Assumptions!C12 -> -30 | D13: =-D5*Assumptions!D12 -> -32.4 | E13: =-E5*Assumptions!E12 -> -28.89 | F13: =-F5*Assumptions!F12 -> -30.6234 | G13: =-G5*Assumptions!G12 -> -32.15457
B14: Net Working Capital ($mm) | C14: =Support!C16 -> 57.191781 | D14: =Support!D16 -> 61.767123 | E14: =Support!E16 -> 62.560701 | F14: =Support!F16 -> 66.431803 | G14: =Support!G16 -> 65.930083
B15: (-) Change in Net Working Capital ($mm) | C15: =0 -> 0 | D15: =-(D14-C14) -> -4.5753425 | E15: =-(E14-D14) -> -0.79357808 | F15: =-(F14-E14) -> -3.8711017 | G15: =-(G14-F14) -> 0.50172036
B16: FREE CASH FLOW TO FIRM (FCFF)
B17: FREE CASH FLOW TO FIRM ($mm) | C17: =C10+C12+C13+C15 -> 61.1 | D17: =D10+D12+D13+D15 -> 65.678658 | E17: =E10+E12+E13+E15 -> 84.720822 | F17: =F10+F12+F13+F15 -> 91.61266 | G17: =G10+G12+G13+G15 -> 105.84009
B18: PRESENT VALUE - PROJECTED FCFFs
B19: WACC (Discount Rate) | C19: =((WACC!C6+(WACC!C8/(1+(1-WACC!C13)*WACC!D17/WACC!D16))*(1+(1-WACC!C13)*Support!C22/WACC!D16)*WACC!C7+WACC!C9)*(WACC!D16/(WACC!D16+Support!C22))+WACC!D14*(Support!C22/(WACC!D16+Support!C22))) -> 0.10278716 | D19: =((WACC!C6+(WACC!C8/(1+(1-WACC!C13)*WACC!D17/WACC!D16))*(1+(1-WACC!C13)*Support!D22/WACC!D16)*WACC!C7+WACC!C9)*(WACC!D16/(WACC!D16+Support!D22))+WACC!D14*(Support!D22/(WACC!D16+Support!D22))) -> 0.10285314 | E19: =((WACC!C6+(WACC!C8/(1+(1-WACC!C13)*WACC!D17/WACC!D16))*(1+(1-WACC!C13)*Support!E22/WACC!D16)*WACC!C7+WACC!C9)*(WACC!D16/(WACC!D16+Support!E22))+WACC!D14*(Support!E22/(WACC!D16+Support!E22))) -> 0.10291989 | F19: =((WACC!C6+(WACC!C8/(1+(1-WACC!C13)*WACC!D17/WACC!D16))*(1+(1-WACC!C13)*Support!F22/WACC!D16)*WACC!C7+WACC!C9)*(WACC!D16/(WACC!D16+Support!F22))+WACC!D14*(Support!F22/(WACC!D16+Support!F22))) -> 0.10298739 | G19: =((WACC!C6+(WACC!C8/(1+(1-WACC!C13)*WACC!D17/WACC!D16))*(1+(1-WACC!C13)*Support!G22/WACC!D16)*WACC!C7+WACC!C9)*(WACC!D16/(WACC!D16+Support!G22))+WACC!D14*(Support!G22/(WACC!D16+Support!G22))) -> 0.10305568
B20: Discount Period (Mid-Year Convention) | C20: =0+0.5 -> 0.5 | D20: =1+0.5 -> 1.5 | E20: =2+0.5 -> 2.5 | F20: =3+0.5 -> 3.5 | G20: =4+0.5 -> 4.5
B21: Discount Factor [1/(1+WACC)^t] | C21: =1/(1+C19)^C20 -> 0.95225695 | D21: =1/(1+D19)^D20 -> 0.86342272 | E21: =1/(1+E19)^E20 -> 0.78278065 | F21: =1/(1+F19)^F20 -> 0.7095828 | G21: =1/(1+G19)^G20 -> 0.64314891
B22: PV of FCFF ($mm) | C22: =C17*C21 -> 58.1829 | D22: =D17*D21 -> 56.708445 | E22: =E17*E21 -> 66.31782 | F22: =F17*F21 -> 65.006767 | G22: =G17*G21 -> 68.070939
B23: Sum of PV of FCFFs ($mm) | C23: =SUM(C22:G22) -> 314.28687
B24: TERMINAL VALUE - GORDON GROWTH MODEL (GGM)
B25: Terminal Growth Rate (g) | C25: =Assumptions!C19 -> 0.02
B26: Terminal Year FCFF ($mm) | C26: =G17*(1+C25) -> 107.95689
B27: Terminal Value — GGM ($mm) | C27: =C26/(G19-C25) -> 1299.8134
B28: PV of GGM Terminal Value ($mm) | C28: =C27/(1+G19)^5 -> 795.96476
B29: TERMINAL VALUE - EV/EBITDA EXIT MULTIPLE METHOD
B30: EV/EBITDA Exit Multiple (x) | C30: =Assumptions!C20 -> 8
B31: Terminal Year EBITDA ($mm) | C31: =G6*(1+C25) -> 170.54784
B32: Terminal Value — Exit Multiple ($mm) | C32: =C30*C31 -> 1364.3827
B33: PV of Exit Multiple TV ($mm) | C33: =C32/(1+G19)^5 -> 835.50495
B34: Blended PV of TV [avg GGM + Exit Multiple] ($mm) | C34: =AVERAGE(C28,C33) -> 815.73486
B35: Implied Perpetuity g [Exit Multiple Cross-Check] | C35: =(G19*C32-G17)/(C32+G17) -> 0.023647641
B36: Sanity Check (implied g vs. long-run GDP) | C36: =IF(C35>0.03,"AGGRESSIVE - implied g exceeds long-run GDP; revise exit multiple downward",IF(C35<0," NEGATIVE - review assumptions"," REASONABLE - implied g within 2%–3% GDP range")) -> REASONABLE - implied g within 2%–3% GDP range
B37: TV as % of Enterprise Value (sanity check) | C37: =IF((C23+C34)>0,C34/(C23+C34),0) -> 0.72187537
B38: ENTERPRISE VALUE - EQUITY BRIDGE
B39: Enterprise Value ($mm) | C39: =C23+C34 -> 1130.0217
B40: (-) Total Debt ($mm) | C40: =Assumptions!C24 -> 250
B41: (-) Minority Interest ($mm) | C41: =Assumptions!C25 -> 0
...

Sheet Sensitivity
B1: SENSITIVITY - EQUITY VALUE PER SHARE ($)
B5: TABLE 1 — EQUITY VALUE / SHARE ($) | WACC vs TERMINAL GROWTH RATE (GGM)
B6: WACC ↓ | C6: 0.005 | D6: 0.01 | E6: 0.015 | F6: 0.02 | G6: 0.025 | H6: 0.03 | I6: 0.035
B7: 0.07 | C7: 13.98 | D7: 15.04 | E7: 16.28 | F7: 17.77 | G7: 19.59 | H7: 21.87 | I7: 24.8
B8: 0.08 | C8: 11.85 | D8: 12.61 | E8: 13.48 | F8: 14.49 | G8: 15.69 | H8: 17.12 | I8: 18.88
B9: 0.09 | C9: 10.23 | D9: 10.79 | E9: 11.43 | F9: 12.15 | G9: 12.99 | H9: 13.96 | I9: 15.12
B10: 0.1 | C10: 8.95 | D10: 9.38 | E10: 9.86 | F10: 10.4 | G10: 11.02 | H10: 11.71 | I10: 12.52
B11: 0.11 | C11: 7.92 | D11: 8.26 | E11: 8.63 | F11: 9.05 | G11: 9.51 | H11: 10.03 | I11: 10.62
B12: 0.12 | C12: 7.08 | D12: 7.35 | E12: 7.64 | F12: 7.97 | G12: 8.33 | H12: 8.73 | I12: 9.17
B13: 0.13 | C13: 6.37 | D13: 6.59 | E13: 6.83 | F13: 7.09 | G13: 7.37 | H13: 7.69 | I13: 8.04
B16: TABLE 2 — EQUITY VALUE / SHARE ($) | WACC vs EV/EBITDA EXIT MULTIPLE
B17: WACC ↓ | C17: 4 | D17: 5 | E17: 6 | F17: 7 | G17: 8 | H17: 9 | I17: 10 | J17: 11 | K17: 12
B18: 0.07 | C18: 7 | D18: 8.21 | E18: 9.43 | F18: 10.64 | G18: 11.86 | H18: 13.08 | I18: 14.29 | J18: 15.51 | K18: 16.72
B19: 0.08 | C19: 6.69 | D19: 7.85 | E19: 9.01 | F19: 10.17 | G19: 11.33 | H19: 12.49 | I19: 13.66 | J19: 14.82 | K19: 15.98
B20: 0.09 | C20: 6.4 | D20: 7.51 | E20: 8.62 | F20: 9.73 | G20: 10.84 | H20: 11.94 | I20: 13.05 | J20: 14.16 | K20: 15.27
B21: 0.1 | C21: 6.13 | D21: 7.19 | E21: 8.24 | F21: 9.3 | G21: 10.36 | H21: 11.42 | I21: 12.48 | J21: 13.54 | K21: 14.6
B22: 0.11 | C22: 5.87 | D22: 6.88 | E22: 7.89 | F22: 8.9 | G22: 9.91 | H22: 10.93 | I22: 11.94 | J22: 12.95 | K22: 13.96
B23: 0.12 | C23: 5.62 | D23: 6.58 | E23: 7.55 | F23: 8.52 | G23: 9.49 | H23: 10.46 | I23: 11.42 | J23: 12.39 | K23: 13.36
B24: 0.13 | C24: 5.38 | D24: 6.31 | E24: 7.23 | F24: 8.16 | G24: 9.08 | H24: 10.01 | I24: 10.93 | J24: 11.86 | K24: 12.79

Sheet Support
B1: SUPPORT SCHEDULES - D&A · NWC · DEBT
B3: LINE ITEM ($mm) | C3: 2025E | D3: 2026E | E3: 2027E | F3: 2028E | G3: 2029E
B4: DEPRECIATION & AMORTIZATION SCHEDULE
B5: Opening PP&E (Net, $mm) | C5: =300 -> 300 | D5: =C8 -> 310 | E5: =D8 -> 320.8 | F5: =E8 -> 326.578 | G5: =F8 -> 332.70268
B6: Capex ($mm) | C6: =Assumptions!C6*Assumptions!C12 -> 30 | D6: =Assumptions!D6*Assumptions!D12 -> 32.4 | E6: =Assumptions!E6*Assumptions!E12 -> 28.89 | F6: =Assumptions!F6*Assumptions!F12 -> 30.6234 | G6: =Assumptions!G6*Assumptions!G12 -> 32.15457
B7: (-) Depreciation ($mm) | C7: =Assumptions!C6*Assumptions!C11 -> 20 | D7: =Assumptions!D6*Assumptions!D11 -> 21.6 | E7: =Assumptions!E6*Assumptions!E11 -> 23.112 | F7: =Assumptions!F6*Assumptions!F11 -> 24.49872 | G7: =Assumptions!G6*Assumptions!G11 -> 25.723656
B8: Closing PP&E (Net, $mm) | C8: =C5+C6-C7 -> 310 | D8: =C8+D6-D7 -> 320.8 | E8: =D8+E6-E7 -> 326.578 | F8: =E8+F6-F7 -> 332.70268 | G8: =F8+G6-G7 -> 339.13359
B9: Total D&A ($mm) | C9: =C7 -> 20 | D9: =D7 -> 21.6 | E9: =E7 -> 23.112 | F9: =F7 -> 24.49872 | G9: =G7 -> 25.723656
B10: NET WORKING CAPITAL SCHEDULE
B11: Revenue ($mm) | C11: =Assumptions!C6 -> 500 | D11: =Assumptions!D6 -> 540 | E11: =Assumptions!E6 -> 577.8 | F11: =Assumptions!F6 -> 612.468 | G11: =Assumptions!G6 -> 643.0914
B12: COGS ($mm) | C12: =C11*Assumptions!C10 -> 325 | D12: =D11*Assumptions!D10 -> 351 | E12: =E11*Assumptions!E10 -> 369.792 | F12: =F11*Assumptions!F10 -> 385.85484 | G12: =G11*Assumptions!G10 -> 398.71667
B13: Accounts Receivable ($mm) | C13: =C11*Assumptions!C15/365 -> 61.643836 | D13: =D11*Assumptions!D15/365 -> 66.575342 | E13: =E11*Assumptions!E15/365 -> 69.652603 | F13: =F11*Assumptions!F15/365 -> 73.831759 | G13: =G11*Assumptions!G15/365 -> 75.761453
B14: Inventory ($mm) | C14: =C12*Assumptions!C16/365 -> 26.712329 | D14: =D12*Assumptions!D16/365 -> 28.849315 | E14: =E12*Assumptions!E16/365 -> 29.380734 | F14: =F12*Assumptions!F16/365 -> 30.65696 | G14: =G12*Assumptions!G16/365 -> 30.586484
B15: Accounts Payable ($mm) | C15: =C12*Assumptions!C17/365 -> 31.164384 | D15: =D12*Assumptions!D17/365 -> 33.657534 | E15: =E12*Assumptions!E17/365 -> 36.472636 | F15: =F12*Assumptions!F17/365 -> 38.056916 | G15: =G12*Assumptions!G17/365 -> 40.417854
B16: Net Working Capital ($mm) | C16: =C13+C14-C15 -> 57.191781 | D16: =D13+D14-D15 -> 61.767123 | E16: =E13+E14-E15 -> 62.560701 | F16: =F13+F14-F15 -> 66.431803 | G16: =G13+G14-G15 -> 65.930083
B17: Change in NWC ($mm) | C17: =0 -> 0 | D17: =D16-C16 -> 4.5753425 | E17: =E16-D16 -> 0.79357808 | F17: =F16-E16 -> 3.8711017 | G17: =G16-F16 -> -0.50172036
B18: DEBT WATERFALL
B19: Opening Debt ($mm) | C19: 250 | D19: =C22 -> 225 | E19: =D22 -> 200 | F19: =E22 -> 175 | G19: =F22 -> 150
B20: New Borrowings ($mm) | C20: 0 | D20: 0 | E20: 0 | F20: 0 | G20: 0
B21: (-) Repayments ($mm) | C21: 25 | D21: 25 | E21: 25 | F21: 25 | G21: 25
B22: Closing Debt ($mm) | C22: =C19+C20-C21 -> 225 | D22: =D19+D20-D21 -> 200 | E22: =E19+E20-E21 -> 175 | F22: =F19+F20-F21 -> 150 | G22: =G19+G20-G21 -> 125
B23: Average Debt ($mm) | C23: =(C19+C21)/2 -> 137.5 | D23: =(D19+D21)/2 -> 125 | E23: =(E19+E21)/2 -> 112.5 | F23: =(F19+F21)/2 -> 100 | G23: =(G19+G21)/2 -> 87.5
B24: Interest Expense ($mm) | C24: =-C22*WACC!C12 -> -12.375 | D24: =-D22*WACC!C12 -> -11 | E24: =-E22*WACC!C12 -> -9.625 | F24: =-F22*WACC!C12 -> -8.25 | G24: =-G22*WACC!C12 -> -6.875
