Workbook

Sheet Dashboard
A1: LEVERAGED BUYOUT MODEL · EXECUTIVE DASHBOARD
C4: Entry EV ($mm) | D4: Equity Invested | E4: Exit EV ($mm) | F4: Gross IRR | G4: MOIC
C5: =Assumptions!C12 -> 0 | D5: =Assumptions!C56 -> 0 | E5: ='Returns Analysis'!C11 -> 0 | F5: ='Returns Analysis'!C19 -> N/A | G5: ='Returns Analysis'!C18 -> -
C6: Entry Transaction | D6: Sponsor Equity | E6: Exit at Year 5 | F6: 5-Year Hold | G6: Money-on-Money
A8: P&L SUMMARY
B9: Metric | C9: FY2024A | D9: FY2025E | E9: FY2026E | F9: FY2027E | G9: FY2028E | H9: FY2029E
B10: Revenue ($mm) | C10: ='Income Statement'!C6 -> 0 | D10: ='Income Statement'!D6 -> 0 | E10: ='Income Statement'!E6 -> 0 | F10: ='Income Statement'!F6 -> 0 | G10: ='Income Statement'!G6 -> 0 | H10: ='Income Statement'!H6 -> 0
B11: YoY Growth | C11: ='Income Statement'!C7 -> "-" | D11: ='Income Statement'!D7 -> - | E11: ='Income Statement'!E7 -> - | F11: ='Income Statement'!F7 -> - | G11: ='Income Statement'!G7 -> - | H11: ='Income Statement'!H7 -> -
B12: Gross Profit | C12: ='Income Statement'!C11 -> 0 | D12: ='Income Statement'!D11 -> 0 | E12: ='Income Statement'!E11 -> 0 | F12: ='Income Statement'!F11 -> 0 | G12: ='Income Statement'!G11 -> 0 | H12: ='Income Statement'!H11 -> 0
B13: Gross Margin | C13: ='Income Statement'!C12 -> - | D13: ='Income Statement'!D12 -> - | E13: ='Income Statement'!E12 -> - | F13: ='Income Statement'!F12 -> - | G13: ='Income Statement'!G12 -> - | H13: ='Income Statement'!H12 -> -
B14: EBITDA | C14: ='Income Statement'!C21 -> 0 | D14: ='Income Statement'!D21 -> 0 | E14: ='Income Statement'!E21 -> 0 | F14: ='Income Statement'!F21 -> 0 | G14: ='Income Statement'!G21 -> 0 | H14: ='Income Statement'!H21 -> 0
B15: EBITDA Margin | C15: ='Income Statement'!C22 -> - | D15: ='Income Statement'!D22 -> - | E15: ='Income Statement'!E22 -> - | F15: ='Income Statement'!F22 -> - | G15: ='Income Statement'!G22 -> - | H15: ='Income Statement'!H22 -> -
B16: EBIT | C16: ='Income Statement'!C24 -> 0 | D16: ='Income Statement'!D24 -> 0 | E16: ='Income Statement'!E24 -> 0 | F16: ='Income Statement'!F24 -> 0 | G16: ='Income Statement'!G24 -> 0 | H16: ='Income Statement'!H24 -> 0
B17: Net Income | C17: ='Income Statement'!C31 -> 0 | D17: ='Income Statement'!D31 -> 0 | E17: ='Income Statement'!E31 -> 0 | F17: ='Income Statement'!F31 -> 0 | G17: ='Income Statement'!G31 -> 0 | H17: ='Income Statement'!H31 -> 0
B18: CapEx | C18: ='Cash Flow Statement'!C12 -> 0 | D18: ='Cash Flow Statement'!D12 -> 0 | E18: ='Cash Flow Statement'!E12 -> 0 | F18: ='Cash Flow Statement'!F12 -> 0 | G18: ='Cash Flow Statement'!G12 -> 0 | H18: ='Cash Flow Statement'!H12 -> 0
B19: FCF (Levered) | C19: ='Cash Flow Statement'!C22 -> 0 | D19: ='Cash Flow Statement'!D22 -> 0 | E19: ='Cash Flow Statement'!E22 -> 0 | F19: ='Cash Flow Statement'!F22 -> 0 | G19: ='Cash Flow Statement'!G22 -> 0 | H19: ='Cash Flow Statement'!H22 -> 0
B20: Total Debt | C20: ='Debt Schedule'!C29 -> 0 | D20: ='Debt Schedule'!D29 -> 0 | E20: ='Debt Schedule'!E29 -> 0 | F20: ='Debt Schedule'!F29 -> 0 | G20: ='Debt Schedule'!G29 -> 0 | H20: ='Debt Schedule'!H29 -> 0
B21: Net Leverage | C21: ='Debt Schedule'!C30 -> - | D21: ='Debt Schedule'!D30 -> - | E21: ='Debt Schedule'!E30 -> - | F21: ='Debt Schedule'!F30 -> - | G21: ='Debt Schedule'!G30 -> - | H21: ='Debt Schedule'!H30 -> -
A23: DEBT PAYDOWN SUMMARY
B24: Tranche | C24: At Entry | D24: FY2025E | E24: FY2026E | F24: FY2027E | G24: FY2028E | H24: FY2029E (Exit)
B25: Revolving Credit Facility | C25: ='Debt Schedule'!C7 -> 0 | D25: ='Debt Schedule'!D7 -> 0 | E25: ='Debt Schedule'!E7 -> 0 | F25: ='Debt Schedule'!F7 -> 0 | G25: ='Debt Schedule'!G7 -> 0 | H25: ='Debt Schedule'!H7 -> 0
B26: Term Loan A | C26: ='Debt Schedule'!C13 -> 0 | D26: ='Debt Schedule'!D13 -> 0 | E26: ='Debt Schedule'!E13 -> 0 | F26: ='Debt Schedule'!F13 -> 0 | G26: ='Debt Schedule'!G13 -> 0 | H26: ='Debt Schedule'!H13 -> 0
B27: Term Loan B | C27: ='Debt Schedule'!C20 -> 0 | D27: ='Debt Schedule'!D20 -> 0 | E27: ='Debt Schedule'!E20 -> 0 | F27: ='Debt Schedule'!F20 -> 0 | G27: ='Debt Schedule'!G20 -> 0 | H27: ='Debt Schedule'!H20 -> 0
B28: Senior Secured Notes | C28: ='Debt Schedule'!C24 -> 0 | D28: ='Debt Schedule'!D24 -> 0 | E28: ='Debt Schedule'!E24 -> 0 | F28: ='Debt Schedule'!F24 -> 0 | G28: ='Debt Schedule'!G24 -> 0 | H28: ='Debt Schedule'!H24 -> 0
B29: Total Debt | C29: ='Debt Schedule'!C29 -> 0 | D29: ='Debt Schedule'!D29 -> 0 | E29: ='Debt Schedule'!E29 -> 0 | F29: ='Debt Schedule'!F29 -> 0 | G29: ='Debt Schedule'!G29 -> 0 | H29: ='Debt Schedule'!H29 -> 0

Sheet Assumptions
A1: LEVERAGED BUYOUT MODEL · ASSUMPTIONS & TRANSACTION PARAMETERS
B4: Label | C4: FY2024A | D4: FY2025E | E4: FY2026E | F4: FY2027E | G4: FY2028E | H4: FY2029E
A5: TRANSACTION ASSUMPTIONS
B6: Entry Year
B7: Hold Period (Years)
B8: Exit Year | C8: =Assumptions!C6+Assumptions!C7 | D8: =Assumptions!C6+Assumptions!C7 | E8: =Assumptions!C6+Assumptions!C7 | F8: =Assumptions!C6+Assumptions!C7 | G8: =Assumptions!C6+Assumptions!C7 | H8: =Assumptions!C6+Assumptions!C7
B9: Entry EV / LTM EBITDA (x)
B10: Exit EV / LTM EBITDA (x)
B11: LTM EBITDA at Entry ($mm)
B12: Entry Enterprise Value ($mm) | C12: =Assumptions!C9*Assumptions!C11 -> 0 | D12: =Assumptions!D9*Assumptions!D11 -> 0 | E12: =Assumptions!E9*Assumptions!E11 -> 0 | F12: =Assumptions!F9*Assumptions!F11 -> 0 | G12: =Assumptions!G9*Assumptions!G11 -> 0 | H12: =Assumptions!H9*Assumptions!H11 -> 0
B13: Net Debt at Entry ($mm)
B14: Equity Purchase Price ($mm) | C14: =Assumptions!C12-Assumptions!C13 -> 0 | D14: =Assumptions!D12-Assumptions!D13 -> 0 | E14: =Assumptions!E12-Assumptions!E13 -> 0 | F14: =Assumptions!F12-Assumptions!F13 -> 0 | G14: =Assumptions!G12-Assumptions!G13 -> 0 | H14: =Assumptions!H12-Assumptions!H13 -> 0
A16: REVENUE ASSUMPTIONS
B17: Revenue – Base Year ($mm)
B18: Revenue Growth – Y1
B19: Revenue Growth – Y2
B20: Revenue Growth – Y3
B21: Revenue Growth – Y4
B22: Revenue Growth – Y5
A24: MARGIN ASSUMPTIONS
B25: Gross Margin %
B26: EBITDA Margin %
B27: D&A as % of Revenue
B28: CapEx as % of Revenue
B29: Change in NWC as % of ΔRevenue
B30: Tax Rate %
A32: DEBT STRUCTURE AT ENTRY ($mm)
B33: Revolving Credit Facility
B34: Term Loan A (TLA)
B35: Term Loan B (TLB)
B36: Senior Secured Notes
B37: Subordinated / Mezzanine Debt
B38: Total Debt | C38: =SUM(Assumptions!C33:C37) -> 0
A40: INTEREST RATES (Annual)
B41: Revolving Credit Facility Rate
B42: Term Loan A Rate
B43: Term Loan B Rate
B44: Senior Secured Notes Rate
B45: Subordinated / Mezzanine Rate
A47: MANDATORY DEBT AMORTIZATION (Annual, $mm)
...

Sheet Income Statement
A1: INCOME STATEMENT · ($mm)
C4: FY2024A | D4: FY2025E | E4: FY2026E | F4: FY2027E | G4: FY2028E | H4: FY2029E
A5: REVENUE
B6: Revenue | C6: =Assumptions!C17 -> 0 | D6: =C6*(1+Assumptions!D18) -> 0 | E6: =D6*(1+Assumptions!E19) -> 0 | F6: =E6*(1+Assumptions!F20) -> 0 | G6: =F6*(1+Assumptions!G21) -> 0 | H6: =G6*(1+Assumptions!H22) -> 0
B7: YoY Growth % | C7: "-" | D7: =IF(C6=0,"-",(D6-C6)/C6) -> - | E7: =IF(D6=0,"-",(E6-D6)/D6) -> - | F7: =IF(E6=0,"-",(F6-E6)/E6) -> - | G7: =IF(F6=0,"-",(G6-F6)/F6) -> - | H7: =IF(G6=0,"-",(H6-G6)/G6) -> -
A9: COST OF GOODS SOLD
B10: Cost of Goods Sold | C10: =-(1-Assumptions!C25)*C6 -> 0 | D10: =-(1-Assumptions!D25)*D6 -> 0 | E10: =-(1-Assumptions!E25)*E6 -> 0 | F10: =-(1-Assumptions!F25)*F6 -> 0 | G10: =-(1-Assumptions!G25)*G6 -> 0 | H10: =-(1-Assumptions!H25)*H6 -> 0
B11: Gross Profit | C11: =C6+C10 -> 0 | D11: =D6+D10 -> 0 | E11: =E6+E10 -> 0 | F11: =F6+F10 -> 0 | G11: =G6+G10 -> 0 | H11: =H6+H10 -> 0
B12: Gross Margin % | C12: =IF(C6=0,"-",C11/C6) -> - | D12: =IF(D6=0,"-",D11/D6) -> - | E12: =IF(E6=0,"-",E11/E6) -> - | F12: =IF(F6=0,"-",F11/F6) -> - | G12: =IF(G6=0,"-",G11/G6) -> - | H12: =IF(H6=0,"-",H11/H6) -> -
A14: OPERATING EXPENSES
B15: Sales & Marketing | C15: =-0.08*C6 -> 0 | D15: =-0.08*D6 -> 0 | E15: =-0.08*E6 -> 0 | F15: =-0.08*F6 -> 0 | G15: =-0.08*G6 -> 0 | H15: =-0.08*H6 -> 0
B16: General & Administrative | C16: =-0.05*C6 -> 0 | D16: =-0.05*D6 -> 0 | E16: =-0.05*E6 -> 0 | F16: =-0.05*F6 -> 0 | G16: =-0.05*G6 -> 0 | H16: =-0.05*H6 -> 0
B17: Research & Development | C17: =-0.03*C6 -> 0 | D17: =-0.03*D6 -> 0 | E17: =-0.03*E6 -> 0 | F17: =-0.03*F6 -> 0 | G17: =-0.03*G6 -> 0 | H17: =-0.03*H6 -> 0
B18: Total Operating Expenses | C18: =SUM(C15:C17) -> 0 | D18: =SUM(D15:D17) -> 0 | E18: =SUM(E15:E17) -> 0 | F18: =SUM(F15:F17) -> 0 | G18: =SUM(G15:G17) -> 0 | H18: =SUM(H15:H17) -> 0
A20: EBITDA
B21: EBITDA | C21: =Assumptions!C26*C6 -> 0 | D21: =Assumptions!D26*D6 -> 0 | E21: =Assumptions!E26*E6 -> 0 | F21: =Assumptions!F26*F6 -> 0 | G21: =Assumptions!G26*G6 -> 0 | H21: =Assumptions!H26*H6 -> 0
B22: EBITDA Margin % | C22: =IF(C6=0,"-",C21/C6) -> - | D22: =IF(D6=0,"-",D21/D6) -> - | E22: =IF(E6=0,"-",E21/E6) -> - | F22: =IF(F6=0,"-",F21/F6) -> - | G22: =IF(G6=0,"-",G21/G6) -> - | H22: =IF(H6=0,"-",H21/H6) -> -
B23: Depreciation & Amortization | C23: =-Assumptions!C27*C6 -> 0 | D23: =-Assumptions!D27*D6 -> 0 | E23: =-Assumptions!E27*E6 -> 0 | F23: =-Assumptions!F27*F6 -> 0 | G23: =-Assumptions!G27*G6 -> 0 | H23: =-Assumptions!H27*H6 -> 0
B24: EBIT (Operating Income) | C24: =C21+C23 -> 0 | D24: =D21+D23 -> 0 | E24: =E21+E23 -> 0 | F24: =F21+F23 -> 0 | G24: =G21+G23 -> 0 | H24: =H21+H23 -> 0
B25: EBIT Margin % | C25: =IF(C6=0,"-",C24/C6) -> - | D25: =IF(D6=0,"-",D24/D6) -> - | E25: =IF(E6=0,"-",E24/E6) -> - | F25: =IF(F6=0,"-",F24/F6) -> - | G25: =IF(G6=0,"-",G24/G6) -> - | H25: =IF(H6=0,"-",H24/H6) -> -
A27: BELOW THE LINE
B28: Interest Expense | C28: ='Debt Schedule'!C26 -> 0 | D28: ='Debt Schedule'!D26 -> 0 | E28: ='Debt Schedule'!E26 -> 0 | F28: ='Debt Schedule'!F26 -> 0 | G28: ='Debt Schedule'!G26 -> 0 | H28: ='Debt Schedule'!H26 -> 0
B29: EBT (Pre-Tax Income) | C29: =C24+C28 -> 0 | D29: =D24+D28 -> 0 | E29: =E24+E28 -> 0 | F29: =F24+F28 -> 0 | G29: =G24+G28 -> 0 | H29: =H24+H28 -> 0
B30: Income Tax Expense | C30: =IF(C29>0,-Assumptions!C30*C29,0) -> 0 | D30: =IF(D29>0,-Assumptions!D30*D29,0) -> 0 | E30: =IF(E29>0,-Assumptions!E30*E29,0) -> 0 | F30: =IF(F29>0,-Assumptions!F30*F29,0) -> 0 | G30: =IF(G29>0,-Assumptions!G30*G29,0) -> 0 | H30: =IF(H29>0,-Assumptions!H30*H29,0) -> 0
B31: Net Income | C31: =C29+C30 -> 0 | D31: =D29+D30 -> 0 | E31: =E29+E30 -> 0 | F31: =F29+F30 -> 0 | G31: =G29+G30 -> 0 | H31: =H29+H30 -> 0
B32: Net Margin % | C32: =IF(C6=0,"-",C31/C6) -> - | D32: =IF(D6=0,"-",D31/D6) -> - | E32: =IF(E6=0,"-",E31/E6) -> - | F32: =IF(F6=0,"-",F31/F6) -> - | G32: =IF(G6=0,"-",G31/G6) -> - | H32: =IF(H6=0,"-",H31/H6) -> -

Sheet Debt Schedule
A1: DEBT SCHEDULE & INTEREST · ($mm)
C4: FY2024A | D4: FY2025E | E4: FY2026E | F4: FY2027E | G4: FY2028E | H4: FY2029E
A5: REVOLVING CREDIT FACILITY
B6: Beginning Balance | C6: =Assumptions!C33 -> 0 | D6: =C7 -> 0 | E6: =D7 -> 0 | F6: =E7 -> 0 | G6: =F7 -> 0 | H6: =G7 -> 0
B7: Ending Balance | C7: =C6 -> 0 | D7: =D6 -> 0 | E7: =E6 -> 0 | F7: =F6 -> 0 | G7: =G6 -> 0 | H7: =H6 -> 0
B8: Interest Expense | C8: =-(C6+C7)/2*Assumptions!C41 -> 0 | D8: =-(D6+D7)/2*Assumptions!C41 -> 0 | E8: =-(E6+E7)/2*Assumptions!C41 -> 0 | F8: =-(F6+F7)/2*Assumptions!C41 -> 0 | G8: =-(G6+G7)/2*Assumptions!C41 -> 0 | H8: =-(H6+H7)/2*Assumptions!C41 -> 0
A10: TERM LOAN A (TLA)
B11: Beginning Balance | C11: =Assumptions!C34 -> 0 | D11: =C13 -> 0 | E11: =D13 -> 0 | F11: =E13 -> 0 | G11: =F13 -> 0 | H11: =G13 -> 0
B12: Mandatory Amortization | C12: =-MIN(Assumptions!C48,MAX(0,C11)) -> 0 | D12: =-MIN(Assumptions!C48,MAX(0,D11)) -> 0 | E12: =-MIN(Assumptions!C48,MAX(0,E11)) -> 0 | F12: =-MIN(Assumptions!C48,MAX(0,F11)) -> 0 | G12: =-MIN(Assumptions!C48,MAX(0,G11)) -> 0 | H12: =-MIN(Assumptions!C48,MAX(0,H11)) -> 0
B13: Ending Balance | C13: =C11+C12 -> 0 | D13: =D11+D12 -> 0 | E13: =E11+E12 -> 0 | F13: =F11+F12 -> 0 | G13: =G11+G12 -> 0 | H13: =H11+H12 -> 0
B14: Interest Expense | C14: =-(C11+C13)/2*Assumptions!C42 -> 0 | D14: =-(D11+D13)/2*Assumptions!C42 -> 0 | E14: =-(E11+E13)/2*Assumptions!C42 -> 0 | F14: =-(F11+F13)/2*Assumptions!C42 -> 0 | G14: =-(G11+G13)/2*Assumptions!C42 -> 0 | H14: =-(H11+H13)/2*Assumptions!C42 -> 0
A16: TERM LOAN B (TLB)
B17: Beginning Balance | C17: =Assumptions!C35 -> 0 | D17: =C20 -> 0 | E17: =D20 -> 0 | F17: =E20 -> 0 | G17: =F20 -> 0 | H17: =G20 -> 0
B18: Mandatory Amortization | C18: =-MIN(Assumptions!C49,MAX(0,C17)) -> 0 | D18: =-MIN(Assumptions!C49,MAX(0,D17)) -> 0 | E18: =-MIN(Assumptions!C49,MAX(0,E17)) -> 0 | F18: =-MIN(Assumptions!C49,MAX(0,F17)) -> 0 | G18: =-MIN(Assumptions!C49,MAX(0,G17)) -> 0 | H18: =-MIN(Assumptions!C49,MAX(0,H17)) -> 0
B19: Cash Sweep (Optional) | C19: =-MIN(MAX(0,'Cash Flow Statement'!C22+C12+C18),MAX(0,C17+C18)) -> 0 | D19: =-MIN(MAX(0,'Cash Flow Statement'!D22+D12+D18),MAX(0,D17+D18)) -> 0 | E19: =-MIN(MAX(0,'Cash Flow Statement'!E22+E12+E18),MAX(0,E17+E18)) -> 0 | F19: =-MIN(MAX(0,'Cash Flow Statement'!F22+F12+F18),MAX(0,F17+F18)) -> 0 | G19: =-MIN(MAX(0,'Cash Flow Statement'!G22+G12+G18),MAX(0,G17+G18)) -> 0 | H19: =-MIN(MAX(0,'Cash Flow Statement'!H22+H12+H18),MAX(0,H17+H18)) -> 0
B20: Ending Balance | C20: =C17+C18+C19 -> 0 | D20: =D17+D18+D19 -> 0 | E20: =E17+E18+E19 -> 0 | F20: =F17+F18+F19 -> 0 | G20: =G17+G18+G19 -> 0 | H20: =H17+H18+H19 -> 0
B21: Interest Expense | C21: =-(C17+C20)/2*Assumptions!C43 -> 0 | D21: =-(D17+D20)/2*Assumptions!C43 -> 0 | E21: =-(E17+E20)/2*Assumptions!C43 -> 0 | F21: =-(F17+F20)/2*Assumptions!C43 -> 0 | G21: =-(G17+G20)/2*Assumptions!C43 -> 0 | H21: =-(H17+H20)/2*Assumptions!C43 -> 0
A23: SENIOR SECURED NOTES
B24: Beginning Balance | C24: =Assumptions!C36 -> 0 | D24: =Assumptions!C36 -> 0 | E24: =Assumptions!C36 -> 0 | F24: =Assumptions!C36 -> 0 | G24: =Assumptions!C36 -> 0 | H24: =Assumptions!C36 -> 0
B25: Interest Expense | C25: =-C24*Assumptions!C44 -> 0 | D25: =-D24*Assumptions!C44 -> 0 | E25: =-E24*Assumptions!C44 -> 0 | F25: =-F24*Assumptions!C44 -> 0 | G25: =-G24*Assumptions!C44 -> 0 | H25: =-H24*Assumptions!C44 -> 0
A27: SUMMARY
B28: Total Debt – Beginning | C28: =C6+C11+C17+C24 -> 0 | D28: =D6+D11+D17+D24 -> 0 | E28: =E6+E11+E17+E24 -> 0 | F28: =F6+F11+F17+F24 -> 0 | G28: =G6+G11+G17+G24 -> 0 | H28: =H6+H11+H17+H24 -> 0
B29: Total Debt – Ending | C29: =C7+C13+C20+C24 -> 0 | D29: =D7+D13+D20+D24 -> 0 | E29: =E7+E13+E20+E24 -> 0 | F29: =F7+F13+F20+F24 -> 0 | G29: =G7+G13+G20+G24 -> 0 | H29: =H7+H13+H20+H24 -> 0
B30: Net Leverage (x) – Ending | C30: =IF('Income Statement'!C21=0,"-",-C29/'Income Statement'!C21) -> - | D30: =IF('Income Statement'!D21=0,"-",-D29/'Income Statement'!D21) -> - | E30: =IF('Income Statement'!E21=0,"-",-E29/'Income Statement'!E21) -> - | F30: =IF('Income Statement'!F21=0,"-",-F29/'Income Statement'!F21) -> - | G30: =IF('Income Statement'!G21=0,"-",-G29/'Income Statement'!G21) -> - | H30: =IF('Income Statement'!H21=0,"-",-H29/'Income Statement'!H21) -> -
B31: Interest Coverage (x) – EBITDA/Interest | C31: =IF(C26=0,"-",-'Income Statement'!C21/C26) -> - | D31: =IF(D26=0,"-",-'Income Statement'!D21/D26) -> - | E31: =IF(E26=0,"-",-'Income Statement'!E21/E26) -> - | F31: =IF(F26=0,"-",-'Income Statement'!F21/F26) -> - | G31: =IF(G26=0,"-",-'Income Statement'!G21/G26) -> - | H31: =IF(H26=0,"-",-'Income Statement'!H21/H26) -> -

Sheet Cash Flow Statement
A1: CASH FLOW STATEMENT · ($mm)
C4: FY2024A | D4: FY2025E | E4: FY2026E | F4: FY2027E | G4: FY2028E | H4: FY2029E
A5: OPERATING ACTIVITIES
B6: Net Income | C6: ='Income Statement'!C31 -> 0 | D6: ='Income Statement'!D31 -> 0 | E6: ='Income Statement'!E31 -> 0 | F6: ='Income Statement'!F31 -> 0 | G6: ='Income Statement'!G31 -> 0 | H6: ='Income Statement'!H31 -> 0
B7: Add: D&A | C7: =-'Income Statement'!C23 -> 0 | D7: =-'Income Statement'!D23 -> 0 | E7: =-'Income Statement'!E23 -> 0 | F7: =-'Income Statement'!F23 -> 0 | G7: =-'Income Statement'!G23 -> 0 | H7: =-'Income Statement'!H23 -> 0
B8: Change in Net Working Capital | C8: =0 -> 0 | D8: =-Assumptions!D29*('Income Statement'!D6-'Income Statement'!C6) -> 0 | E8: =-Assumptions!E29*('Income Statement'!E6-'Income Statement'!D6) -> 0 | F8: =-Assumptions!F29*('Income Statement'!F6-'Income Statement'!E6) -> 0 | G8: =-Assumptions!G29*('Income Statement'!G6-'Income Statement'!F6) -> 0 | H8: =-Assumptions!H29*('Income Statement'!H6-'Income Statement'!G6) -> 0
B9: Cash from Operations | C9: =SUM(C6:C8) -> 0 | D9: =SUM(D6:D8) -> 0 | E9: =SUM(E6:E8) -> 0 | F9: =SUM(F6:F8) -> 0 | G9: =SUM(G6:G8) -> 0 | H9: =SUM(H6:H8) -> 0
A11: INVESTING ACTIVITIES
B12: Capital Expenditures | C12: =-Assumptions!C28*'Income Statement'!C6 -> 0 | D12: =-Assumptions!D28*'Income Statement'!D6 -> 0 | E12: =-Assumptions!E28*'Income Statement'!E6 -> 0 | F12: =-Assumptions!F28*'Income Statement'!F6 -> 0 | G12: =-Assumptions!G28*'Income Statement'!G6 -> 0 | H12: =-Assumptions!H28*'Income Statement'!H6 -> 0
B13: Cash from Investing | C13: =C12 -> 0 | D13: =D12 -> 0 | E13: =E12 -> 0 | F13: =F12 -> 0 | G13: =G12 -> 0 | H13: =H12 -> 0
A15: FINANCING ACTIVITIES
B16: TLA Repayment | C16: ='Debt Schedule'!C12 -> 0 | D16: ='Debt Schedule'!D12 -> 0 | E16: ='Debt Schedule'!E12 -> 0 | F16: ='Debt Schedule'!F12 -> 0 | G16: ='Debt Schedule'!G12 -> 0 | H16: ='Debt Schedule'!H12 -> 0
B17: TLB Repayment | C17: ='Debt Schedule'!C18 -> 0 | D17: ='Debt Schedule'!D18 -> 0 | E17: ='Debt Schedule'!E18 -> 0 | F17: ='Debt Schedule'!F18 -> 0 | G17: ='Debt Schedule'!G18 -> 0 | H17: ='Debt Schedule'!H18 -> 0
B18: TLB Cash Sweep | C18: ='Debt Schedule'!C19 -> 0 | D18: ='Debt Schedule'!D19 -> 0 | E18: ='Debt Schedule'!E19 -> 0 | F18: ='Debt Schedule'!F19 -> 0 | G18: ='Debt Schedule'!G19 -> 0 | H18: ='Debt Schedule'!H19 -> 0
B19: Cash from Financing | C19: =SUM(C16:C18) -> 0 | D19: =SUM(D16:D18) -> 0 | E19: =SUM(E16:E18) -> 0 | F19: =SUM(F16:F18) -> 0 | G19: =SUM(G16:G18) -> 0 | H19: =SUM(H16:H18) -> 0
A21: FREE CASH FLOW
B22: Free Cash Flow (Levered) | C22: =C9+C13 -> 0 | D22: =D9+D13 -> 0 | E22: =E9+E13 -> 0 | F22: =F9+F13 -> 0 | G22: =G9+G13 -> 0 | H22: =H9+H13 -> 0
B23: Unlevered Free Cash Flow (UFCF) | C23: ='Income Statement'!C21*(1-Assumptions!C30)-'Income Statement'!C23+C8+C12 -> 0 | D23: ='Income Statement'!D21*(1-Assumptions!D30)-'Income Statement'!D23+D8+D12 -> 0 | E23: ='Income Statement'!E21*(1-Assumptions!E30)-'Income Statement'!E23+E8+E12 -> 0 | F23: ='Income Statement'!F21*(1-Assumptions!F30)-'Income Statement'!F23+F8+F12 -> 0 | G23: ='Income Statement'!G21*(1-Assumptions!G30)-'Income Statement'!G23+G8+G12 -> 0 | H23: ='Income Statement'!H21*(1-Assumptions!H30)-'Income Statement'!H23+H8+H12 -> 0
A25: CASH BALANCE
B26: Beginning Cash | C26: 0 | D26: =C27 -> 0 | E26: =D27 -> 0 | F26: =E27 -> 0 | G26: =F27 -> 0 | H26: =G27 -> 0
B27: Ending Cash | C27: =C26+C22 -> 0 | D27: =D26+D22 -> 0 | E27: =E26+E22 -> 0 | F27: =F26+F22 -> 0 | G27: =G26+G22 -> 0 | H27: =H26+H22 -> 0

Sheet Balance Sheet
A1: BALANCE SHEET · ($mm)
C4: FY2024A | D4: FY2025E | E4: FY2026E | F4: FY2027E | G4: FY2028E | H4: FY2029E
A5: CURRENT ASSETS
B6: Cash & Equivalents | C6: ='Cash Flow Statement'!C26 -> 0 | D6: ='Cash Flow Statement'!D26 -> 0 | E6: ='Cash Flow Statement'!E26 -> 0 | F6: ='Cash Flow Statement'!F26 -> 0 | G6: ='Cash Flow Statement'!G26 -> 0 | H6: ='Cash Flow Statement'!H26 -> 0
B7: Accounts Receivable | C7: ='Income Statement'!C6*0.12 -> 0 | D7: ='Income Statement'!D6*0.12 -> 0 | E7: ='Income Statement'!E6*0.12 -> 0 | F7: ='Income Statement'!F6*0.12 -> 0 | G7: ='Income Statement'!G6*0.12 -> 0 | H7: ='Income Statement'!H6*0.12 -> 0
B8: Inventory | C8: ='Income Statement'!C6*0.08 -> 0 | D8: ='Income Statement'!D6*0.08 -> 0 | E8: ='Income Statement'!E6*0.08 -> 0 | F8: ='Income Statement'!F6*0.08 -> 0 | G8: ='Income Statement'!G6*0.08 -> 0 | H8: ='Income Statement'!H6*0.08 -> 0
B9: Other Current Assets | C9: ='Income Statement'!C6*0.03 -> 0 | D9: ='Income Statement'!D6*0.03 -> 0 | E9: ='Income Statement'!E6*0.03 -> 0 | F9: ='Income Statement'!F6*0.03 -> 0 | G9: ='Income Statement'!G6*0.03 -> 0 | H9: ='Income Statement'!H6*0.03 -> 0
B10: Total Current Assets | C10: =SUM(C6:C9) -> 0 | D10: =SUM(D6:D9) -> 0 | E10: =SUM(E6:E9) -> 0 | F10: =SUM(F6:F9) -> 0 | G10: =SUM(G6:G9) -> 0 | H10: =SUM(H6:H9) -> 0
A12: NON-CURRENT ASSETS
B13: PP&E – Gross | C13: 0 | D13: =C13+'Cash Flow Statement'!D12*-1+'Income Statement'!D23 -> 0 | E13: =D13+'Cash Flow Statement'!E12*-1+'Income Statement'!E23 -> 0 | F13: =E13+'Cash Flow Statement'!F12*-1+'Income Statement'!F23 -> 0 | G13: =F13+'Cash Flow Statement'!G12*-1+'Income Statement'!G23 -> 0 | H13: =G13+'Cash Flow Statement'!H12*-1+'Income Statement'!H23 -> 0
B14: Accumulated Depreciation | C14: =0 -> 0 | D14: =C14+'Income Statement'!C23 -> 0 | E14: =D14+'Income Statement'!D23 -> 0 | F14: =E14+'Income Statement'!E23 -> 0 | G14: =F14+'Income Statement'!F23 -> 0 | H14: =G14+'Income Statement'!G23 -> 0
B15: PP&E – Net | C15: =C13+C14 -> 0 | D15: =D13+D14 -> 0 | E15: =E13+E14 -> 0 | F15: =F13+F14 -> 0 | G15: =G13+G14 -> 0 | H15: =H13+H14 -> 0
B16: Goodwill & Intangibles | C16: 0
B17: Total Non-Current Assets | C17: =C15+C16 -> 0 | D17: =D15+D16 -> 0 | E17: =E15+E16 -> 0 | F17: =F15+F16 -> 0 | G17: =G15+G16 -> 0 | H17: =H15+H16 -> 0
B19: TOTAL ASSETS | C19: =C10+C17 -> 0 | D19: =D10+D17 -> 0 | E19: =E10+E17 -> 0 | F19: =F10+F17 -> 0 | G19: =G10+G17 -> 0 | H19: =H10+H17 -> 0
A21: CURRENT LIABILITIES
B22: Accounts Payable | C22: ='Income Statement'!C10*-0.15 -> 0 | D22: ='Income Statement'!D10*-0.15 -> 0 | E22: ='Income Statement'!E10*-0.15 -> 0 | F22: ='Income Statement'!F10*-0.15 -> 0 | G22: ='Income Statement'!G10*-0.15 -> 0 | H22: ='Income Statement'!H10*-0.15 -> 0
B23: Accrued Liabilities | C23: ='Income Statement'!C6*0.04 -> 0 | D23: ='Income Statement'!D6*0.04 -> 0 | E23: ='Income Statement'!E6*0.04 -> 0 | F23: ='Income Statement'!F6*0.04 -> 0 | G23: ='Income Statement'!G6*0.04 -> 0 | H23: ='Income Statement'!H6*0.04 -> 0
B24: Current Portion of Debt | C24: ='Debt Schedule'!C12*-1+Assumptions!C48 -> 0 | D24: ='Debt Schedule'!D12*-1+Assumptions!C48 -> 0 | E24: ='Debt Schedule'!E12*-1+Assumptions!C48 -> 0 | F24: ='Debt Schedule'!F12*-1+Assumptions!C48 -> 0 | G24: ='Debt Schedule'!G12*-1+Assumptions!C48 -> 0 | H24: ='Debt Schedule'!H12*-1+Assumptions!C48 -> 0
B25: Total Current Liabilities | C25: =SUM(C22:C24) -> 0 | D25: =SUM(D22:D24) -> 0 | E25: =SUM(E22:E24) -> 0 | F25: =SUM(F22:F24) -> 0 | G25: =SUM(G22:G24) -> 0 | H25: =SUM(H22:H24) -> 0
A27: NON-CURRENT LIABILITIES
B28: Long-Term Debt | C28: ='Debt Schedule'!C28 -> 0 | D28: ='Debt Schedule'!D28 -> 0 | E28: ='Debt Schedule'!E28 -> 0 | F28: ='Debt Schedule'!F28 -> 0 | G28: ='Debt Schedule'!G28 -> 0 | H28: ='Debt Schedule'!H28 -> 0
B29: Other LT Liabilities | C29: ='Income Statement'!C6*0.02 -> 0 | D29: ='Income Statement'!D6*0.02 -> 0 | E29: ='Income Statement'!E6*0.02 -> 0 | F29: ='Income Statement'!F6*0.02 -> 0 | G29: ='Income Statement'!G6*0.02 -> 0 | H29: ='Income Statement'!H6*0.02 -> 0
B30: Total Non-Current Liabilities | C30: =C28+C29 -> 0 | D30: =D28+D29 -> 0 | E30: =E28+E29 -> 0 | F30: =F28+F29 -> 0 | G30: =G28+G29 -> 0 | H30: =H28+H29 -> 0
B32: TOTAL LIABILITIES | C32: =C25+C30 -> 0 | D32: =D25+D30 -> 0 | E32: =E25+E30 -> 0 | F32: =F25+F30 -> 0 | G32: =G25+G30 -> 0 | H32: =H25+H30 -> 0
A34: SHAREHOLDERS' EQUITY
B35: Contributed Equity | C35: =Assumptions!C56 -> 0 | D35: =Assumptions!C56 -> 0 | E35: =Assumptions!C56 -> 0 | F35: =Assumptions!C56 -> 0 | G35: =Assumptions!C56 -> 0 | H35: =Assumptions!C56 -> 0
B36: Retained Earnings | C36: ='Income Statement'!C31 -> 0 | D36: =C36+'Income Statement'!D31 -> 0 | E36: =D36+'Income Statement'!E31 -> 0 | F36: =E36+'Income Statement'!F31 -> 0 | G36: =F36+'Income Statement'!G31 -> 0 | H36: =G36+'Income Statement'!H31 -> 0
B37: Total Equity | C37: =C35+C36 -> 0 | D37: =D35+D36 -> 0 | E37: =E35+E36 -> 0 | F37: =F35+F36 -> 0 | G37: =G35+G36 -> 0 | H37: =H35+H36 -> 0
B39: TOTAL LIABILITIES + EQUITY | C39: =C32+C37 -> 0 | D39: =D32+D37 -> 0 | E39: =E32+E37 -> 0 | F39: =F32+F37 -> 0 | G39: =G32+G37 -> 0 | H39: =H32+H37 -> 0
B40: Balance Check (must be 0) | C40: =C19-C39 -> 0 | D40: =D19-D39 -> 0 | E40: =E19-E39 -> 0 | F40: =F19-F39 -> 0 | G40: =G19-G39 -> 0 | H40: =H19-H39 -> 0

Sheet Returns Analysis
A1: RETURNS ANALYSIS · IRR · MOIC · SENSITIVITY
C4: Base Case
A5: ENTRY & EXIT PARAMETERS
B6: Entry Enterprise Value ($mm) | C6: =Assumptions!C12 -> 0
B7: Entry Equity Value ($mm) | C7: =Assumptions!C14 -> 0
B8: Total Equity Invested ($mm) | C8: =Assumptions!C56 -> 0
B9: Exit Year EBITDA ($mm) | C9: ='Income Statement'!H21 -> 0
B10: Exit EV/EBITDA Multiple (x) | C10: =Assumptions!C10 -> 0
B11: Exit Enterprise Value ($mm) | C11: =C9*C10 -> 0
B12: Exit Net Debt ($mm) | C12: ='Debt Schedule'!H29 -> 0
B13: Exit Equity Value ($mm) | C13: =C11+C12 -> 0
B14: Management Promote (10%) | C14: =-Assumptions!$C$58*C13 -> 0
B15: Net Proceeds to Sponsor ($mm) | C15: =C13+C14 -> 0
A17: RETURN METRICS
B18: Money-on-Money (MOIC) | C18: =IF(C8=0,"-",C15/C8) -> -
B19: Gross IRR (5-Year Hold) | C19: =IFERROR(RATE(Assumptions!C7,0,-C8,C15),"N/A") -> N/A
B20: Cash Yield (Avg Annual) | C20: =IF(C8=0,"-",(C15-C8)/C8/Assumptions!C7) -> -
B21: EBITDA Growth (Entry→Exit) | C21: =IF('Income Statement'!C21=0,"-",('Income Statement'!H21-'Income Statement'!C21)/'Income Statement'!C21) -> -
B22: Equity Bridge – EBITDA Growth | C22: =('Income Statement'!H21-'Income Statement'!C21)*Assumptions!C10 -> 0
B23: Equity Bridge – Multiple Expansion | C23: =(Assumptions!C10-Assumptions!C9)*'Income Statement'!H21 -> 0
B24: Equity Bridge – Debt Paydown | C24: =-('Debt Schedule'!H29-'Debt Schedule'!C28) -> 0
B25: Equity Bridge – Total Value Created | C25: =IFERROR(C21+C22+C23,"N/A") -> N/A
A27: SENSITIVITY TABLE – IRR vs EXIT MULTIPLE / ENTRY MULTIPLE
B28: IRR ↓Exit / Entry→ | C28: 8 | D28: 9 | E28: 10 | F28: 11 | G28: 12
B29: 7 | C29: =IFERROR(RATE(Assumptions!$C$7,0,-(8*Assumptions!$C$11-Assumptions!$C$13+Assumptions!$C$55),(1-Assumptions!$C$58)*(7*'Income Statement'!$H$21+'Debt Schedule'!$H$29)),"N/A") -> N/A | D29: =IFERROR(RATE(Assumptions!$C$7,0,-(9*Assumptions!$C$11-Assumptions!$C$13+Assumptions!$C$55),(1-Assumptions!$C$58)*(7*'Income Statement'!$H$21+'Debt Schedule'!$H$29)),"N/A") -> N/A | E29: =IFERROR(RATE(Assumptions!$C$7,0,-(10*Assumptions!$C$11-Assumptions!$C$13+Assumptions!$C$55),(1-Assumptions!$C$58)*(7*'Income Statement'!$H$21+'Debt Schedule'!$H$29)),"N/A") -> N/A | F29: =IFERROR(RATE(Assumptions!$C$7,0,-(11*Assumptions!$C$11-Assumptions!$C$13+Assumptions!$C$55),(1-Assumptions!$C$58)*(7*'Income Statement'!$H$21+'Debt Schedule'!$H$29)),"N/A") -> N/A | G29: =IFERROR(RATE(Assumptions!$C$7,0,-(12*Assumptions!$C$11-Assumptions!$C$13+Assumptions!$C$55),(1-Assumptions!$C$58)*(7*'Income Statement'!$H$21+'Debt Schedule'!$H$29)),"N/A") -> N/A
B30: 8 | C30: =IFERROR(RATE(Assumptions!$C$7,0,-(8*Assumptions!$C$11-Assumptions!$C$13+Assumptions!$C$55),(1-Assumptions!$C$58)*(8*'Income Statement'!$H$21+'Debt Schedule'!$H$29)),"N/A") -> N/A | D30: =IFERROR(RATE(Assumptions!$C$7,0,-(9*Assumptions!$C$11-Assumptions!$C$13+Assumptions!$C$55),(1-Assumptions!$C$58)*(8*'Income Statement'!$H$21+'Debt Schedule'!$H$29)),"N/A") -> N/A | E30: =IFERROR(RATE(Assumptions!$C$7,0,-(10*Assumptions!$C$11-Assumptions!$C$13+Assumptions!$C$55),(1-Assumptions!$C$58)*(8*'Income Statement'!$H$21+'Debt Schedule'!$H$29)),"N/A") -> N/A | F30: =IFERROR(RATE(Assumptions!$C$7,0,-(11*Assumptions!$C$11-Assumptions!$C$13+Assumptions!$C$55),(1-Assumptions!$C$58)*(8*'Income Statement'!$H$21+'Debt Schedule'!$H$29)),"N/A") -> N/A | G30: =IFERROR(RATE(Assumptions!$C$7,0,-(12*Assumptions!$C$11-Assumptions!$C$13+Assumptions!$C$55),(1-Assumptions!$C$58)*(8*'Income Statement'!$H$21+'Debt Schedule'!$H$29)),"N/A") -> N/A
B31: 9 | C31: =IFERROR(RATE(Assumptions!$C$7,0,-(8*Assumptions!$C$11-Assumptions!$C$13+Assumptions!$C$55),(1-Assumptions!$C$58)*(9*'Income Statement'!$H$21+'Debt Schedule'!$H$29)),"N/A") -> N/A | D31: =IFERROR(RATE(Assumptions!$C$7,0,-(9*Assumptions!$C$11-Assumptions!$C$13+Assumptions!$C$55),(1-Assumptions!$C$58)*(9*'Income Statement'!$H$21+'Debt Schedule'!$H$29)),"N/A") -> N/A | E31: =IFERROR(RATE(Assumptions!$C$7,0,-(10*Assumptions!$C$11-Assumptions!$C$13+Assumptions!$C$55),(1-Assumptions!$C$58)*(9*'Income Statement'!$H$21+'Debt Schedule'!$H$29)),"N/A") -> N/A | F31: =IFERROR(RATE(Assumptions!$C$7,0,-(11*Assumptions!$C$11-Assumptions!$C$13+Assumptions!$C$55),(1-Assumptions!$C$58)*(9*'Income Statement'!$H$21+'Debt Schedule'!$H$29)),"N/A") -> N/A | G31: =IFERROR(RATE(Assumptions!$C$7,0,-(12*Assumptions!$C$11-Assumptions!$C$13+Assumptions!$C$55),(1-Assumptions!$C$58)*(9*'Income Statement'!$H$21+'Debt Schedule'!$H$29)),"N/A") -> N/A
B32: 10 | C32: =IFERROR(RATE(Assumptions!$C$7,0,-(8*Assumptions!$C$11-Assumptions!$C$13+Assumptions!$C$55),(1-Assumptions!$C$58)*(10*'Income Statement'!$H$21+'Debt Schedule'!$H$29)),"N/A") -> N/A | D32: =IFERROR(RATE(Assumptions!$C$7,0,-(9*Assumptions!$C$11-Assumptions!$C$13+Assumptions!$C$55),(1-Assumptions!$C$58)*(10*'Income Statement'!$H$21+'Debt Schedule'!$H$29)),"N/A") -> N/A | E32: =IFERROR(RATE(Assumptions!$C$7,0,-(10*Assumptions!$C$11-Assumptions!$C$13+Assumptions!$C$55),(1-Assumptions!$C$58)*(10*'Income Statement'!$H$21+'Debt Schedule'!$H$29)),"N/A") -> N/A | F32: =IFERROR(RATE(Assumptions!$C$7,0,-(11*Assumptions!$C$11-Assumptions!$C$13+Assumptions!$C$55),(1-Assumptions!$C$58)*(10*'Income Statement'!$H$21+'Debt Schedule'!$H$29)),"N/A") -> N/A | G32: =IFERROR(RATE(Assumptions!$C$7,0,-(12*Assumptions!$C$11-Assumptions!$C$13+Assumptions!$C$55),(1-Assumptions!$C$58)*(10*'Income Statement'!$H$21+'Debt Schedule'!$H$29)),"N/A") -> N/A
B33: 11 | C33: =IFERROR(RATE(Assumptions!$C$7,0,-(8*Assumptions!$C$11-Assumptions!$C$13+Assumptions!$C$55),(1-Assumptions!$C$58)*(11*'Income Statement'!$H$21+'Debt Schedule'!$H$29)),"N/A") -> N/A | D33: =IFERROR(RATE(Assumptions!$C$7,0,-(9*Assumptions!$C$11-Assumptions!$C$13+Assumptions!$C$55),(1-Assumptions!$C$58)*(11*'Income Statement'!$H$21+'Debt Schedule'!$H$29)),"N/A") -> N/A | E33: =IFERROR(RATE(Assumptions!$C$7,0,-(10*Assumptions!$C$11-Assumptions!$C$13+Assumptions!$C$55),(1-Assumptions!$C$58)*(11*'Income Statement'!$H$21+'Debt Schedule'!$H$29)),"N/A") -> N/A | F33: =IFERROR(RATE(Assumptions!$C$7,0,-(11*Assumptions!$C$11-Assumptions!$C$13+Assumptions!$C$55),(1-Assumptions!$C$58)*(11*'Income Statement'!$H$21+'Debt Schedule'!$H$29)),"N/A") -> N/A | G33: =IFERROR(RATE(Assumptions!$C$7,0,-(12*Assumptions!$C$11-Assumptions!$C$13+Assumptions!$C$55),(1-Assumptions!$C$58)*(11*'Income Statement'!$H$21+'Debt Schedule'!$H$29)),"N/A") -> N/A
B34: 12 | C34: =IFERROR(RATE(Assumptions!$C$7,0,-(8*Assumptions!$C$11-Assumptions!$C$13+Assumptions!$C$55),(1-Assumptions!$C$58)*(12*'Income Statement'!$H$21+'Debt Schedule'!$H$29)),"N/A") -> N/A | D34: =IFERROR(RATE(Assumptions!$C$7,0,-(9*Assumptions!$C$11-Assumptions!$C$13+Assumptions!$C$55),(1-Assumptions!$C$58)*(12*'Income Statement'!$H$21+'Debt Schedule'!$H$29)),"N/A") -> N/A | E34: =IFERROR(RATE(Assumptions!$C$7,0,-(10*Assumptions!$C$11-Assumptions!$C$13+Assumptions!$C$55),(1-Assumptions!$C$58)*(12*'Income Statement'!$H$21+'Debt Schedule'!$H$29)),"N/A") -> N/A | F34: =IFERROR(RATE(Assumptions!$C$7,0,-(11*Assumptions!$C$11-Assumptions!$C$13+Assumptions!$C$55),(1-Assumptions!$C$58)*(12*'Income Statement'!$H$21+'Debt Schedule'!$H$29)),"N/A") -> N/A | G34: =IFERROR(RATE(Assumptions!$C$7,0,-(12*Assumptions!$C$11-Assumptions!$C$13+Assumptions!$C$55),(1-Assumptions!$C$58)*(12*'Income Statement'!$H$21+'Debt Schedule'!$H$29)),"N/A") -> N/A
A36: SENSITIVITY TABLE – MOIC vs EXIT MULTIPLE / ENTRY MULTIPLE
B37: MOIC ↓Exit / Entry→ | C37: 8 | D37: 9 | E37: 10 | F37: 11 | G37: 12
B38: 7 | C38: =IFERROR((1-Assumptions!$C$58)*(7*'Income Statement'!$H$21+'Debt Schedule'!$H$29)/(8*Assumptions!$C$11-Assumptions!$C$13+Assumptions!$C$55),"N/A") -> N/A | D38: =IFERROR((1-Assumptions!$C$58)*(7*'Income Statement'!$H$21+'Debt Schedule'!$H$29)/(9*Assumptions!$C$11-Assumptions!$C$13+Assumptions!$C$55),"N/A") -> N/A | E38: =IFERROR((1-Assumptions!$C$58)*(7*'Income Statement'!$H$21+'Debt Schedule'!$H$29)/(10*Assumptions!$C$11-Assumptions!$C$13+Assumptions!$C$55),"N/A") -> N/A | F38: =IFERROR((1-Assumptions!$C$58)*(7*'Income Statement'!$H$21+'Debt Schedule'!$H$29)/(11*Assumptions!$C$11-Assumptions!$C$13+Assumptions!$C$55),"N/A") -> N/A | G38: =IFERROR((1-Assumptions!$C$58)*(7*'Income Statement'!$H$21+'Debt Schedule'!$H$29)/(12*Assumptions!$C$11-Assumptions!$C$13+Assumptions!$C$55),"N/A") -> N/A
B39: 8 | C39: =IFERROR((1-Assumptions!$C$58)*(8*'Income Statement'!$H$21+'Debt Schedule'!$H$29)/(8*Assumptions!$C$11-Assumptions!$C$13+Assumptions!$C$55),"N/A") -> N/A | D39: =IFERROR((1-Assumptions!$C$58)*(8*'Income Statement'!$H$21+'Debt Schedule'!$H$29)/(9*Assumptions!$C$11-Assumptions!$C$13+Assumptions!$C$55),"N/A") -> N/A | E39: =IFERROR((1-Assumptions!$C$58)*(8*'Income Statement'!$H$21+'Debt Schedule'!$H$29)/(10*Assumptions!$C$11-Assumptions!$C$13+Assumptions!$C$55),"N/A") -> N/A | F39: =IFERROR((1-Assumptions!$C$58)*(8*'Income Statement'!$H$21+'Debt Schedule'!$H$29)/(11*Assumptions!$C$11-Assumptions!$C$13+Assumptions!$C$55),"N/A") -> N/A | G39: =IFERROR((1-Assumptions!$C$58)*(8*'Income Statement'!$H$21+'Debt Schedule'!$H$29)/(12*Assumptions!$C$11-Assumptions!$C$13+Assumptions!$C$55),"N/A") -> N/A
B40: 9 | C40: =IFERROR((1-Assumptions!$C$58)*(9*'Income Statement'!$H$21+'Debt Schedule'!$H$29)/(8*Assumptions!$C$11-Assumptions!$C$13+Assumptions!$C$55),"N/A") -> N/A | D40: =IFERROR((1-Assumptions!$C$58)*(9*'Income Statement'!$H$21+'Debt Schedule'!$H$29)/(9*Assumptions!$C$11-Assumptions!$C$13+Assumptions!$C$55),"N/A") -> N/A | E40: =IFERROR((1-Assumptions!$C$58)*(9*'Income Statement'!$H$21+'Debt Schedule'!$H$29)/(10*Assumptions!$C$11-Assumptions!$C$13+Assumptions!$C$55),"N/A") -> N/A | F40: =IFERROR((1-Assumptions!$C$58)*(9*'Income Statement'!$H$21+'Debt Schedule'!$H$29)/(11*Assumptions!$C$11-Assumptions!$C$13+Assumptions!$C$55),"N/A") -> N/A | G40: =IFERROR((1-Assumptions!$C$58)*(9*'Income Statement'!$H$21+'Debt Schedule'!$H$29)/(12*Assumptions!$C$11-Assumptions!$C$13+Assumptions!$C$55),"N/A") -> N/A
B41: 10 | C41: =IFERROR((1-Assumptions!$C$58)*(10*'Income Statement'!$H$21+'Debt Schedule'!$H$29)/(8*Assumptions!$C$11-Assumptions!$C$13+Assumptions!$C$55),"N/A") -> N/A | D41: =IFERROR((1-Assumptions!$C$58)*(10*'Income Statement'!$H$21+'Debt Schedule'!$H$29)/(9*Assumptions!$C$11-Assumptions!$C$13+Assumptions!$C$55),"N/A") -> N/A | E41: =IFERROR((1-Assumptions!$C$58)*(10*'Income Statement'!$H$21+'Debt Schedule'!$H$29)/(10*Assumptions!$C$11-Assumptions!$C$13+Assumptions!$C$55),"N/A") -> N/A | F41: =IFERROR((1-Assumptions!$C$58)*(10*'Income Statement'!$H$21+'Debt Schedule'!$H$29)/(11*Assumptions!$C$11-Assumptions!$C$13+Assumptions!$C$55),"N/A") -> N/A | G41: =IFERROR((1-Assumptions!$C$58)*(10*'Income Statement'!$H$21+'Debt Schedule'!$H$29)/(12*Assumptions!$C$11-Assumptions!$C$13+Assumptions!$C$55),"N/A") -> N/A
B42: 11 | C42: =IFERROR((1-Assumptions!$C$58)*(11*'Income Statement'!$H$21+'Debt Schedule'!$H$29)/(8*Assumptions!$C$11-Assumptions!$C$13+Assumptions!$C$55),"N/A") -> N/A | D42: =IFERROR((1-Assumptions!$C$58)*(11*'Income Statement'!$H$21+'Debt Schedule'!$H$29)/(9*Assumptions!$C$11-Assumptions!$C$13+Assumptions!$C$55),"N/A") -> N/A | E42: =IFERROR((1-Assumptions!$C$58)*(11*'Income Statement'!$H$21+'Debt Schedule'!$H$29)/(10*Assumptions!$C$11-Assumptions!$C$13+Assumptions!$C$55),"N/A") -> N/A | F42: =IFERROR((1-Assumptions!$C$58)*(11*'Income Statement'!$H$21+'Debt Schedule'!$H$29)/(11*Assumptions!$C$11-Assumptions!$C$13+Assumptions!$C$55),"N/A") -> N/A | G42: =IFERROR((1-Assumptions!$C$58)*(11*'Income Statement'!$H$21+'Debt Schedule'!$H$29)/(12*Assumptions!$C$11-Assumptions!$C$13+Assumptions!$C$55),"N/A") -> N/A
B43: 12 | C43: =IFERROR((1-Assumptions!$C$58)*(12*'Income Statement'!$H$21+'Debt Schedule'!$H$29)/(8*Assumptions!$C$11-Assumptions!$C$13+Assumptions!$C$55),"N/A") -> N/A | D43: =IFERROR((1-Assumptions!$C$58)*(12*'Income Statement'!$H$21+'Debt Schedule'!$H$29)/(9*Assumptions!$C$11-Assumptions!$C$13+Assumptions!$C$55),"N/A") -> N/A | E43: =IFERROR((1-Assumptions!$C$58)*(12*'Income Statement'!$H$21+'Debt Schedule'!$H$29)/(10*Assumptions!$C$11-Assumptions!$C$13+Assumptions!$C$55),"N/A") -> N/A | F43: =IFERROR((1-Assumptions!$C$58)*(12*'Income Statement'!$H$21+'Debt Schedule'!$H$29)/(11*Assumptions!$C$11-Assumptions!$C$13+Assumptions!$C$55),"N/A") -> N/A | G43: =IFERROR((1-Assumptions!$C$58)*(12*'Income Statement'!$H$21+'Debt Schedule'!$H$29)/(12*Assumptions!$C$11-Assumptions!$C$13+Assumptions!$C$55),"N/A") -> N/A

Sheet Sources & Uses
A1: SOURCES & USES OF FUNDS · ($mm)
B4: SOURCES | C4: Amount ($mm | E4: USES | F4: Amount ($mm)
B5: Revolving Credit Facility | C5: =Assumptions!C33 -> 0 | E5: Equity Purchase Price | F5: =Assumptions!C14 -> 0
B6: Term Loan A | C6: =Assumptions!C34 -> 0 | E6: Transaction Fees | F6: =Assumptions!C53 -> 0
B7: Term Loan B | C7: =Assumptions!C35 -> 0 | E7: Financing Fees | F7: =Assumptions!C54 -> 0
B8: Senior Secured Notes | C8: =Assumptions!C36 -> 0 | E8: Refinancing of Old Debt | F8: 0
B9: Sponsor Equity Contribution | C9: =Assumptions!C56 -> 0 | E9: Excess Cash to B/S | F9: =0 -> 0
B11: Total Sources | C11: =SUM(C5:C9) -> 0 | E11: Total Uses | F11: =SUM(F5:F9) -> 0
B12: =IF(C11=F11," Balanced"," CHECK: "&TEXT(C11-F11,"$#,##0.0")&" difference") -> Balanced
