Workbook

Sheet Cover
B3: M&A MERGER MODEL
B4: Industry-Grade | Accretion/Dilution | Pro-Forma Combined | Full Formula Model
C7: MODEL NAVIGATION
C8: 1 | D8: Txn Assumptions
C9: 2 | D9: Sources & Uses
C10: 3 | D10: PPA
C11: 4 | D11: Acquiror IS
C12: 5 | D12: Target IS
C13: 6 | D13: Pro-Forma IS
C14: 7 | D14: Accretion-Dilution
C15: 8 | D15: Synergy Schedule
C16: 9 | D16: Goodwill & Intangibles
C17: 10 | D17: Sensitivity Tables

Sheet Txn Assumptions
A2: TRANSACTION ASSUMPTIONS (Yellow = Input Cells)
A5: ASSUMPTION / INPUT | C5: FY-1 (LTM) | D5: FY+1 (Proj.) | E5: FY+2 (Proj.) | F5: FY+3 (Proj.) | G5: FY+4 (Proj.) | H5: FY+5 (Proj.) | I5: BACK -->
A7: DEAL STRUCTURE & OFFER PRICE
A8: Acquiror Name | C8: Acquiror Co.
A9: Target Name | C9: Target Co.
A10: Transaction Close Date | C10: 12/31/2025
A11: Target Share Price – Unaffected ($) | C11: 25
A12: Acquisition Premium [KEY INPUT — change this] | C12: 0.3
A13: Offer Price per Share ($) [= Unaffected × (1 + Premium)] | C13: =C11*(1+C12) -> 32.5
A14: Target Diluted Shares Outstanding (mm) | C14: 150
A15: Equity Purchase Price ($mm) | C15: =C13*C14 -> 4875
A16: (+) Target Net Debt Assumed ($mm) | C16: 200
A17: (-) Cash & Equivalents Acquired ($mm) | C17: 80
A18: ENTERPRISE VALUE ($mm) | C18: =C15+C16-C17 -> 4995
A20: ENTRY MULTIPLES (IMPLIED)
A21: Target LTM Revenue ($mm) | C21: 500
A22: Target LTM EBITDA ($mm) | C22: 100
A23: Target LTM EBIT ($mm) | C23: 75
A24: Target LTM Net Income ($mm) | C24: 55
A25: EV / LTM Revenue (x) | C25: =C18/C21 -> 9.99
A26: EV / LTM EBITDA (x) | C26: =C18/C22 -> 49.95
A27: EV / LTM EBIT (x) | C27: =C18/C23 -> 66.6
A28: P / LTM Net Income (x) [Offer P/E] | C28: =C15/C24 -> 88.636364
A30: FINANCING MIX
A31: % Cash Consideration | C31: 0.6
A32: % Stock Consideration [= 1 – Cash %] | C32: =1-C31 -> 0.4
A33: Cash Paid to Target Shareholders ($mm) | C33: =C15*C31 -> 2925
A34: Stock Paid to Target Shareholders ($mm) | C34: =C15*C32 -> 1950
A36: FIX #2 — EXCHANGE RATIO: Dynamic Math (Offer Price ÷ Acquiror Price)
A37: Exchange Ratio = Offer Price per Target Share ÷ Acquiror Share Price | New Shares = Stock $ Value ÷ Acquiror Price
A38: Acquiror Current Share Price ($) | C38: 55
A39: Exchange Ratio [AUTO = Offer Price ÷ Acquiror Price] | C39: =C13/C38 -> 0.59090909
A40: Stock Consideration Value ($mm) | C40: =C34 -> 1950
A41: New Acquiror Shares Issued (mm) [= Stock Value ÷ Acquiror Price] | C41: =C40/C38 -> 35.454545
A42: Cross-check via Exchange Ratio [= Target Shares × Ratio] | C42: =C14*C39 -> 88.636364
A43: Acquiror Shares – Pre-Deal (mm) | C43: 250
A44: Acquiror Shares – Post-Deal (mm) | C44: =C43+C41 -> 285.45455
A46: FIX #4 — DEBT FINANCING: Distinct Tranche Rates
A47: New Term Loan ($mm) | C47: 300
A48: Term Loan Interest Rate (%) | C48: 0.07
...

Sheet Sources & Uses
A2: SOURCES & USES ($mm) | FIX #1: Revolver = Auto-Balancing Plug | Balance Always = $0.00
A4: SOURCES OF FUNDS | C4: AMOUNT ($mm) | D4: % OF TOTAL | E4: TYPE
A5: Cash on Hand – Acquiror | C5: 50 | D5: =IF(C11=0,0,C5/C11) -> 0.0097789947 | E5: Hard input
A6: New Term Loan | C6: ='Txn Assumptions'!C47 -> 300 | D6: =IF(C11=0,0,C6/C11) -> 0.058673968 | E6: → Txn Assumptions
A7: New Senior Notes | C7: ='Txn Assumptions'!C50 -> 100 | D7: =IF(C11=0,0,C7/C11) -> 0.019557989 | E7: → Txn Assumptions
A8: Revolving Credit Facility ← AUTO-PLUG (draws to balance S&U) | C8: =MAX(0,C19-(C5+'Txn Assumptions'!C47+'Txn Assumptions'!C50+C9+C10)) -> 2713 | D8: =IF(C11=0,0,C8/C11) -> 0.53060825 | E8: AUTO-PLUG ↓
A9: Stock Consideration (Market Value) | C9: ='Txn Assumptions'!C34 -> 1950 | D9: =IF(C11=0,0,C9/C11) -> 0.38138079 | E9: → Txn Assumptions
A10: Rollover Equity | C10: 0 | D10: =IF(C11=0,0,C10/C11) -> 0 | E10: Hard input
A11: TOTAL SOURCES | C11: =SUM(C5:C10) -> 5113 | D11: ="100.0%" -> 100.0%
A13: USES OF FUNDS | C13: AMOUNT ($mm) | D13: % OF TOTAL | E13: TYPE
A14: Equity Purchase Price [DYNAMIC: rises with offer premium] | C14: ='Txn Assumptions'!C15 -> 4875 | D14: =IF(C19=0,0,C14/C19) -> 0.95345199 | E14: → Txn Assumptions (formula)
A15: Repay Target's Existing Debt (Change of Control) | C15: 200 | D15: =IF(C19=0,0,C15/C19) -> 0.039115979 | E15: Hard input
A16: Financing Fees & OID [CAPITALIZED → amortized; added to BS as asset offset] | C16: =('Txn Assumptions'!C47+'Txn Assumptions'!C50)*0.02 -> 8 | D16: =IF(C19=0,0,C16/C19) -> 0.0015646392 | E16: Formula (2% × debt)
A17: M&A Advisory & Legal Fees [EXPENSED → hits Retained Earnings Day 1, not capitalized] | C17: 25 | D17: =IF(C19=0,0,C17/C19) -> 0.0048894974 | E17: Hard input
A18: Other Transaction Costs [EXPENSED → hits Retained Earnings Day 1] | C18: 5 | D18: =IF(C19=0,0,C18/C19) -> 0.00097789947 | E18: Hard input
A19: TOTAL USES | C19: =SUM(C14:C18) -> 5113 | D19: ="100.0%" -> 100.0%
A21: BALANCE CHECK | Sources – Uses = Must Always = $0.00
A22: Sources – Uses (MUST = $0.00 at all times) | C22: =C11-C19 -> 0
A23: HOW IT WORKS: Change premium in Txn Assumptions → Offer Price rises → EPP rises → Uses rise → Revolver plug auto-draws → Balance stays $0.00
A25: FEE TREATMENT SUMMARY — Capitalized vs. Expensed
A26: Financing Fees (Row 16): CAPITALIZED — recorded as Deferred Financing Cost asset on Balance Sheet; amortized over debt life via interest expense.
A27: Advisory/Legal Fees (Row 17) + Other Costs (Row 18): EXPENSED — charged directly to Income Statement in the period incurred (deal close), reducing Retained Earnings on Day-0 Balance Sheet.
A28: Total Expensed Fees (after 25% tax shield): see Pro-Forma IS row — reduces Net Income in Year 1 only.

Sheet PPA
A2: PURCHASE PRICE ALLOCATION ($mm)
A5: LINE ITEM | C5: BOOK VALUE ($mm) | D5: FV ADJUSTMENT ($mm)
A6: STEP 1 – CONSIDERATION TRANSFERRED
A7: Equity Purchase Price | C7: ='Txn Assumptions'!C15 -> 4875
A8: (+) Fair Value of Net Debt Assumed | C8: ='Txn Assumptions'!C16 -> 200
A9: (-) Cash Acquired | C9: =-'Txn Assumptions'!C17 -> -80
A10: TOTAL CONSIDERATION (EV) | C10: =C7+C8+C9 -> 4995
A12: STEP 2 – NET IDENTIFIABLE ASSETS ACQUIRED (BOOK VALUE)
A13: Cash | C13: 80
A14: Accounts Receivable | C14: 60
A15: Inventories | C15: 45
A16: Other Current Assets | C16: 15
A17: Net PP&E | C17: 120
A18: Existing Intangibles | C18: 30
A19: Other Non-Current Assets | C19: 10
A20: Accounts Payable | C20: -40
A21: Accrued Liabilities | C21: -25
A22: Deferred Revenue | C22: -10
A23: Long-Term Debt (assumed) | C23: -200
A24: Other Liabilities | C24: -15
A25: Net Book Value of Assets Acquired | C25: =SUM(C13:C24) -> 70
A27: STEP 3 – FAIR VALUE STEP-UPS
A28: PP&E Step-Up | D28: 30
A29: Inventory Step-Up (one-time COGS) | D29: 5
A30: Customer Relationships | D30: 80
A31: Developed Technology / IP | D31: 50
A32: Trade Names & Trademarks | D32: 20
A33: Non-Compete Agreements | D33: 10
A34: Deferred Revenue Step-Down | D34: -5
A35: Deferred Tax Liability on Step-Ups [= (PP&E + Intangibles step-up) × Tax Rate] | D35: =-(PPA!D28+PPA!D30+PPA!D31+PPA!D32+PPA!D33)*'Txn Assumptions'!C59 -> -47.5
A36: Total Fair Value Adjustments | D36: =SUM(D28:D35) -> 142.5
A38: STEP 4 – GOODWILL
A39: Total Consideration (EV) | C39: =C10 -> 4995
A40: (-) Net Book Value of Assets | C40: =-C25 -> -70
A41: (-) Fair Value Step-Ups (net of DTL) | C41: =-D36 -> -142.5
A42: GOODWILL CREATED | C42: =C39+C40+C41 -> 4782.5
A44: IDENTIFIED INTANGIBLES & ANNUAL AMORTIZATION
A45: Intangible Asset | C45: Fair Value ($mm) | D45: Ann. Amort. ($mm)
A46: Customer Relationships | C46: 80 | D46: =C46/12 -> 6.6666667
A47: Developed Technology / IP | C47: 50 | D47: =C47/7 -> 7.1428571
...

Sheet Acquiror IS
A2: ACQUIROR – STANDALONE INCOME STATEMENT ($mm)
A5: ACQUIROR STANDALONE ($mm) | C5: FY-1 (LTM) | D5: FY+1 (Proj.) | E5: FY+2 (Proj.) | F5: FY+3 (Proj.) | G5: FY+4 (Proj.) | H5: FY+5 (Proj.) | I5: BACK -->
A7: INCOME STATEMENT – ACQUIROR STANDALONE
A8: Net Revenue | C8: 1500 | D8: 1620 | E8: 1750 | F8: 1890 | G8: 2040 | H8: 2200
A9: YoY Growth % | C9: "-" | D9: =D8/C8-1 -> 0.08 | E9: =E8/D8-1 -> 0.080246914 | F9: =F8/E8-1 -> 0.08 | G9: =G8/F8-1 -> 0.079365079 | H9: =H8/G8-1 -> 0.078431373
A10: Cost of Goods Sold | C10: =-C8*0.6 -> -900 | D10: =-D8*0.6 -> -972 | E10: =-E8*0.6 -> -1050 | F10: =-F8*0.6 -> -1134 | G10: =-G8*0.6 -> -1224 | H10: =-H8*0.6 -> -1320
A11: GROSS PROFIT | C11: =C8+C10 -> 600 | D11: =D8+D10 -> 648 | E11: =E8+E10 -> 700 | F11: =F8+F10 -> 756 | G11: =G8+G10 -> 816 | H11: =H8+H10 -> 880
A12: Gross Margin % | C12: =C11/C8 -> 0.4 | D12: =D11/D8 -> 0.4 | E12: =E11/E8 -> 0.4 | F12: =F11/F8 -> 0.4 | G12: =G11/G8 -> 0.4 | H12: =H11/H8 -> 0.4
A13: OPERATING EXPENSES
A14: Research & Development | C14: =-C8*0.08 -> -120 | D14: =-D8*0.08 -> -129.6 | E14: =-E8*0.08 -> -140 | F14: =-F8*0.08 -> -151.2 | G14: =-G8*0.08 -> -163.2 | H14: =-H8*0.08 -> -176
A15: Selling, General & Administrative | C15: =-C8*0.12 -> -180 | D15: =-D8*0.12 -> -194.4 | E15: =-E8*0.12 -> -210 | F15: =-F8*0.12 -> -226.8 | G15: =-G8*0.12 -> -244.8 | H15: =-H8*0.12 -> -264
A16: Depreciation & Amortization | C16: =-C8*0.04 -> -60 | D16: =-D8*0.04 -> -64.8 | E16: =-E8*0.04 -> -70 | F16: =-F8*0.04 -> -75.6 | G16: =-G8*0.04 -> -81.6 | H16: =-H8*0.04 -> -88
A17: Total Operating Expenses | C17: =SUM(C14:C16) -> -360 | D17: =SUM(D14:D16) -> -388.8 | E17: =SUM(E14:E16) -> -420 | F17: =SUM(F14:F16) -> -453.6 | G17: =SUM(G14:G16) -> -489.6 | H17: =SUM(H14:H16) -> -528
A18: EBIT (Operating Income) | C18: =C11+C17 -> 240 | D18: =D11+D17 -> 259.2 | E18: =E11+E17 -> 280 | F18: =F11+F17 -> 302.4 | G18: =G11+G17 -> 326.4 | H18: =H11+H17 -> 352
A19: EBIT Margin % | C19: =C18/C8 -> 0.16 | D19: =D18/D8 -> 0.16 | E19: =E18/E8 -> 0.16 | F19: =F18/F8 -> 0.16 | G19: =G18/G8 -> 0.16 | H19: =H18/H8 -> 0.16
A20: EBITDA | C20: =C18-C16 -> 300 | D20: =D18-D16 -> 324 | E20: =E18-E16 -> 350 | F20: =F18-F16 -> 378 | G20: =G18-G16 -> 408 | H20: =H18-H16 -> 440
A21: EBITDA Margin % | C21: =C20/C8 -> 0.2 | D21: =D20/D8 -> 0.2 | E21: =E20/E8 -> 0.2 | F21: =F20/F8 -> 0.2 | G21: =G20/G8 -> 0.2 | H21: =H20/H8 -> 0.2
A22: BELOW-THE-LINE
A23: Interest Expense (Existing Debt) | C23: -30 | D23: -30 | E23: -30 | F23: -30 | G23: -30 | H23: -30
A24: Interest Income | C24: 5 | D24: 5 | E24: 5 | F24: 5 | G24: 5 | H24: 5
A25: Earnings Before Tax | C25: =C18+C23+C24 -> 215 | D25: =D18+D23+D24 -> 234.2 | E25: =E18+E23+E24 -> 255 | F25: =F18+F23+F24 -> 277.4 | G25: =G18+G23+G24 -> 301.4 | H25: =H18+H23+H24 -> 327
A26: Income Tax Expense (25%) | C26: =-C25*0.25 -> -53.75 | D26: =-D25*0.25 -> -58.55 | E26: =-E25*0.25 -> -63.75 | F26: =-F25*0.25 -> -69.35 | G26: =-G25*0.25 -> -75.35 | H26: =-H25*0.25 -> -81.75
A27: NET INCOME – ACQUIROR | C27: =C25+C26 -> 161.25 | D27: =D25+D26 -> 175.65 | E27: =E25+E26 -> 191.25 | F27: =F25+F26 -> 208.05 | G27: =G25+G26 -> 226.05 | H27: =H25+H26 -> 245.25
A28: Net Margin % | C28: =C27/C8 -> 0.1075 | D28: =D27/D8 -> 0.10842593 | E28: =E27/E8 -> 0.10928571 | F28: =F27/F8 -> 0.11007937 | G28: =G27/G8 -> 0.11080882 | H28: =H27/H8 -> 0.11147727
A29: PER SHARE DATA
A30: Diluted Shares – Pre-Deal (mm) | C30: 250 | D30: 250 | E30: 250 | F30: 250 | G30: 250 | H30: 250
A31: EPS – Acquiror Standalone ($) | C31: =C27/C30 -> 0.645 | D31: =D27/D30 -> 0.7026 | E31: =E27/E30 -> 0.765 | F31: =F27/F30 -> 0.8322 | G31: =G27/G30 -> 0.9042 | H31: =H27/H30 -> 0.981

Sheet Target IS
A2: TARGET – STANDALONE INCOME STATEMENT ($mm)
A5: TARGET STANDALONE ($mm) | C5: FY-1 (LTM) | D5: FY+1 (Proj.) | E5: FY+2 (Proj.) | F5: FY+3 (Proj.) | G5: FY+4 (Proj.) | H5: FY+5 (Proj.) | I5: BACK -->
A7: INCOME STATEMENT – TARGET STANDALONE
A8: Net Revenue | C8: 500 | D8: 545 | E8: 595 | F8: 650 | G8: 710 | H8: 775
A9: YoY Growth % | C9: "-" | D9: =D8/C8-1 -> 0.09 | E9: =E8/D8-1 -> 0.091743119 | F9: =F8/E8-1 -> 0.092436975 | G9: =G8/F8-1 -> 0.092307692 | H9: =H8/G8-1 -> 0.091549296
A10: Cost of Goods Sold | C10: =-C8*0.55 -> -275 | D10: =-D8*0.55 -> -299.75 | E10: =-E8*0.55 -> -327.25 | F10: =-F8*0.55 -> -357.5 | G10: =-G8*0.55 -> -390.5 | H10: =-H8*0.55 -> -426.25
A11: GROSS PROFIT | C11: =C8+C10 -> 225 | D11: =D8+D10 -> 245.25 | E11: =E8+E10 -> 267.75 | F11: =F8+F10 -> 292.5 | G11: =G8+G10 -> 319.5 | H11: =H8+H10 -> 348.75
A12: Gross Margin % | C12: =C11/C8 -> 0.45 | D12: =D11/D8 -> 0.45 | E12: =E11/E8 -> 0.45 | F12: =F11/F8 -> 0.45 | G12: =G11/G8 -> 0.45 | H12: =H11/H8 -> 0.45
A13: OPERATING EXPENSES
A14: Research & Development | C14: =-C8*0.1 -> -50 | D14: =-D8*0.1 -> -54.5 | E14: =-E8*0.1 -> -59.5 | F14: =-F8*0.1 -> -65 | G14: =-G8*0.1 -> -71 | H14: =-H8*0.1 -> -77.5
A15: Selling, General & Administrative | C15: =-C8*0.15 -> -75 | D15: =-D8*0.15 -> -81.75 | E15: =-E8*0.15 -> -89.25 | F15: =-F8*0.15 -> -97.5 | G15: =-G8*0.15 -> -106.5 | H15: =-H8*0.15 -> -116.25
A16: Depreciation & Amortization | C16: =-C8*0.05 -> -25 | D16: =-D8*0.05 -> -27.25 | E16: =-E8*0.05 -> -29.75 | F16: =-F8*0.05 -> -32.5 | G16: =-G8*0.05 -> -35.5 | H16: =-H8*0.05 -> -38.75
A17: Total Operating Expenses | C17: =SUM(C14:C16) -> -150 | D17: =SUM(D14:D16) -> -163.5 | E17: =SUM(E14:E16) -> -178.5 | F17: =SUM(F14:F16) -> -195 | G17: =SUM(G14:G16) -> -213 | H17: =SUM(H14:H16) -> -232.5
A18: EBIT | C18: =C11+C17 -> 75 | D18: =D11+D17 -> 81.75 | E18: =E11+E17 -> 89.25 | F18: =F11+F17 -> 97.5 | G18: =G11+G17 -> 106.5 | H18: =H11+H17 -> 116.25
A19: EBIT Margin % | C19: =C18/C8 -> 0.15 | D19: =D18/D8 -> 0.15 | E19: =E18/E8 -> 0.15 | F19: =F18/F8 -> 0.15 | G19: =G18/G8 -> 0.15 | H19: =H18/H8 -> 0.15
A20: EBITDA | C20: =C18-C16 -> 100 | D20: =D18-D16 -> 109 | E20: =E18-E16 -> 119 | F20: =F18-F16 -> 130 | G20: =G18-G16 -> 142 | H20: =H18-H16 -> 155
A21: EBITDA Margin % | C21: =C20/C8 -> 0.2 | D21: =D20/D8 -> 0.2 | E21: =E20/E8 -> 0.2 | F21: =F20/F8 -> 0.2 | G21: =G20/G8 -> 0.2 | H21: =H20/H8 -> 0.2
A22: BELOW-THE-LINE
A23: Interest Expense (Existing Debt) | C23: -14 | D23: -14 | E23: -14 | F23: -14 | G23: -14 | H23: -14
A24: Earnings Before Tax | C24: =C18+C23 -> 61 | D24: =D18+D23 -> 67.75 | E24: =E18+E23 -> 75.25 | F24: =F18+F23 -> 83.5 | G24: =G18+G23 -> 92.5 | H24: =H18+H23 -> 102.25
A25: Income Tax (25%) | C25: =-C24*0.25 -> -15.25 | D25: =-D24*0.25 -> -16.9375 | E25: =-E24*0.25 -> -18.8125 | F25: =-F24*0.25 -> -20.875 | G25: =-G24*0.25 -> -23.125 | H25: =-H24*0.25 -> -25.5625
A26: NET INCOME – TARGET | C26: =C24+C25 -> 45.75 | D26: =D24+D25 -> 50.8125 | E26: =E24+E25 -> 56.4375 | F26: =F24+F25 -> 62.625 | G26: =G24+G25 -> 69.375 | H26: =H24+H25 -> 76.6875
A27: Net Margin % | C27: =C26/C8 -> 0.0915 | D27: =D26/D8 -> 0.093233945 | E27: =E26/E8 -> 0.094852941 | F27: =F26/F8 -> 0.096346154 | G27: =G26/G8 -> 0.097711268 | H27: =H26/H8 -> 0.098951613

Sheet Synergy Schedule
A2: SYNERGY SCHEDULE ($mm)
A5: SYNERGY ITEM ($mm) | C5: FY-1 (LTM) | D5: FY+1 (Proj.) | E5: FY+2 (Proj.) | F5: FY+3 (Proj.) | G5: FY+4 (Proj.) | H5: FY+5 (Proj.) | I5: BACK -->
A7: REVENUE SYNERGIES
A8: Cross-Sell / Expanded Distribution | C8: 0 | D8: 5 | E8: 12 | F8: 20 | G8: 25 | H8: 28
A9: New Product / Market Entry | C9: 0 | D9: 2 | E9: 6 | F9: 12 | G9: 18 | H9: 22
A10: Pricing Power | C10: 0 | D10: 1 | E10: 3 | F10: 5 | G10: 7 | H10: 8
A11: TOTAL REVENUE SYNERGIES | C11: =SUM(C8:C10) -> 0 | D11: =SUM(D8:D10) -> 8 | E11: =SUM(E8:E10) -> 21 | F11: =SUM(F8:F10) -> 37 | G11: =SUM(G8:G10) -> 50 | H11: =SUM(H8:H10) -> 58
A13: COST SYNERGIES
A14: Headcount Reduction / Duplicate Roles | C14: 0 | D14: 8 | E14: 18 | F14: 28 | G14: 32 | H14: 34
A15: Procurement / Vendor Savings | C15: 0 | D15: 3 | E15: 8 | F15: 13 | G15: 16 | H15: 18
A16: Facilities Consolidation | C16: 0 | D16: 2 | E16: 5 | F16: 8 | G16: 10 | H16: 11
A17: IT & Systems Integration Savings | C17: 0 | D17: 1 | E17: 4 | F17: 6 | G17: 7 | H17: 8
A18: Supply Chain Optimization | C18: 0 | D18: 1 | E18: 3 | F18: 5 | G18: 6 | H18: 7
A19: TOTAL COST SYNERGIES | C19: =SUM(C14:C18) -> 0 | D19: =SUM(D14:D18) -> 15 | E19: =SUM(E14:E18) -> 38 | F19: =SUM(F14:F18) -> 60 | G19: =SUM(G14:G18) -> 71 | H19: =SUM(H14:H18) -> 78
A21: TOTAL & ONE-TIME INTEGRATION COSTS
A22: TOTAL SYNERGIES (Revenue + Cost) | C22: =C11+C19 -> 0 | D22: =D11+D19 -> 23 | E22: =E11+E19 -> 59 | F22: =F11+F19 -> 97 | G22: =G11+G19 -> 121 | H22: =H11+H19 -> 136
A24: ONE-TIME INTEGRATION & RESTRUCTURING COSTS
A25: Severance & Restructuring | C25: -20 | D25: -15 | E25: -5 | F25: 0 | G25: 0 | H25: 0
A26: IT Integration Costs | C26: -10 | D26: -8 | E26: -3 | F26: 0 | G26: 0 | H26: 0
A27: Facilities & Lease Termination | C27: -5 | D27: -3 | E27: 0 | F27: 0 | G27: 0 | H27: 0
A28: Other Integration Costs | C28: -5 | D28: -2 | E28: 0 | F28: 0 | G28: 0 | H28: 0
A29: TOTAL ONE-TIME COSTS | C29: =SUM(C25:C28) -> -40 | D29: =SUM(D25:D28) -> -28 | E29: =SUM(E25:E28) -> -8 | F29: =SUM(F25:F28) -> 0 | G29: =SUM(G25:G28) -> 0 | H29: =SUM(H25:H28) -> 0
A30: NET SYNERGIES (After Integration Costs) | C30: =C22+C29 -> -40 | D30: =D22+D29 -> -5 | E30: =E22+E29 -> 51 | F30: =F22+F29 -> 97 | G30: =G22+G29 -> 121 | H30: =H22+H29 -> 136

Sheet Pro-Forma IS
A2: PRO-FORMA COMBINED INCOME STATEMENT ($mm)
A5: PRO-FORMA COMBINED ($mm) | C5: FY-1 (LTM) | D5: FY+1 (Proj.) | E5: FY+2 (Proj.) | F5: FY+3 (Proj.) | G5: FY+4 (Proj.) | H5: FY+5 (Proj.) | I5: BACK -->
A7: COMBINED REVENUE
A8: Acquiror Net Revenue | C8: ='Acquiror IS'!C8 -> 1500 | D8: ='Acquiror IS'!D8 -> 1620 | E8: ='Acquiror IS'!E8 -> 1750 | F8: ='Acquiror IS'!F8 -> 1890 | G8: ='Acquiror IS'!G8 -> 2040 | H8: ='Acquiror IS'!H8 -> 2200
A9: (+) Target Net Revenue | C9: ='Target IS'!C8 -> 500 | D9: ='Target IS'!D8 -> 545 | E9: ='Target IS'!E8 -> 595 | F9: ='Target IS'!F8 -> 650 | G9: ='Target IS'!G8 -> 710 | H9: ='Target IS'!H8 -> 775
A10: (+) Revenue Synergies | C10: ='Synergy Schedule'!C11 -> 0 | D10: ='Synergy Schedule'!D11 -> 8 | E10: ='Synergy Schedule'!E11 -> 21 | F10: ='Synergy Schedule'!F11 -> 37 | G10: ='Synergy Schedule'!G11 -> 50 | H10: ='Synergy Schedule'!H11 -> 58
A11: TOTAL PRO-FORMA REVENUE | C11: =C8+C9+C10 -> 2000 | D11: =D8+D9+D10 -> 2173 | E11: =E8+E9+E10 -> 2366 | F11: =F8+F9+F10 -> 2577 | G11: =G8+G9+G10 -> 2800 | H11: =H8+H9+H10 -> 3033
A12: COST OF GOODS SOLD
A13: Acquiror COGS | C13: ='Acquiror IS'!C10 -> -900 | D13: ='Acquiror IS'!D10 -> -972 | E13: ='Acquiror IS'!E10 -> -1050 | F13: ='Acquiror IS'!F10 -> -1134 | G13: ='Acquiror IS'!G10 -> -1224 | H13: ='Acquiror IS'!H10 -> -1320
A14: Target COGS | C14: ='Target IS'!C10 -> -275 | D14: ='Target IS'!D10 -> -299.75 | E14: ='Target IS'!E10 -> -327.25 | F14: ='Target IS'!F10 -> -357.5 | G14: ='Target IS'!G10 -> -390.5 | H14: ='Target IS'!H10 -> -426.25
A15: Inventory Step-Up (one-time, Year 1 only) | C15: -5 | D15: =0 -> 0 | E15: =0 -> 0 | F15: =0 -> 0 | G15: =0 -> 0 | H15: =0 -> 0
A16: TOTAL PRO-FORMA COGS | C16: =SUM(C13:C15) -> -1180 | D16: =SUM(D13:D15) -> -1271.75 | E16: =SUM(E13:E15) -> -1377.25 | F16: =SUM(F13:F15) -> -1491.5 | G16: =SUM(G13:G15) -> -1614.5 | H16: =SUM(H13:H15) -> -1746.25
A17: GROSS PROFIT | C17: =C11+C16 -> 820 | D17: =D11+D16 -> 901.25 | E17: =E11+E16 -> 988.75 | F17: =F11+F16 -> 1085.5 | G17: =G11+G16 -> 1185.5 | H17: =H11+H16 -> 1286.75
A18: Gross Margin % | C18: =C17/C11 -> 0.41 | D18: =D17/D11 -> 0.41474919 | E18: =E17/E11 -> 0.41789941 | F18: =F17/F11 -> 0.42122623 | G18: =G17/G11 -> 0.42339286 | H18: =H17/H11 -> 0.42424992
A19: OPERATING EXPENSES – PRO-FORMA
A20: Acquiror R&D | C20: ='Acquiror IS'!C14 -> -120 | D20: ='Acquiror IS'!D14 -> -129.6 | E20: ='Acquiror IS'!E14 -> -140 | F20: ='Acquiror IS'!F14 -> -151.2 | G20: ='Acquiror IS'!G14 -> -163.2 | H20: ='Acquiror IS'!H14 -> -176
A21: Target R&D | C21: ='Target IS'!C14 -> -50 | D21: ='Target IS'!D14 -> -54.5 | E21: ='Target IS'!E14 -> -59.5 | F21: ='Target IS'!F14 -> -65 | G21: ='Target IS'!G14 -> -71 | H21: ='Target IS'!H14 -> -77.5
A22: Acquiror SG&A | C22: ='Acquiror IS'!C15 -> -180 | D22: ='Acquiror IS'!D15 -> -194.4 | E22: ='Acquiror IS'!E15 -> -210 | F22: ='Acquiror IS'!F15 -> -226.8 | G22: ='Acquiror IS'!G15 -> -244.8 | H22: ='Acquiror IS'!H15 -> -264
A23: Target SG&A | C23: ='Target IS'!C15 -> -75 | D23: ='Target IS'!D15 -> -81.75 | E23: ='Target IS'!E15 -> -89.25 | F23: ='Target IS'!F15 -> -97.5 | G23: ='Target IS'!G15 -> -106.5 | H23: ='Target IS'!H15 -> -116.25
A24: (+) Cost Synergies | C24: ='Synergy Schedule'!C19 -> 0 | D24: ='Synergy Schedule'!D19 -> 15 | E24: ='Synergy Schedule'!E19 -> 38 | F24: ='Synergy Schedule'!F19 -> 60 | G24: ='Synergy Schedule'!G19 -> 71 | H24: ='Synergy Schedule'!H19 -> 78
A25: Acquiror D&A (Standalone) | C25: ='Acquiror IS'!C16 -> -60 | D25: ='Acquiror IS'!D16 -> -64.8 | E25: ='Acquiror IS'!E16 -> -70 | F25: ='Acquiror IS'!F16 -> -75.6 | G25: ='Acquiror IS'!G16 -> -81.6 | H25: ='Acquiror IS'!H16 -> -88
A26: Target D&A (Standalone) | C26: ='Target IS'!C16 -> -25 | D26: ='Target IS'!D16 -> -27.25 | E26: ='Target IS'!E16 -> -29.75 | F26: ='Target IS'!F16 -> -32.5 | G26: ='Target IS'!G16 -> -35.5 | H26: ='Target IS'!H16 -> -38.75
A27: PPA Amortization of Acquired Intangibles | C27: -20 | D27: -20 | E27: -20 | F27: -20 | G27: -20 | H27: -20
A28: TOTAL PRO-FORMA OPEX | C28: =SUM(C20:C27) -> -530 | D28: =SUM(D20:D27) -> -557.3 | E28: =SUM(E20:E27) -> -580.5 | F28: =SUM(F20:F27) -> -608.6 | G28: =SUM(G20:G27) -> -651.6 | H28: =SUM(H20:H27) -> -702.5
A29: PRO-FORMA EBIT | C29: =C17+C28 -> 290 | D29: =D17+D28 -> 343.95 | E29: =E17+E28 -> 408.25 | F29: =F17+F28 -> 476.9 | G29: =G17+G28 -> 533.9 | H29: =H17+H28 -> 584.25
A30: EBIT Margin % | C30: =IF(C11=0,0,C29/C11) -> 0.145 | D30: =IF(D11=0,0,D29/D11) -> 0.15828348 | E30: =IF(E11=0,0,E29/E11) -> 0.17254861 | F30: =IF(F11=0,0,F29/F11) -> 0.18506015 | G30: =IF(G11=0,0,G29/G11) -> 0.19067857 | H30: =IF(H11=0,0,H29/H11) -> 0.19263106
A31: PRO-FORMA EBITDA | C31: =C29-'Acquiror IS'!C16-'Target IS'!C16+C27 -> 355 | D31: =D29-'Acquiror IS'!D16-'Target IS'!D16+D27 -> 416 | E31: =E29-'Acquiror IS'!E16-'Target IS'!E16+E27 -> 488 | F31: =F29-'Acquiror IS'!F16-'Target IS'!F16+F27 -> 565 | G31: =G29-'Acquiror IS'!G16-'Target IS'!G16+G27 -> 631 | H31: =H29-'Acquiror IS'!H16-'Target IS'!H16+H27 -> 691
A32: EBITDA Margin % | C32: =IF(C11=0,0,C31/C11) -> 0.1775 | D32: =IF(D11=0,0,D31/D11) -> 0.1914404 | E32: =IF(E11=0,0,E31/E11) -> 0.20625528 | F32: =IF(F11=0,0,F31/F11) -> 0.21924719 | G32: =IF(G11=0,0,G31/G11) -> 0.22535714 | H32: =IF(H11=0,0,H31/H11) -> 0.22782723
A33: BELOW-THE-LINE – PRO-FORMA
A34: Acquiror Interest Expense (Existing) | C34: ='Acquiror IS'!C23 -> -30 | D34: ='Acquiror IS'!D23 -> -30 | E34: ='Acquiror IS'!E23 -> -30 | F34: ='Acquiror IS'!F23 -> -30 | G34: ='Acquiror IS'!G23 -> -30 | H34: ='Acquiror IS'!H23 -> -30
A35: New Debt Interest – Term Loan (7.0%) + Sr Notes (9.0%) + Revolver (5.5%) | C35: =-('Txn Assumptions'!C47*'Txn Assumptions'!C48+'Txn Assumptions'!C50*'Txn Assumptions'!C51+'Txn Assumptions'!C53*'Txn Assumptions'!C54) -> -179.215 | D35: =-('Txn Assumptions'!C47*'Txn Assumptions'!C48+'Txn Assumptions'!C50*'Txn Assumptions'!C51+'Txn Assumptions'!C53*'Txn Assumptions'!C54) -> -179.215 | E35: =-('Txn Assumptions'!C47*'Txn Assumptions'!C48+'Txn Assumptions'!C50*'Txn Assumptions'!C51+'Txn Assumptions'!C53*'Txn Assumptions'!C54) -> -179.215 | F35: =-('Txn Assumptions'!C47*'Txn Assumptions'!C48+'Txn Assumptions'!C50*'Txn Assumptions'!C51+'Txn Assumptions'!C53*'Txn Assumptions'!C54) -> -179.215 | G35: =-('Txn Assumptions'!C47*'Txn Assumptions'!C48+'Txn Assumptions'!C50*'Txn Assumptions'!C51+'Txn Assumptions'!C53*'Txn Assumptions'!C54) -> -179.215 | H35: =-('Txn Assumptions'!C47*'Txn Assumptions'!C48+'Txn Assumptions'!C50*'Txn Assumptions'!C51+'Txn Assumptions'!C53*'Txn Assumptions'!C54) -> -179.215
A36: (-) M&A Advisory, Legal & Other Fees [EXPENSED — Year 1 only; not capitalized] | C36: =-('Sources & Uses'!C17+'Sources & Uses'!C18) -> -30 | D36: =0 -> 0 | E36: =0 -> 0 | F36: =0 -> 0 | G36: =0 -> 0 | H36: =0 -> 0
A37: (-) Financing Fee Amortization [CAPITALIZED — amortized over 5-yr debt life] | C37: =-'Sources & Uses'!C16/5 -> -1.6 | D37: =-'Sources & Uses'!C16/5 -> -1.6 | E37: =-'Sources & Uses'!C16/5 -> -1.6 | F37: =-'Sources & Uses'!C16/5 -> -1.6 | G37: =-'Sources & Uses'!C16/5 -> -1.6 | H37: =-'Sources & Uses'!C16/5 -> -1.6
A38: (-) Foregone Interest Income on Cash Used [= Cash Deployed × 3.0% opportunity cost] | C38: =-'Sources & Uses'!C5*0.03 -> -1.5 | D38: =-'Sources & Uses'!C5*0.03 -> -1.5 | E38: =-'Sources & Uses'!C5*0.03 -> -1.5 | F38: =-'Sources & Uses'!C5*0.03 -> -1.5 | G38: =-'Sources & Uses'!C5*0.03 -> -1.5 | H38: =-'Sources & Uses'!C5*0.03 -> -1.5
A39: PRO-FORMA EBT | C39: =C29+C34+C35+C36+C37+C38 -> 47.685 | D39: =D29+D34+D35+D36+D37+D38 -> 131.635 | E39: =E29+E34+E35+E36+E37+E38 -> 195.935 | F39: =F29+F34+F35+F36+F37+F38 -> 264.585 | G39: =G29+G34+G35+G36+G37+G38 -> 321.585 | H39: =H29+H34+H35+H36+H37+H38 -> 371.935
A40: Income Tax (25%) | C40: =-C39*'Txn Assumptions'!C59 -> -11.92125 | D40: =-D39*'Txn Assumptions'!C59 -> -32.90875 | E40: =-E39*'Txn Assumptions'!C59 -> -48.98375 | F40: =-F39*'Txn Assumptions'!C59 -> -66.14625 | G40: =-G39*'Txn Assumptions'!C59 -> -80.39625 | H40: =-H39*'Txn Assumptions'!C59 -> -92.98375
A41: PRO-FORMA NET INCOME | C41: =C39+C40 -> 35.76375 | D41: =D39+D40 -> 98.72625 | E41: =E39+E40 -> 146.95125 | F41: =F39+F40 -> 198.43875 | G41: =G39+G40 -> 241.18875 | H41: =H39+H40 -> 278.95125
A42: Net Margin % | C42: =IF(C11=0,0,C41/C11) -> 0.017881875 | D42: =IF(D11=0,0,D41/D11) -> 0.045433157 | E42: =IF(E11=0,0,E41/E11) -> 0.062109573 | F42: =IF(F11=0,0,F41/F11) -> 0.077003783 | G42: =IF(G11=0,0,G41/G11) -> 0.086138839 | H42: =IF(H11=0,0,H41/H11) -> 0.091972057
A43: PRO-FORMA EPS BRIDGE
A44: Pro-Forma Diluted Shares Outstanding (mm) | C44: ='Txn Assumptions'!C44 -> 285.45455 | D44: ='Txn Assumptions'!C44 -> 285.45455 | E44: ='Txn Assumptions'!C44 -> 285.45455 | F44: ='Txn Assumptions'!C44 -> 285.45455 | G44: ='Txn Assumptions'!C44 -> 285.45455 | H44: ='Txn Assumptions'!C44 -> 285.45455
...

Sheet Pro-Forma BS
A2: PRO-FORMA BALANCE SHEET ($mm) | Day-0 Closing | Four-Column Combination
A5: LINE ITEM | C5: Acquiror Standalone | D5: Target Standalone (Book) | E5: PPA Adjustments | F5: Deal Adjustments | G5: PRO-FORMA COMBINED | H5: BACK -->
C6: Acq. standalone Blue = input | D6: Tgt. book value Blue = input | E6: PPA step-ups Green = linked | F6: Deal adj. Green = linked | G6: Auto-calculated Sum of all cols
A7: ASSETS — (Positive = asset, adds to total)
A8: CURRENT ASSETS
A9: Cash & Cash Equivalents | C9: 200 | D9: 80 | E9: =0 -> 0 | F9: =-'Sources & Uses'!C5-'Sources & Uses'!C17-'Sources & Uses'!C18-'Sources & Uses'!C16 -> -88 | G9: =C9+D9+E9+F9 -> 192
A10: Accounts Receivable (net) | C10: 180 | D10: 60 | E10: =0 -> 0 | F10: =0 -> 0 | G10: =C10+D10+E10+F10 -> 240
A11: Inventories | C11: 120 | D11: 45 | E11: =5 -> 5 | F11: =0 -> 0 | G11: =C11+D11+E11+F11 -> 170
A12: Prepaid & Other Current Assets | C12: 40 | D12: 15 | E12: =0 -> 0 | F12: =0 -> 0 | G12: =C12+D12+E12+F12 -> 55
A13: TOTAL CURRENT ASSETS | C13: =SUM(C9:C12) -> 540 | D13: =SUM(D9:D12) -> 200 | E13: =SUM(E9:E12) -> 5 | F13: =SUM(F9:F12) -> -88 | G13: =C13+D13+E13+F13 -> 657
A14: NON-CURRENT ASSETS
A15: Net PP&E | C15: 800 | D15: 120 | E15: =30 -> 30 | F15: =0 -> 0 | G15: =C15+D15+E15+F15 -> 950
A16: Existing Intangibles (net) | C16: 100 | D16: 30 | E16: =0 -> 0 | F16: =0 -> 0 | G16: =C16+D16+E16+F16 -> 130
A17: Acquired Intangibles — PPA-created (Customer Rel, Tech, Trade, NCA) | C17: =0 -> 0 | D17: =0 -> 0 | E17: =160 -> 160 | F17: =0 -> 0 | G17: =C17+D17+E17+F17 -> 160
A18: Goodwill [= EV − Net Book Value − Fair Value Step-ups] | C18: =0 -> 0 | D18: =0 -> 0 | E18: ='Txn Assumptions'!C18-70-145 -> 4780 | F18: =0 -> 0 | G18: =C18+D18+E18+F18 -> 4780
A19: Deferred Tax Assets & Other Long-Term Assets | C19: 50 | D19: 10 | E19: =0 -> 0 | F19: =0 -> 0 | G19: =C19+D19+E19+F19 -> 60
A20: Capitalized Financing Fees (OID, netted against debt) | C20: =0 -> 0 | D20: =0 -> 0 | E20: =0 -> 0 | F20: ='Sources & Uses'!C16 -> 8 | G20: =C20+D20+E20+F20 -> 8
A21: TOTAL NON-CURRENT ASSETS | C21: =SUM(C14:C20) -> 950 | D21: =SUM(D14:D20) -> 160 | E21: =SUM(E14:E20) -> 4970 | F21: =SUM(F14:F20) -> 8 | G21: =C21+D21+E21+F21 -> 6088
A22: TOTAL ASSETS | C22: =C13+C21 -> 1490 | D22: =D13+D21 -> 360 | E22: =E13+E21 -> 4975 | F22: =F13+F21 -> -80 | G22: =C22+D22+E22+F22 -> 6745
A24: LIABILITIES — (Positive = liability, adds to total)
A25: CURRENT LIABILITIES
A26: Accounts Payable | C26: 90 | D26: 40 | E26: =0 -> 0 | F26: =0 -> 0 | G26: =C26+D26+E26+F26 -> 130
A27: Accrued Liabilities & Other | C27: 60 | D27: 25 | E27: =0 -> 0 | F27: =0 -> 0 | G27: =C27+D27+E27+F27 -> 85
A28: Current Portion of LTD – Acquiror | C28: 25 | D28: =0 -> 0 | E28: =0 -> 0 | F28: =0 -> 0 | G28: =C28+D28+E28+F28 -> 25
A29: Deferred Revenue & Other Current Liabilities | C29: 30 | D29: 10 | E29: =-5 -> -5 | F29: =0 -> 0 | G29: =C29+D29+E29+F29 -> 35
A30: TOTAL CURRENT LIABILITIES | C30: =SUM(C26:C29) -> 205 | D30: =SUM(D26:D29) -> 75 | E30: =SUM(E26:E29) -> -5 | F30: =SUM(F26:F29) -> 0 | G30: =C30+D30+E30+F30 -> 275
A31: NON-CURRENT LIABILITIES
A32: Long-Term Debt – Acquiror Existing | C32: 400 | D32: =0 -> 0 | E32: =0 -> 0 | F32: =0 -> 0 | G32: =C32+D32+E32+F32 -> 400
A33: Long-Term Debt – Target Existing [Repaid at close → zeroed out] | C33: =0 -> 0 | D33: 200 | E33: =0 -> 0 | F33: =-'Sources & Uses'!C15 -> -200 | G33: =C33+D33+E33+F33 -> 0
A34: New Term Loan (from deal financing) | C34: =0 -> 0 | D34: =0 -> 0 | E34: =0 -> 0 | F34: ='Txn Assumptions'!C47 -> 300 | G34: =C34+D34+E34+F34 -> 300
A35: New Senior Notes (from deal financing) | C35: =0 -> 0 | D35: =0 -> 0 | E35: =0 -> 0 | F35: ='Txn Assumptions'!C50 -> 100 | G35: =C35+D35+E35+F35 -> 100
A36: Revolving Credit Facility [Auto-plug draw from S&U] | C36: =0 -> 0 | D36: =0 -> 0 | E36: =0 -> 0 | F36: ='Txn Assumptions'!C53 -> 2713 | G36: =C36+D36+E36+F36 -> 2713
A37: Deferred Tax Liability on PPA Step-ups | C37: 50 | D37: =0 -> 0 | E37: =PPA!D59 -> 47.5 | F37: =0 -> 0 | G37: =C37+D37+E37+F37 -> 97.5
A38: Other Non-Current Liabilities | C38: 30 | D38: 15 | E38: =0 -> 0 | F38: =0 -> 0 | G38: =C38+D38+E38+F38 -> 45
A39: TOTAL NON-CURRENT LIABILITIES | C39: =SUM(C32:C38) -> 480 | D39: =SUM(D32:D38) -> 215 | E39: =SUM(E32:E38) -> 47.5 | F39: =SUM(F32:F38) -> 2913 | G39: =C39+D39+E39+F39 -> 3655.5
A40: TOTAL LIABILITIES | C40: =C30+C39 -> 685 | D40: =D30+D39 -> 290 | E40: =E30+E39 -> 42.5 | F40: =F30+F39 -> 2913 | G40: =C40+D40+E40+F40 -> 3930.5
A42: SHAREHOLDERS' EQUITY
A43: Common Stock & APIC – Acquiror | C43: 500 | D43: =0 -> 0 | E43: =0 -> 0 | F43: ='Txn Assumptions'!C34 -> 1950 | G43: =C43+D43+E43+F43 -> 2450
A44: Common Stock & APIC – Target [Eliminated on consolidation] | C44: =0 -> 0 | D44: 250 | E44: =0 -> 0 | F44: =-D44 -> -250 | G44: =C44+D44+E44+F44 -> 0
A45: Retained Earnings – Acquiror | C45: 350 | D45: =0 -> 0 | E45: =0 -> 0 | F45: =-('Sources & Uses'!C17+'Sources & Uses'!C18)*(1-'Txn Assumptions'!C59) -> -22.5 | G45: =C45+D45+E45+F45 -> 327.5
...

Sheet Accretion-Dilution
A2: ACCRETION / DILUTION ANALYSIS
A5: ACCRETION / DILUTION | C5: FY-1 (LTM) | D5: FY+1 (Proj.) | E5: FY+2 (Proj.) | F5: FY+3 (Proj.) | G5: FY+4 (Proj.) | H5: FY+5 (Proj.) | I5: BACK -->
A7: EPS ACCRETION / (DILUTION) SUMMARY
A8: Acquiror Standalone EPS ($) | C8: ='Acquiror IS'!C31 -> 0.645 | D8: ='Acquiror IS'!D31 -> 0.7026 | E8: ='Acquiror IS'!E31 -> 0.765 | F8: ='Acquiror IS'!F31 -> 0.8322 | G8: ='Acquiror IS'!G31 -> 0.9042 | H8: ='Acquiror IS'!H31 -> 0.981
A9: Pro-Forma Combined EPS ($) | C9: ='Pro-Forma IS'!C45 -> 0.12528702 | D9: ='Pro-Forma IS'!D45 -> 0.34585629 | E9: ='Pro-Forma IS'!E45 -> 0.51479737 | F9: ='Pro-Forma IS'!F45 -> 0.6951676 | G9: ='Pro-Forma IS'!G45 -> 0.84492874 | H9: ='Pro-Forma IS'!H45 -> 0.97721775
A10: EPS Change ($) [Pro-Forma – Standalone] | C10: =C9-C8 -> -0.51971298 | D10: =D9-D8 -> -0.35674371 | E10: =E9-E8 -> -0.25020263 | F10: =F9-F8 -> -0.1370324 | G10: =G9-G8 -> -0.059271258 | H10: =H9-H8 -> -0.0037822452
A11: EPS Accretion / (Dilution) (%) | C11: =IF(C8=0,0,C10/C8) -> -0.80575655 | D11: =IF(D8=0,0,D10/D8) -> -0.50774795 | E11: =IF(E8=0,0,E10/E8) -> -0.32706226 | F11: =IF(F8=0,0,F10/F8) -> -0.16466283 | G11: =IF(G8=0,0,G10/G8) -> -0.065551048 | H11: =IF(H8=0,0,H10/H8) -> -0.0038554997
A13: NET INCOME BRIDGE (Acquiror → Pro-Forma)
A14: Acquiror Standalone Net Income ($mm) | C14: ='Acquiror IS'!C27 -> 161.25 | D14: ='Acquiror IS'!D27 -> 175.65 | E14: ='Acquiror IS'!E27 -> 191.25 | F14: ='Acquiror IS'!F27 -> 208.05 | G14: ='Acquiror IS'!G27 -> 226.05 | H14: ='Acquiror IS'!H27 -> 245.25
A15: (+) Target Standalone Net Income ($mm) | C15: ='Target IS'!C26 -> 45.75 | D15: ='Target IS'!D26 -> 50.8125 | E15: ='Target IS'!E26 -> 56.4375 | F15: ='Target IS'!F26 -> 62.625 | G15: ='Target IS'!G26 -> 69.375 | H15: ='Target IS'!H26 -> 76.6875
A16: (+) Revenue Synergies – After Tax | C16: ='Synergy Schedule'!C11*(1-0.25) -> 0 | D16: ='Synergy Schedule'!D11*(1-0.25) -> 6 | E16: ='Synergy Schedule'!E11*(1-0.25) -> 15.75 | F16: ='Synergy Schedule'!F11*(1-0.25) -> 27.75 | G16: ='Synergy Schedule'!G11*(1-0.25) -> 37.5 | H16: ='Synergy Schedule'!H11*(1-0.25) -> 43.5
A17: (+) Cost Synergies – After Tax | C17: ='Synergy Schedule'!C19*(1-0.25) -> 0 | D17: ='Synergy Schedule'!D19*(1-0.25) -> 11.25 | E17: ='Synergy Schedule'!E19*(1-0.25) -> 28.5 | F17: ='Synergy Schedule'!F19*(1-0.25) -> 45 | G17: ='Synergy Schedule'!G19*(1-0.25) -> 53.25 | H17: ='Synergy Schedule'!H19*(1-0.25) -> 58.5
A18: (-) PPA Amortization – After Tax | C18: ='Pro-Forma IS'!C27*(1-0.25) -> -15 | D18: ='Pro-Forma IS'!D27*(1-0.25) -> -15 | E18: ='Pro-Forma IS'!E27*(1-0.25) -> -15 | F18: ='Pro-Forma IS'!F27*(1-0.25) -> -15 | G18: ='Pro-Forma IS'!G27*(1-0.25) -> -15 | H18: ='Pro-Forma IS'!H27*(1-0.25) -> -15
A19: (-) Incremental Interest on New Debt – After Tax | C19: =-('Txn Assumptions'!C47*'Txn Assumptions'!C48+'Txn Assumptions'!C50*'Txn Assumptions'!C51+'Txn Assumptions'!C53*'Txn Assumptions'!C54)*(1-0.25) -> -134.41125 | D19: =-('Txn Assumptions'!C47*'Txn Assumptions'!C48+'Txn Assumptions'!C50*'Txn Assumptions'!C51+'Txn Assumptions'!C53*'Txn Assumptions'!C54)*(1-0.25) -> -134.41125 | E19: =-('Txn Assumptions'!C47*'Txn Assumptions'!C48+'Txn Assumptions'!C50*'Txn Assumptions'!C51+'Txn Assumptions'!C53*'Txn Assumptions'!C54)*(1-0.25) -> -134.41125 | F19: =-('Txn Assumptions'!C47*'Txn Assumptions'!C48+'Txn Assumptions'!C50*'Txn Assumptions'!C51+'Txn Assumptions'!C53*'Txn Assumptions'!C54)*(1-0.25) -> -134.41125 | G19: =-('Txn Assumptions'!C47*'Txn Assumptions'!C48+'Txn Assumptions'!C50*'Txn Assumptions'!C51+'Txn Assumptions'!C53*'Txn Assumptions'!C54)*(1-0.25) -> -134.41125 | H19: =-('Txn Assumptions'!C47*'Txn Assumptions'!C48+'Txn Assumptions'!C50*'Txn Assumptions'!C51+'Txn Assumptions'!C53*'Txn Assumptions'!C54)*(1-0.25) -> -134.41125
A20: (-) One-Time Transaction Costs – After Tax | C20: -30 | D20: =0 -> 0 | E20: =0 -> 0 | F20: =0 -> 0 | G20: =0 -> 0 | H20: =0 -> 0
A21: PRO-FORMA NET INCOME ($mm) [Cross-check] | C21: ='Pro-Forma IS'!C41 -> 35.76375 | D21: ='Pro-Forma IS'!D41 -> 98.72625 | E21: ='Pro-Forma IS'!E41 -> 146.95125 | F21: ='Pro-Forma IS'!F41 -> 198.43875 | G21: ='Pro-Forma IS'!G41 -> 241.18875 | H21: ='Pro-Forma IS'!H41 -> 278.95125
A23: BREAKEVEN SYNERGY REQUIRED
A24: EPS Breakeven Synergy ($mm) – Synergy needed to reach zero accretion/dilution | C24: =IF(C8=0,0,(C8-C9)*'Txn Assumptions'!C50/(1-0.25)) -> 69.295064 | D24: =IF(D8=0,0,(D8-D9)*'Txn Assumptions'!C50/(1-0.25)) -> 47.565828 | E24: =IF(E8=0,0,(E8-E9)*'Txn Assumptions'!C50/(1-0.25)) -> 33.36035 | F24: =IF(F8=0,0,(F8-F9)*'Txn Assumptions'!C50/(1-0.25)) -> 18.270987 | G24: =IF(G8=0,0,(G8-G9)*'Txn Assumptions'!C50/(1-0.25)) -> 7.9028344 | H24: =IF(H8=0,0,(H8-H9)*'Txn Assumptions'!C50/(1-0.25)) -> 0.50429936
A25: As % of Transaction EV | C25: =IF('Txn Assumptions'!C18=0,0,C24/'Txn Assumptions'!C18) -> 0.013872886 | D25: =IF('Txn Assumptions'!C18=0,0,D24/'Txn Assumptions'!C18) -> 0.0095226883 | E25: =IF('Txn Assumptions'!C18=0,0,E24/'Txn Assumptions'!C18) -> 0.0066787488 | F25: =IF('Txn Assumptions'!C18=0,0,F24/'Txn Assumptions'!C18) -> 0.0036578553 | G25: =IF('Txn Assumptions'!C18=0,0,G24/'Txn Assumptions'!C18) -> 0.001582149 | H25: =IF('Txn Assumptions'!C18=0,0,H24/'Txn Assumptions'!C18) -> 0.00010096083
A27: PRO-FORMA CREDIT METRICS
A28: Pro-Forma Revenue ($mm) | C28: ='Pro-Forma IS'!C11 -> 2000 | D28: ='Pro-Forma IS'!D11 -> 2173 | E28: ='Pro-Forma IS'!E11 -> 2366 | F28: ='Pro-Forma IS'!F11 -> 2577 | G28: ='Pro-Forma IS'!G11 -> 2800 | H28: ='Pro-Forma IS'!H11 -> 3033
A29: Pro-Forma EBITDA ($mm) | C29: ='Pro-Forma IS'!C31 -> 355 | D29: ='Pro-Forma IS'!D31 -> 416 | E29: ='Pro-Forma IS'!E31 -> 488 | F29: ='Pro-Forma IS'!F31 -> 565 | G29: ='Pro-Forma IS'!G31 -> 631 | H29: ='Pro-Forma IS'!H31 -> 691
A30: Transaction Enterprise Value ($mm) | C30: ='Txn Assumptions'!C18 -> 4995 | D30: ='Txn Assumptions'!C18 -> 4995 | E30: ='Txn Assumptions'!C18 -> 4995 | F30: ='Txn Assumptions'!C18 -> 4995 | G30: ='Txn Assumptions'!C18 -> 4995 | H30: ='Txn Assumptions'!C18 -> 4995
A31: EV / Pro-Forma EBITDA (x) | C31: =IF(C29=0,0,C30/C29) -> 14.070423 | D31: =IF(D29=0,0,D30/D29) -> 12.007212 | E31: =IF(E29=0,0,E30/E29) -> 10.235656 | F31: =IF(F29=0,0,F30/F29) -> 8.840708 | G31: =IF(G29=0,0,G30/G29) -> 7.9160063 | H31: =IF(H29=0,0,H30/H29) -> 7.2286541
A32: Net Debt / Pro-Forma EBITDA (x) | C32: =IF(C29=0,0,('Txn Assumptions'!C40+'Txn Assumptions'!C16-50)/C29) -> 5.915493 | D32: =IF(D29=0,0,('Txn Assumptions'!C40+'Txn Assumptions'!C16-50)/D29) -> 5.0480769 | E32: =IF(E29=0,0,('Txn Assumptions'!C40+'Txn Assumptions'!C16-50)/E29) -> 4.3032787 | F32: =IF(F29=0,0,('Txn Assumptions'!C40+'Txn Assumptions'!C16-50)/F29) -> 3.7168142 | G32: =IF(G29=0,0,('Txn Assumptions'!C40+'Txn Assumptions'!C16-50)/G29) -> 3.3280507 | H32: =IF(H29=0,0,('Txn Assumptions'!C40+'Txn Assumptions'!C16-50)/H29) -> 3.0390738

Sheet Goodwill & Intangibles
A2: GOODWILL & INTANGIBLES ROLL-FORWARD ($mm)
A5: GOODWILL & INTANGIBLES ($mm) | C5: FY-1 (LTM) | D5: FY+1 (Proj.) | E5: FY+2 (Proj.) | F5: FY+3 (Proj.) | G5: FY+4 (Proj.) | H5: FY+5 (Proj.) | I5: BACK -->
A7: GOODWILL ROLL-FORWARD
A8: Beginning Goodwill Balance | C8: =0 -> 0 | D8: =C11 -> 4782.5 | E8: =D11 -> 4782.5 | F8: =E11 -> 4782.5 | G8: =F11 -> 4782.5 | H8: =G11 -> 4782.5
A9: (+) Goodwill Created on Acquisition | C9: =PPA!C42 -> 4782.5 | D9: =0 -> 0 | E9: =0 -> 0 | F9: =0 -> 0 | G9: =0 -> 0 | H9: =0 -> 0
A10: (-) Goodwill Impairment | C10: 0 | D10: 0 | E10: 0 | F10: 0 | G10: 0 | H10: 0
A11: ENDING GOODWILL | C11: =C8+C9+C10 -> 4782.5 | D11: =D8+D9+D10 -> 4782.5 | E11: =E8+E9+E10 -> 4782.5 | F11: =F8+F9+F10 -> 4782.5 | G11: =G8+G9+G10 -> 4782.5 | H11: =H8+H9+H10 -> 4782.5
A13: ACQUIRED INTANGIBLES ROLL-FORWARD
A14: Beginning Intangibles Balance | C14: =0 -> 0 | D14: =C17 -> 140 | E14: =D17 -> 120 | F14: =E17 -> 100 | G14: =F17 -> 80 | H14: =G17 -> 60
A15: (+) New Intangibles from Acquisition | C15: 160 | D15: =0 -> 0 | E15: =0 -> 0 | F15: =0 -> 0 | G15: =0 -> 0 | H15: =0 -> 0
A16: (-) Annual Amortization | C16: -20 | D16: -20 | E16: -20 | F16: -20 | G16: -20 | H16: -20
A17: ENDING INTANGIBLES BALANCE | C17: =C14+C15+C16 -> 140 | D17: =D14+D15+D16 -> 120 | E17: =E14+E15+E16 -> 100 | F17: =F14+F15+F16 -> 80 | G17: =G14+G15+G16 -> 60 | H17: =H14+H15+H16 -> 40
A19: INTANGIBLE ASSET DETAIL – LIVES & AMORTIZATION
A20: Asset | C20: Fair Value | D20: Life (yrs) | E20: Ann. Amort.
A21: Customer Relationships | C21: 80 | D21: 12 | E21: =C21/D21 -> 6.6666667
A22: Developed Technology / IP | C22: 50 | D22: 7 | E22: =C22/D22 -> 7.1428571
A23: Trade Names & Trademarks | C23: 20 | D23: 10 | E23: =C23/D23 -> 2
A24: Non-Compete Agreements | C24: 10 | D24: 3 | E24: =C24/D24 -> 3.3333333
A25: Total Intangibles | C25: =SUM(C21:C24) -> 160 | E25: =SUM(E21:E24) -> 19.142857

Sheet Sensitivity Tables
B2: SENSITIVITY & SCENARIO ANALYSIS | Deal Pricing & Synergy Impact
B5: TABLE 1 | EPS Accretion/(Dilution) % – Offer Price vs. Total Synergies ($mm)
B6: ↓ Synergies | Offer Price → | C6: $27.50 | D6: $30.00 | E6: $32.50 | F6: $35.00 | G6: $37.50
B7: $0mm Synergies | C7: -0.25327323 | D7: -0.2545734 | E7: -0.25841956 | F7: -0.26226571 | G7: -0.26611186
B8: $20mm Synergies | C8: -0.24308931 | D8: -0.24693546 | E8: -0.25078162 | F8: -0.25462777 | G8: -0.25847392
B9: $40mm Synergies | C9: -0.23545137 | D9: -0.23929752 | E9: -0.24314367 | F9: -0.24698983 | G9: -0.25083598
B10: $60mm Synergies | C10: -0.22781343 | D10: -0.23165958 | E10: -0.23550573 | F10: -0.23935189 | G10: -0.24319804
B11: $80mm Synergies | C11: -0.22017548 | D11: -0.22402164 | E11: -0.22786779 | F11: -0.23171395 | G11: -0.2355601
B13: TABLE 2 | EV / Pro-Forma EBITDA (x) – Synergy Level vs. EBITDA Multiple
B14: ↓ Cost Synergies | EV ($mm) → | C14: $600mm EV | D14: $650mm EV | E14: $700mm EV | F14: $750mm EV | G14: $800mm EV
B15: $0mm Cost Syn | C15: 5 | D15: 5.4166667 | E15: 5.8333333 | F15: 6.25 | G15: 6.6666667
B16: $15mm Cost Syn | C16: 4.4444444 | D16: 4.8148148 | E16: 5.1851852 | F16: 5.5555556 | G16: 5.9259259
B17: $30mm Cost Syn | C17: 4 | D17: 4.3333333 | E17: 4.6666667 | F17: 5 | G17: 5.3333333
B18: $45mm Cost Syn | C18: 3.6363636 | D18: 3.9393939 | E18: 4.2424242 | F18: 4.5454545 | G18: 4.8484848
B19: $60mm Cost Syn | C19: 3.3333333 | D19: 3.6111111 | E19: 3.8888889 | F19: 4.1666667 | G19: 4.4444444
B21: TABLE 3 | EPS Dilution (%) – Offer Premium vs. % Stock Consideration
B22: ↓ Premium | % Stock → | C22: 0% Stock | D22: 25% Stock | E22: 50% Stock | F22: 75% Stock | G22: 100% Stock
B23: 10% Premium | C23: -0.018 | D23: -0.028 | E23: -0.038 | F23: -0.048 | G23: -0.058
B24: 20% Premium | C24: -0.036 | D24: -0.046 | E24: -0.056 | F24: -0.066 | G24: -0.076
B25: 30% Premium | C25: -0.054 | D25: -0.064 | E25: -0.074 | F25: -0.084 | G25: -0.094
B26: 40% Premium | C26: -0.072 | D26: -0.082 | E26: -0.092 | F26: -0.102 | G26: -0.112
B27: 50% Premium | C27: -0.09 | D27: -0.1 | E27: -0.11 | F27: -0.12 | G27: -0.13
